Workbook

Sheet Inteligencia emocional
A1: Dimension 1
B3: Percepción emocional | J3: Comprensión emocional | R3: Regulación emocional | Z3: Total | AA3: Valoración
B4: PRG.1 | C4: PRG.2 | D4: PRG.3 | E4: PRG.4 | F4: PRG.5 | G4: PRG.6 | H4: PRG.7 | I4: PRG.8 | J4: PRG.9 | K4: PRG.10 | L4: PRG.11 | M4: PRG.12 | N4: PRG.13 | O4: PRG.14 | P4: PRG.15 | Q4: PRG.16 | R4: PRG.17 | S4: PRG.18 | T4: PRG.19 | U4: PRG.20 | V4: PRG.21 | W4: PRG.22 | X4: PRG.23 | Y4: PRG.24
A5: Docente 1 | B5: 3 | C5: 1 | D5: 4 | E5: 2 | F5: 3 | G5: 3 | H5: 2 | I5: 2 | J5: 3 | K5: 4 | L5: 2 | M5: 3 | N5: 3 | O5: 3 | P5: 3 | Q5: 3 | R5: 3 | S5: 1 | T5: 3 | U5: 3 | V5: 2 | W5: 3 | X5: 3 | Y5: 2 | Z5: 64
A6: Docente 2 | B6: 2 | C6: 1 | D6: 3 | E6: 3 | F6: 2 | G6: 4 | H6: 3 | I6: 4 | J6: 4 | K6: 4 | L6: 1 | M6: 3 | N6: 3 | O6: 4 | P6: 1 | Q6: 4 | R6: 4 | S6: 1 | T6: 3 | U6: 3 | V6: 4 | W6: 1 | X6: 3 | Y6: 4 | Z6: 69
A7: Docente 3 | B7: 2 | C7: 3 | D7: 2 | E7: 2 | F7: 1 | G7: 1 | H7: 2 | I7: 1 | J7: 2 | K7: 1 | L7: 3 | M7: 2 | N7: 2 | O7: 1 | P7: 1 | Q7: 1 | R7: 2 | S7: 2 | T7: 1 | U7: 2 | V7: 2 | W7: 2 | X7: 2 | Y7: 1 | Z7: 41
A8: Docente 4 | B8: 1 | C8: 2 | D8: 4 | E8: 4 | F8: 2 | G8: 2 | H8: 4 | I8: 2 | J8: 3 | K8: 3 | L8: 1 | M8: 3 | N8: 4 | O8: 4 | P8: 2 | Q8: 4 | R8: 4 | S8: 2 | T8: 4 | U8: 4 | V8: 3 | W8: 2 | X8: 4 | Y8: 4 | Z8: 72
A9: Docente 5 | B9: 3 | C9: 2 | D9: 3 | E9: 3 | F9: 1 | G9: 4 | H9: 3 | I9: 3 | J9: 4 | K9: 3 | L9: 2 | M9: 4 | N9: 4 | O9: 2 | P9: 3 | Q9: 4 | R9: 4 | S9: 2 | T9: 4 | U9: 3 | V9: 3 | W9: 1 | X9: 3 | Y9: 4 | Z9: 72
A10: Docente 6 | B10: 1 | C10: 3 | D10: 5 | E10: 4 | F10: 2 | G10: 4 | H10: 5 | I10: 4 | J10: 4 | K10: 3 | L10: 2 | M10: 4 | N10: 5 | O10: 4 | P10: 2 | Q10: 5 | R10: 5 | S10: 3 | T10: 5 | U10: 5 | V10: 4 | W10: 2 | X10: 5 | Y10: 5 | Z10: 91
A11: Docente 7 | B11: 1 | C11: 3 | D11: 3 | E11: 3 | F11: 3 | G11: 3 | H11: 4 | I11: 2 | J11: 2 | K11: 2 | L11: 3 | M11: 3 | N11: 3 | O11: 3 | P11: 1 | Q11: 4 | R11: 3 | S11: 2 | T11: 3 | U11: 2 | V11: 3 | W11: 3 | X11: 3 | Y11: 2 | Z11: 64
A12: Docente 8 | B12: 3 | C12: 1 | D12: 1 | E12: 2 | F12: 3 | G12: 1 | H12: 1 | I12: 2 | J12: 1 | K12: 2 | L12: 2 | M12: 1 | N12: 1 | O12: 1 | P12: 2 | Q12: 1 | R12: 1 | S12: 2 | T12: 1 | U12: 1 | V12: 1 | W12: 2 | X12: 1 | Y12: 1 | Z12: 35
A13: Docente 9 | B13: 1 | C13: 2 | D13: 3 | E13: 3 | F13: 2 | G13: 2 | H13: 3 | I13: 3 | J13: 3 | K13: 3 | L13: 2 | M13: 3 | N13: 3 | O13: 3 | P13: 1 | Q13: 2 | R13: 3 | S13: 1 | T13: 3 | U13: 2 | V13: 3 | W13: 3 | X13: 3 | Y13: 3 | Z13: 60
A14: Docente 10 | B14: 3 | C14: 3 | D14: 3 | E14: 3 | F14: 2 | G14: 2 | H14: 4 | I14: 3 | J14: 3 | K14: 2 | L14: 2 | M14: 2 | N14: 4 | O14: 4 | P14: 3 | Q14: 2 | R14: 2 | S14: 2 | T14: 3 | U14: 2 | V14: 3 | W14: 2 | X14: 4 | Y14: 2 | Z14: 65
A15: Docente 11 | B15: 3 | C15: 3 | D15: 4 | E15: 4 | F15: 3 | G15: 5 | H15: 4 | I15: 5 | J15: 5 | K15: 5 | L15: 1 | M15: 4 | N15: 5 | O15: 4 | P15: 2 | Q15: 5 | R15: 5 | S15: 1 | T15: 3 | U15: 4 | V15: 3 | W15: 2 | X15: 3 | Y15: 5 | Z15: 88
A16: Docente 12 | B16: 2 | C16: 3 | D16: 5 | E16: 4 | F16: 2 | G16: 3 | H16: 4 | I16: 5 | J16: 4 | K16: 3 | L16: 3 | M16: 5 | N16: 4 | O16: 5 | P16: 2 | Q16: 5 | R16: 4 | S16: 2 | T16: 5 | U16: 4 | V16: 5 | W16: 3 | X16: 5 | Y16: 5 | Z16: 92
... A359: Docente 355 | B359: 2 | C359: 3 | D359: 3 | E359: 3 | F359: 2 | G359: 3 | H359: 2 | I359: 2 | J359: 2 | K359: 2 | L359: 2 | M359: 2 | N359: 2 | O359: 2 | P359: 1 | Q359: 2 | R359: 3 | S359: 1 | T359: 1 | U359: 3 | V359: 2 | W359: 2 | X359: 2 | Y359: 3 | Z359: 52
A360: TOTAL | B360: =SUM(B5:B359) -> 0 | C360: =SUM(C5:C359) -> 0 | D360: =SUM(D5:D359) -> 0 | E360: =SUM(E5:E359) -> 0 | F360: =SUM(F5:F359) -> 0 | G360: =SUM(G5:G359) -> 0 | H360: =SUM(H5:H359) -> 0 | I360: =SUM(I5:I359) -> 0 | ... Z360: =SUM(Z5:Z359) -> 0
A361: MODA | B361: =MODE(B5:B359) -> 0 | C361: =MODE(C5:C359) -> 0 | D361: =MODE(D5:D359) -> 0 | E361: =MODE(E5:E359) -> 0 | F361: =MODE(F5:F359) -> 0 | G361: =MODE(G5:G359) -> 0 | H361: =MODE(H5:H359) -> 0 | I361: =MODE(I5:I359) -> 0 | ... Z361: =MODE(Z5:Z359) -> 0
A362: MEDIA | B362: =(B360/355) -> 0 | C362: =(C360/355) -> 0 | D362: =(D360/355) -> 0 | E362: =(E360/355) -> 0 | F362: =(F360/355) -> 0 | G362: =(G360/355) -> 0 | H362: =(H360/355) -> 0 | I362: =(I360/355) -> 0 | ... Z362: =(Z360/355) -> 0
A363: MEDIANA | B363: =MEDIAN(B5:B359) -> 0 | C363: =MEDIAN(C5:C359) -> 0 | D363: =MEDIAN(D5:D359) -> 0 | E363: =MEDIAN(E5:E359) -> 0 | F363: =MEDIAN(F5:F359) -> 0 | G363: =MEDIAN(G5:G359) -> 0 | H363: =MEDIAN(H5:H359) -> 0 | I363: =MEDIAN(I5:I359) -> 0 | ... Z363: =MEDIAN(Z5:Z359) -> 0
A364: Desv.Est | B364: =ROUND(STDEV(B5:B359),2) -> 0 | C364: =ROUND(STDEV(C5:C359),2) -> 0 | D364: =ROUND(STDEV(D5:D359),2) -> 0 | E364: =ROUND(STDEV(E5:E359),2) -> 0 | F364: =ROUND(STDEV(F5:F359),2) -> 0 | G364: =ROUND(STDEV(G5:G359),2) -> 0 | H364: =ROUND(STDEV(H5:H359),2) -> 0 | I364: =ROUND(STDEV(I5:I359),2) -> 0 | ... Z364: =ROUND(STDEV(Z5:Z359),2) -> 0
A365: Coef. Varia. | B365: =(B364/B362) -> 0 | C365: =(C364/C362) -> 0 | D365: =(D364/D362) -> 0 | E365: =(E364/E362) -> 0 | F365: =(F364/F362) -> 0 | G365: =(G364/G362) -> 0 | H365: =(H364/H362) -> 0 | I365: =(I364/I362) -> 0 | ... Z365: =(Z364/Z362) -> 0
A366: Nada de acuerdo | B366: =COUNTIF($B$5:$B$359,$A1355) -> 0 | C366: =COUNTIF($C$5:$C$359,$A1355) -> 0 | D366: =COUNTIF($D$5:$D$359,$A1355) -> 0 | E366: =COUNTIF($E$5:$E$359,$A1355) -> 0 | F366: =COUNTIF($F$5:$F$359,$A1355) -> 0 | G366: =COUNTIF($G$5:$G$359,$A1355) -> 0 | H366: =COUNTIF($H$5:$H$359,$A1355) -> 0 | I366: =COUNTIF($I$5:$I$359,$A1355) -> 0 | J366: =COUNTIF($J$5:$J$359,$A1355) -> 0 | K366: =COUNTIF($K$5:$K$359,$A1355) -> 0 | L366: =COUNTIF($L$5:$L$359,$A1355) -> 0 | M366: =COUNTIF($M$5:$M$359,$A1355) -> 0 | N366: =COUNTIF($N$5:$N$359,$A1355) -> 0 | O366: =COUNTIF($O$5:$O$359,$A1355) -> 0 | P366: =COUNTIF($P$5:$P$359,$A1355) -> 0 | Q366: =COUNTIF($Q$5:$Q$359,$A1355) -> 0 | R366: =COUNTIF($R$5:$R$359,$A1355) -> 0 | S366: =COUNTIF($S$5:$S$359,$A1355) -> 0 | T366: =COUNTIF($T$5:$T$359,$A1355) -> 0 | U366: =COUNTIF($U$5:$U$359,$A1355) -> 0 | V366: =COUNTIF($V$5:$V$359,$A1355) -> 0 | W366: =COUNTIF($W$5:$W$359,$A1355) -> 0 | X366: =COUNTIF($X$5:$X$359,$A1355) -> 0 | Y366: =COUNTIF($Y$5:$Y$359,$A1355) -> 0
A367: Algo de acuerdo | B367: =COUNTIF($B$5:$B$359,$A1356) -> 0 | C367: =COUNTIF($C$5:$C$359,$A1356) -> 0 | D367: =COUNTIF($D$5:$D$359,$A1356) -> 0 | E367: =COUNTIF($E$5:$E$359,$A1356) -> 0 | F367: =COUNTIF($F$5:$F$359,$A1356) -> 0 | G367: =COUNTIF($G$5:$G$359,$A1356) -> 0 | H367: =COUNTIF($H$5:$H$359,$A1356) -> 0 | I367: =COUNTIF($I$5:$I$359,$A1356) -> 0 | J367: =COUNTIF($J$5:$J$359,$A1356) -> 0 | K367: =COUNTIF($K$5:$K$359,$A1356) -> 0 | L367: =COUNTIF($L$5:$L$359,$A1356) -> 0 | M367: =COUNTIF($M$5:$M$359,$A1356) -> 0 | N367: =COUNTIF($N$5:$N$359,$A1356) -> 0 | O367: =COUNTIF($O$5:$O$359,$A1356) -> 0 | P367: =COUNTIF($P$5:$P$359,$A1356) -> 0 | Q367: =COUNTIF($Q$5:$Q$359,$A1356) -> 0 | R367: =COUNTIF($R$5:$R$359,$A1356) -> 0 | S367: =COUNTIF($S$5:$S$359,$A1356) -> 0 | T367: =COUNTIF($T$5:$T$359,$A1356) -> 0 | U367: =COUNTIF($U$5:$U$359,$A1356) -> 0 | V367: =COUNTIF($V$5:$V$359,$A1356) -> 0 | W367: =COUNTIF($W$5:$W$359,$A1356) -> 0 | X367: =COUNTIF($X$5:$X$359,$A1356) -> 0 | Y367: =COUNTIF($Y$5:$Y$359,$A1356) -> 0
A368: Bastante de acuerdo | B368: =COUNTIF($B$5:$B$359,$A1357) -> 0 | C368: =COUNTIF($C$5:$C$359,$A1357) -> 0 | D368: =COUNTIF($D$5:$D$359,$A1357) -> 0 | E368: =COUNTIF($E$5:$E$359,$A1357) -> 0 | F368: =COUNTIF($F$5:$F$359,$A1357) -> 0 | G368: =COUNTIF($G$5:$G$359,$A1357) -> 0 | H368: =COUNTIF($H$5:$H$359,$A1357) -> 0 | I368: =COUNTIF($I$5:$I$359,$A1357) -> 0 | J368: =COUNTIF($J$5:$J$359,$A1357) -> 0 | K368: =COUNTIF($K$5:$K$359,$A1357) -> 0 | L368: =COUNTIF($L$5:$L$359,$A1357) -> 0 | M368: =COUNTIF($M$5:$M$359,$A1357) -> 0 | N368: =COUNTIF($N$5:$N$359,$A1357) -> 0 | O368: =COUNTIF($O$5:$O$359,$A1357) -> 0 | P368: =COUNTIF($P$5:$P$359,$A1357) -> 0 | Q368: =COUNTIF($Q$5:$Q$359,$A1357) -> 0 | R368: =COUNTIF($R$5:$R$359,$A1357) -> 0 | S368: =COUNTIF($S$5:$S$359,$A1357) -> 0 | T368: =COUNTIF($T$5:$T$359,$A1357) -> 0 | U368: =COUNTIF($U$5:$U$359,$A1357) -> 0 | V368: =COUNTIF($V$5:$V$359,$A1357) -> 0 | W368: =COUNTIF($W$5:$W$359,$A1357) -> 0 | X368: =COUNTIF($X$5:$X$359,$A1357) -> 0 | Y368: =COUNTIF($Y$5:$Y$359,$A1357) -> 0
A369: Muy de acuerdo | B369: =COUNTIF($B$5:$B$359,$A1358) -> 0 | C369: =COUNTIF($C$5:$C$359,$A1358) -> 0 | D369: =COUNTIF($D$5:$D$359,$A1358) -> 0 | E369: =COUNTIF($E$5:$E$359,$A1358) -> 0 | F369: =COUNTIF($F$5:$F$359,$A1358) -> 0 | G369: =COUNTIF($G$5:$G$359,$A1358) -> 0 | H369: =COUNTIF($H$5:$H$359,$A1358) -> 0 | I369: =COUNTIF($I$5:$I$359,$A1358) -> 0 | J369: =COUNTIF($J$5:$J$359,$A1358) -> 0 | K369: =COUNTIF($K$5:$K$359,$A1358) -> 0 | L369: =COUNTIF($L$5:$L$359,$A1358) -> 0 | M369: =COUNTIF($M$5:$M$359,$A1358) -> 0 | N369: =COUNTIF($N$5:$N$359,$A1358) -> 0 | O369: =COUNTIF($O$5:$O$359,$A1358) -> 0 | P369: =COUNTIF($P$5:$P$359,$A1358) -> 0 | Q369: =COUNTIF($Q$5:$Q$359,$A1358) -> 0 | R369: =COUNTIF($R$5:$R$359,$A1358) -> 0 | S369: =COUNTIF($S$5:$S$359,$A1358) -> 0 | T369: =COUNTIF($T$5:$T$359,$A1358) -> 0 | U369: =COUNTIF($U$5:$U$359,$A1358) -> 0 | V369: =COUNTIF($V$5:$V$359,$A1358) -> 0 | W369: =COUNTIF($W$5:$W$359,$A1358) -> 0 | X369: =COUNTIF($X$5:$X$359,$A1358) -> 0 | Y369: =COUNTIF($Y$5:$Y$359,$A1358) -> 0
A370: Totalmente de acuerdo | B370: =COUNTIF($B$5:$B$359,$A1359) -> 0 | C370: =COUNTIF($C$5:$C$359,$A1359) -> 0 | D370: =COUNTIF($D$5:$D$359,$A1359) -> 0 | E370: =COUNTIF($E$5:$E$359,$A1359) -> 0 | F370: =COUNTIF($F$5:$F$359,$A1359) -> 0 | G370: =COUNTIF($G$5:$G$359,$A1359) -> 0 | H370: =COUNTIF($H$5:$H$359,$A1359) -> 0 | I370: =COUNTIF($I$5:$I$359,$A1359) -> 0 | J370: =COUNTIF($J$5:$J$359,$A1359) -> 0 | K370: =COUNTIF($K$5:$K$359,$A1359) -> 0 | L370: =COUNTIF($L$5:$L$359,$A1359) -> 0 | M370: =COUNTIF($M$5:$M$359,$A1359) -> 0 | N370: =COUNTIF($N$5:$N$359,$A1359) -> 0 | O370: =COUNTIF($O$5:$O$359,$A1359) -> 0 | P370: =COUNTIF($P$5:$P$359,$A1359) -> 0 | Q370: =COUNTIF($Q$5:$Q$359,$A1359) -> 0 | R370: =COUNTIF($R$5:$R$359,$A1359) -> 0 | S370: =COUNTIF($S$5:$S$359,$A1359) -> 0 | T370: =COUNTIF($T$5:$T$359,$A1359) -> 0 | U370: =COUNTIF($U$5:$U$359,$A1359) -> 0 | V370: =COUNTIF($V$5:$V$359,$A1359) -> 0 | W370: =COUNTIF($W$5:$W$359,$A1359) -> 0 | X370: =COUNTIF($X$5:$X$359,$A1359) -> 0 | Y370: =COUNTIF($Y$5:$Y$359,$A1359) -> 0
A371: Total | B371: =SUM($B366:$B370) -> 0 | C371: =SUM($C366:$C370) -> 0 | D371: =SUM($D366:$D370) -> 0 | E371: =SUM($E366:$E370) -> 0 | F371: =SUM($F366:$F370) -> 0 | G371: =SUM($G366:$G370) -> 0 | H371: =SUM($H366:$H370) -> 0 | I371: =SUM($I366:$I370) -> 0 | J371: =SUM($J366:$J370) -> 0 | K371: =SUM($K366:$K370) -> 0 | L371: =SUM($L366:$L370) -> 0 | M371: =SUM($M366:$M370) -> 0 | N371: =SUM($N366:$N370) -> 0 | O371: =SUM($O366:$O370) -> 0 | P371: =SUM($P366:$P370) -> 0 | Q371: =SUM($Q366:$Q370) -> 0 | R371: =SUM($R366:$R370) -> 0 | S371: =SUM($S366:$S370) -> 0 | T371: =SUM($T366:$T370) -> 0 | U371: =SUM($U366:$U370) -> 0 | V371: =SUM($V366:$V370) -> 0 | W371: =SUM($W366:$W370) -> 0 | X371: =SUM($X366:$X370) -> 0 | Y371: =SUM($Y366:$Y370) -> 0
A372: Nada de acuerdo% | B372: =($B366/$B371) -> 0 | C372: =($C366/$C371) -> 0 | D372: =($D366/$D371) -> 0 | E372: =($E366/$E371) -> 0 | F372: =($F366/$F371) -> 0 | G372: =($G366/$G371) -> 0 | H372: =($H366/$H371) -> 0 | I372: =($I366/$I371) -> 0 | J372: =($J366/$J371) -> 0 | K372: =($K366/$K371) -> 0 | L372: =($L366/$L371) -> 0 | M372: =($M366/$M371) -> 0 | N372: =($N366/$N371) -> 0 | O372: =($O366/$O371) -> 0 | P372: =($P366/$P371) -> 0 | Q372: =($Q366/$Q371) -> 0 | R372: =($R366/$R371) -> 0 | S372: =($S366/$S371) -> 0 | T372: =($T366/$T371) -> 0 | U372: =($U366/$U371) -> 0 | V372: =($V366/$V371) -> 0 | W372: =($W366/$W371) -> 0 | X372: =($X366/$X371) -> 0 | Y372: =($Y366/$Y371) -> 0
A373: Algo de acuerdo% | B373: =($B367/$B371) -> 0 | C373: =($C367/$C371) -> 0 | D373: =($D367/$D371) -> 0 | E373: =($E367/$E371) -> 0 | F373: =($F367/$F371) -> 0 | G373: =($G367/$G371) -> 0 | H373: =($H367/$H371) -> 0 | I373: =($I367/$I371) -> 0 | J373: =($J367/$J371) -> 0 | K373: =($K367/$K371) -> 0 | L373: =($L367/$L371) -> 0 | M373: =($M367/$M371) -> 0 | N373: =($N367/$N371) -> 0 | O373: =($O367/$O371) -> 0 | P373: =($P367/$P371) -> 0 | Q373: =($Q367/$Q371) -> 0 | R373: =($R367/$R371) -> 0 | S373: =($S367/$S371) -> 0 | T373: =($T367/$T371) -> 0 | U373: =($U367/$U371) -> 0 | V373: =($V367/$V371) -> 0 | W373: =($W367/$W371) -> 0 | X373: =($X367/$X371) -> 0 | Y373: =($Y367/$Y371) -> 0
A374: Bastante de acuerdo% | B374: =($B368/$B371) -> 0 | C374: =($C368/$C371) -> 0 | D374: =($D368/$D371) -> 0 | E374: =($E368/$E371) -> 0 | F374: =($F368/$F371) -> 0 | G374: =($G368/$G371) -> 0 | H374: =($H368/$H371) -> 0 | I374: =($I368/$I371) -> 0 | J374: =($J368/$J371) -> 0 | K374: =($K368/$K371) -> 0 | L374: =($L368/$L371) -> 0 | M374: =($M368/$M371) -> 0 | N374: =($N368/$N371) -> 0 | O374: =($O368/$O371) -> 0 | P374: =($P368/$P371) -> 0 | Q374: =($Q368/$Q371) -> 0 | R374: =($R368/$R371) -> 0 | S374: =($S368/$S371) -> 0 | T374: =($T368/$T371) -> 0 | U374: =($U368/$U371) -> 0 | V374: =($V368/$V371) -> 0 | W374: =($W368/$W371) -> 0 | X374: =($X368/$X371) -> 0 | Y374: =($Y368/$Y371) -> 0
A375: Muy de acuerdo% | B375: =($B369/$B371) -> 0 | C375: =($C369/$C371) -> 0 | D375: =($D369/$D371) -> 0 | E375: =($E369/$E371) -> 0 | F375: =($F369/$F371) -> 0 | G375: =($G369/$G371) -> 0 | H375: =($H369/$H371) -> 0 | I375: =($I369/$I371) -> 0 | J375: =($J369/$J371) -> 0 | K375: =($K369/$K371) -> 0 | L375: =($L369/$L371) -> 0 | M375: =($M369/$M371) -> 0 | N375: =($N369/$N371) -> 0 | O375: =($O369/$O371) -> 0 | P375: =($P369/$P371) -> 0 | Q375: =($Q369/$Q371) -> 0 | R375: =($R369/$R371) -> 0 | S375: =($S369/$S371) -> 0 | T375: =($T369/$T371) -> 0 | U375: =($U369/$U371) -> 0 | V375: =($V369/$V371) -> 0 | W375: =($W369/$W371) -> 0 | X375: =($X369/$X371) -> 0 | Y375: =($Y369/$Y371) -> 0
A376: Totalmente de acuerdo% | B376: =($B370/$B371) -> 0 | C376: =($C370/$C371) -> 0 | D376: =($D370/$D371) -> 0 | E376: =($E370/$E371) -> 0 | F376: =($F370/$F371) -> 0 | G376: =($G370/$G371) -> 0 | H376: =($H370/$H371) -> 0 | I376: =($I370/$I371) -> 0 | J376: =($J370/$J371) -> 0 | K376: =($K370/$K371) -> 0 | L376: =($L370/$L371) -> 0 | M376: =($M370/$M371) -> 0 | N376: =($N370/$N371) -> 0 | O376: =($O370/$O371) -> 0 | P376: =($P370/$P371) -> 0 | Q376: =($Q370/$Q371) -> 0 | R376: =($R370/$R371) -> 0 | S376: =($S370/$S371) -> 0 | T376: =($T370/$T371) -> 0 | U376: =($U370/$U371) -> 0 | V376: =($V370/$V371) -> 0 | W376: =($W370/$W371) -> 0 | X376: =($X370/$X371) -> 0 | Y376: =($Y370/$Y371) -> 0
A377: Total % | B377: =SUM($B372:$B376) -> 0 | C377: =SUM($C372:$C376) -> 0 | D377: =SUM($D372:$D376) -> 0 | E377: =SUM($E372:$E376) -> 0 | F377: =SUM($F372:$F376) -> 0 | G377: =SUM($G372:$G376) -> 0 | H377: =SUM($H372:$H376) -> 0 | I377: =SUM($I372:$I376) -> 0 | J377: =SUM($J372:$J376) -> 0 | K377: =SUM($K372:$K376) -> 0 | L377: =SUM($L372:$L376) -> 0 | M377: =SUM($M372:$M376) -> 0 | N377: =SUM($N372:$N376) -> 0 | O377: =SUM($O372:$O376) -> 0 | P377: =SUM($P372:$P376) -> 0 | Q377: =SUM($Q372:$Q376) -> 0 | R377: =SUM($R372:$R376) -> 0 | S377: =SUM($S372:$S376) -> 0 | T377: =SUM($T372:$T376) -> 0 | U377: =SUM($U372:$U376) -> 0 | V377: =SUM($V372:$V376) -> 0 | W377: =SUM($W372:$W376) -> 0 | X377: =SUM($X372:$X376) -> 0 | Y377: =SUM($Y372:$Y376) -> 0
A1355: 1
A1356: 2
A1357: 3
A1358: 4
A1359: 5
B1360: =SUM($B1355:$B1359) -> 0 | C1360: =SUM($C1355:$C1359) -> 0 | D1360: =SUM($D1355:$D1359) -> 0 | E1360: =SUM($E1355:$E1359) -> 0 | F1360: =SUM($F1355:$F1359) -> 0 | G1360: =SUM($G1355:$G1359) -> 0 | H1360: =SUM($H1355:$H1359) -> 0 | I1360: =SUM($I1355:$I1359) -> 0 | J1360: =SUM($J1355:$J1359) -> 0 | K1360: =SUM($K1355:$K1359) -> 0 | L1360: =SUM($L1355:$L1359) -> 0 | M1360: =SUM($M1355:$M1359) -> 0 | N1360: =SUM($N1355:$N1359) -> 0 | O1360: =SUM($O1355:$O1359) -> 0 | P1360: =SUM($P1355:$P1359) -> 0 | Q1360: =SUM($Q1355:$Q1359) -> 0 | R1360: =SUM($R1355:$R1359) -> 0 | S1360: =SUM($S1355:$S1359) -> 0 | T1360: =SUM($T1355:$T1359) -> 0 | U1360: =SUM($U1355:$U1359) -> 0 | V1360: =SUM($V1355:$V1359) -> 0 | W1360: =SUM($W1355:$W1359) -> 0 | X1360: =SUM($X1355:$X1359) -> 0 | Y1360: =SUM($Y1355:$Y1359) -> 0
...

Sheet Por Valoracion (3) Dimension
A1: Dimension 1
A2: Nº de Personas | B2: Percepción emocional | D2: Comprensión emocional | F2: Regulación emocional | H2: Inteligencia emocional
B3: Suma Total | C3: Valoración | D3: Suma Total | E3: Valoración | F3: Suma Total | G3: Valoración | H3: Suma Total | I3: Valoración
A4: Docente 1 | B4: =SUM('Inteligencia emocional'!B5:I5) -> 0 | C4: =IF(B4<=$Q$19,"Bajo",IF(B4<=$Q$20,"Regular",IF(B4<=$Q$21,"Alto",0))) -> 0 | D4: =SUM('Inteligencia emocional'!J5:Q5) -> 0 | E4: =IF(D4<=$AC$19,"Bajo",IF(D4<=$AC$20,"Regular",IF(D4<=$AC$21,"Alto",0))) -> 0 | F4: =SUM('Inteligencia emocional'!R5:Y5) -> 0 | G4: =IF(F4<=$AO$19,"Bajo",IF(F4<=$AO$20,"Regular",IF(F4<=$AO$21,"Alto",0))) -> 0 | H4: =SUM(B4:F4) -> 0 | I4: =IF(H4<=$BA$19,"Bajo",IF(H4<=$BA$20,"Regular",IF(H4<=$BA$21,"Alto",0))) -> 0 | M4: Variable | N4: Inteligencia emocional | Y4: Variable | Z4: Inteligencia emocional | AK4: Variable | AL4: Inteligencia emocional | AW4: Variable | AX4: Inteligencia emocional
A5: Docente 2 | B5: =SUM('Inteligencia emocional'!B6:I6) -> 0 | C5: =IF(B5<=$Q$19,"Bajo",IF(B5<=$Q$20,"Regular",IF(B5<=$Q$21,"Alto",0))) -> 0 | D5: =SUM('Inteligencia emocional'!J6:Q6) -> 0 | E5: =IF(D5<=$AC$19,"Bajo",IF(D5<=$AC$20,"Regular",IF(D5<=$AC$21,"Alto",0))) -> 0 | F5: =SUM('Inteligencia emocional'!R6:Y6) -> 0 | G5: =IF(F5<=$AO$19,"Bajo",IF(F5<=$AO$20,"Regular",IF(F5<=$AO$21,"Alto",0))) -> 0 | H5: =SUM(B5:F5) -> 0 | I5: =IF(H5<=$BA$19,"Bajo",IF(H5<=$BA$20,"Regular",IF(H5<=$BA$21,"Alto",0))) -> 0 | M5: Nombre de la Dimensión | N5: =B2 -> 0 | Y5: Nombre de la Dimensión | Z5: =D2 -> 0 | AK5: Nombre de la Dimensión | AL5: =F2 -> 0
A6: Docente 3 | B6: =SUM('Inteligencia emocional'!B7:I7) -> 0 | C6: =IF(B6<=$Q$19,"Bajo",IF(B6<=$Q$20,"Regular",IF(B6<=$Q$21,"Alto",0))) -> 0 | D6: =SUM('Inteligencia emocional'!J7:Q7) -> 0 | E6: =IF(D6<=$AC$19,"Bajo",IF(D6<=$AC$20,"Regular",IF(D6<=$AC$21,"Alto",0))) -> 0 | F6: =SUM('Inteligencia emocional'!R7:Y7) -> 0 | G6: =IF(F6<=$AO$19,"Bajo",IF(F6<=$AO$20,"Regular",IF(F6<=$AO$21,"Alto",0))) -> 0 | H6: =SUM(B6:F6) -> 0 | I6: =IF(H6<=$BA$19,"Bajo",IF(H6<=$BA$20,"Regular",IF(H6<=$BA$21,"Alto",0))) -> 0 | M6: Cantidad de Escalas Valorativas | N6: 3 | Y6: Cantidad de Escalas Valorativas | Z6: 3 | AK6: Cantidad de Escalas Valorativas | AL6: 3 | AW6: Cantidad de Escalas Valorativas | AX6: 3
A7: Docente 4 | B7: =SUM('Inteligencia emocional'!B8:I8) -> 0 | C7: =IF(B7<=$Q$19,"Bajo",IF(B7<=$Q$20,"Regular",IF(B7<=$Q$21,"Alto",0))) -> 0 | D7: =SUM('Inteligencia emocional'!J8:Q8) -> 0 | E7: =IF(D7<=$AC$19,"Bajo",IF(D7<=$AC$20,"Regular",IF(D7<=$AC$21,"Alto",0))) -> 0 | F7: =SUM('Inteligencia emocional'!R8:Y8) -> 0 | G7: =IF(F7<=$AO$19,"Bajo",IF(F7<=$AO$20,"Regular",IF(F7<=$AO$21,"Alto",0))) -> 0 | H7: =SUM(B7:F7) -> 0 | I7: =IF(H7<=$BA$19,"Bajo",IF(H7<=$BA$20,"Regular",IF(H7<=$BA$21,"Alto",0))) -> 0 | M7: Nº de Peguntas | N7: 8 | Y7: Nº de Peguntas | Z7: 8 | AK7: Nº de Peguntas | AL7: 8 | AW7: Nº de Peguntas | AX7: 24
A8: Docente 5 | B8: =SUM('Inteligencia emocional'!B9:I9) -> 0 | C8: =IF(B8<=$Q$19,"Bajo",IF(B8<=$Q$20,"Regular",IF(B8<=$Q$21,"Alto",0))) -> 0 | D8: =SUM('Inteligencia emocional'!J9:Q9) -> 0 | E8: =IF(D8<=$AC$19,"Bajo",IF(D8<=$AC$20,"Regular",IF(D8<=$AC$21,"Alto",0))) -> 0 | F8: =SUM('Inteligencia emocional'!R9:Y9) -> 0 | G8: =IF(F8<=$AO$19,"Bajo",IF(F8<=$AO$20,"Regular",IF(F8<=$AO$21,"Alto",0))) -> 0 | H8: =SUM(B8:F8) -> 0 | I8: =IF(H8<=$BA$19,"Bajo",IF(H8<=$BA$20,"Regular",IF(H8<=$BA$21,"Alto",0))) -> 0 | M8: Valor Mínimo por item | N8: 1 | Y8: Valor Mínimo por item | Z8: 1 | AK8: Valor Mínimo por item | AL8: 1 | AW8: Valor Mínimo por item | AX8: 1
A9: Docente 6 | B9: =SUM('Inteligencia emocional'!B10:I10) -> 0 | C9: =IF(B9<=$Q$19,"Bajo",IF(B9<=$Q$20,"Regular",IF(B9<=$Q$21,"Alto",0))) -> 0 | D9: =SUM('Inteligencia emocional'!J10:Q10) -> 0 | E9: =IF(D9<=$AC$19,"Bajo",IF(D9<=$AC$20,"Regular",IF(D9<=$AC$21,"Alto",0))) -> 0 | F9: =SUM('Inteligencia emocional'!R10:Y10) -> 0 | G9: =IF(F9<=$AO$19,"Bajo",IF(F9<=$AO$20,"Regular",IF(F9<=$AO$21,"Alto",0))) -> 0 | H9: =SUM(B9:F9) -> 0 | I9: =IF(H9<=$BA$19,"Bajo",IF(H9<=$BA$20,"Regular",IF(H9<=$BA$21,"Alto",0))) -> 0 | M9: Valor Máximo por item | N9: 5 | Y9: Valor Máximo por item | Z9: 5 | AK9: Valor Máximo por item | AL9: 5 | AW9: Valor Máximo por item | AX9: 5
A10: Docente 7 | B10: =SUM('Inteligencia emocional'!B11:I11) -> 0 | C10: =IF(B10<=$Q$19,"Bajo",IF(B10<=$Q$20,"Regular",IF(B10<=$Q$21,"Alto",0))) -> 0 | D10: =SUM('Inteligencia emocional'!J11:Q11) -> 0 | E10: =IF(D10<=$AC$19,"Bajo",IF(D10<=$AC$20,"Regular",IF(D10<=$AC$21,"Alto",0))) -> 0 | F10: =SUM('Inteligencia emocional'!R11:Y11) -> 0 | G10: =IF(F10<=$AO$19,"Bajo",IF(F10<=$AO$20,"Regular",IF(F10<=$AO$21,"Alto",0))) -> 0 | H10: =SUM(B10:F10) -> 0 | I10: =IF(H10<=$BA$19,"Bajo",IF(H10<=$BA$20,"Regular",IF(H10<=$BA$21,"Alto",0))) -> 0 | M10: Máximo | N10: =N7*N9 -> 0 | Y10: Máximo | Z10: =Z7*Z9 -> 0 | AK10: Máximo | AL10: =AL7*AL9 -> 0 | AW10: Máximo | AX10: =AX7*AX9 -> 0
A11: Docente 8 | B11: =SUM('Inteligencia emocional'!B12:I12) -> 0 | C11: =IF(B11<=$Q$19,"Bajo",IF(B11<=$Q$20,"Regular",IF(B11<=$Q$21,"Alto",0))) -> 0 | D11: =SUM('Inteligencia emocional'!J12:Q12) -> 0 | E11: =IF(D11<=$AC$19,"Bajo",IF(D11<=$AC$20,"Regular",IF(D11<=$AC$21,"Alto",0))) -> 0 | F11: =SUM('Inteligencia emocional'!R12:Y12) -> 0 | G11: =IF(F11<=$AO$19,"Bajo",IF(F11<=$AO$20,"Regular",IF(F11<=$AO$21,"Alto",0))) -> 0 | H11: =SUM(B11:F11) -> 0 | I11: =IF(H11<=$BA$19,"Bajo",IF(H11<=$BA$20,"Regular",IF(H11<=$BA$21,"Alto",0))) -> 0 | M11: Mínimo | N11: =N8*N7 -> 0 | Y11: Mínimo | Z11: =Z8*Z7 -> 0 | AK11: Mínimo | AL11: =AL8*AL7 -> 0 | AW11: Mínimo | AX11: =AX8*AX7 -> 0
A12: Docente 9 | B12: =SUM('Inteligencia emocional'!B13:I13) -> 0 | C12: =IF(B12<=$Q$19,"Bajo",IF(B12<=$Q$20,"Regular",IF(B12<=$Q$21,"Alto",0))) -> 0 | D12: =SUM('Inteligencia emocional'!J13:Q13) -> 0 | E12: =IF(D12<=$AC$19,"Bajo",IF(D12<=$AC$20,"Regular",IF(D12<=$AC$21,"Alto",0))) -> 0 | F12: =SUM('Inteligencia emocional'!R13:Y13) -> 0 | G12: =IF(F12<=$AO$19,"Bajo",IF(F12<=$AO$20,"Regular",IF(F12<=$AO$21,"Alto",0))) -> 0 | H12: =SUM(B12:F12) -> 0 | I12: =IF(H12<=$BA$19,"Bajo",IF(H12<=$BA$20,"Regular",IF(H12<=$BA$21,"Alto",0))) -> 0 | M12: Rango | N12: =N10-N11 -> 0 | Y12: Rango | Z12: =Z10-Z11 -> 0 | AK12: Rango | AL12: =AL10-AL11 -> 0 | AW12: Rango | AX12: =AX10-AX11 -> 0
A13: Docente 10 | B13: =SUM('Inteligencia emocional'!B14:I14) -> 0 | C13: =IF(B13<=$Q$19,"Bajo",IF(B13<=$Q$20,"Regular",IF(B13<=$Q$21,"Alto",0))) -> 0 | D13: =SUM('Inteligencia emocional'!J14:Q14) -> 0 | E13: =IF(D13<=$AC$19,"Bajo",IF(D13<=$AC$20,"Regular",IF(D13<=$AC$21,"Alto",0))) -> 0 | F13: =SUM('Inteligencia emocional'!R14:Y14) -> 0 | G13: =IF(F13<=$AO$19,"Bajo",IF(F13<=$AO$20,"Regular",IF(F13<=$AO$21,"Alto",0))) -> 0 | H13: =SUM(B13:F13) -> 0 | I13: =IF(H13<=$BA$19,"Bajo",IF(H13<=$BA$20,"Regular",IF(H13<=$BA$21,"Alto",0))) -> 0 | M13: Amplitud del Intervalo | N13: =ROUND(N12/N6,0) -> 0 | Y13: Amplitud del Intervalo | Z13: =ROUND(Z12/Z6,0) -> 0 | AK13: Amplitud del Intervalo | AL13: =ROUND(AL12/AL6,0) -> 0 | AW13: Amplitud del Intervalo | AX13: =ROUND(AX12/AX6,0) -> 0
A14: Docente 11 | B14: =SUM('Inteligencia emocional'!B15:I15) -> 0 | C14: =IF(B14<=$Q$19,"Bajo",IF(B14<=$Q$20,"Regular",IF(B14<=$Q$21,"Alto",0))) -> 0 | D14: =SUM('Inteligencia emocional'!J15:Q15) -> 0 | E14: =IF(D14<=$AC$19,"Bajo",IF(D14<=$AC$20,"Regular",IF(D14<=$AC$21,"Alto",0))) -> 0 | F14: =SUM('Inteligencia emocional'!R15:Y15) -> 0 | G14: =IF(F14<=$AO$19,"Bajo",IF(F14<=$AO$20,"Regular",IF(F14<=$AO$21,"Alto",0))) -> 0 | H14: =SUM(B14:F14) -> 0 | I14: =IF(H14<=$BA$19,"Bajo",IF(H14<=$BA$20,"Regular",IF(H14<=$BA$21,"Alto",0))) -> 0
A15: Docente 12 | B15: =SUM('Inteligencia emocional'!B16:I16) -> 0 | C15: =IF(B15<=$Q$19,"Bajo",IF(B15<=$Q$20,"Regular",IF(B15<=$Q$21,"Alto",0))) -> 0 | D15: =SUM('Inteligencia emocional'!J16:Q16) -> 0 | E15: =IF(D15<=$AC$19,"Bajo",IF(D15<=$AC$20,"Regular",IF(D15<=$AC$21,"Alto",0))) -> 0 | F15: =SUM('Inteligencia emocional'!R16:Y16) -> 0 | G15: =IF(F15<=$AO$19,"Bajo",IF(F15<=$AO$20,"Regular",IF(F15<=$AO$21,"Alto",0))) -> 0 | H15: =SUM(B15:F15) -> 0 | I15: =IF(H15<=$BA$19,"Bajo",IF(H15<=$BA$20,"Regular",IF(H15<=$BA$21,"Alto",0))) -> 0 | O15: Tabla 1 | AA15: Tabla 2 | AM15: Tabla 3 | AY15: Tabla 4
A16: Docente 13 | B16: =SUM('Inteligencia emocional'!B17:I17) -> 0 | C16: =IF(B16<=$Q$19,"Bajo",IF(B16<=$Q$20,"Regular",IF(B16<=$Q$21,"Alto",0))) -> 0 | D16: =SUM('Inteligencia emocional'!J17:Q17) -> 0 | E16: =IF(D16<=$AC$19,"Bajo",IF(D16<=$AC$20,"Regular",IF(D16<=$AC$21,"Alto",0))) -> 0 | F16: =SUM('Inteligencia emocional'!R17:Y17) -> 0 | G16: =IF(F16<=$AO$19,"Bajo",IF(F16<=$AO$20,"Regular",IF(F16<=$AO$21,"Alto",0))) -> 0 | H16: =SUM(B16:F16) -> 0 | I16: =IF(H16<=$BA$19,"Bajo",IF(H16<=$BA$20,"Regular",IF(H16<=$BA$21,"Alto",0))) -> 0 | O16: =N5 -> 0 | AA16: =Z5 -> 0 | AM16: =AL5 -> 0 | AY16: =AX4 -> 0
A17: Docente 14 | B17: =SUM('Inteligencia emocional'!B18:I18) -> 0 | C17: =IF(B17<=$Q$19,"Bajo",IF(B17<=$Q$20,"Regular",IF(B17<=$Q$21,"Alto",0))) -> 0 | D17: =SUM('Inteligencia emocional'!J18:Q18) -> 0 | E17: =IF(D17<=$AC$19,"Bajo",IF(D17<=$AC$20,"Regular",IF(D17<=$AC$21,"Alto",0))) -> 0 | F17: =SUM('Inteligencia emocional'!R18:Y18) -> 0 | G17: =IF(F17<=$AO$19,"Bajo",IF(F17<=$AO$20,"Regular",IF(F17<=$AO$21,"Alto",0))) -> 0 | H17: =SUM(B17:F17) -> 0 | I17: =IF(H17<=$BA$19,"Bajo",IF(H17<=$BA$20,"Regular",IF(H17<=$BA$21,"Alto",0))) -> 0 | O17: Calificación | P17: Rango | R17: Frec. | S17: % | AA17: Calificación | AB17: Rango | AD17: Frec. | AE17: % | AM17: Calificación | AN17: Rango | AP17: Frec. | AQ17: % | AY17: Calificación | AZ17: Rango | BB17: Frec. | BC17: %
A18: Docente 15 | B18: =SUM('Inteligencia emocional'!B19:I19) -> 0 | C18: =IF(B18<=$Q$19,"Bajo",IF(B18<=$Q$20,"Regular",IF(B18<=$Q$21,"Alto",0))) -> 0 | D18: =SUM('Inteligencia emocional'!J19:Q19) -> 0 | E18: =IF(D18<=$AC$19,"Bajo",IF(D18<=$AC$20,"Regular",IF(D18<=$AC$21,"Alto",0))) -> 0 | F18: =SUM('Inteligencia emocional'!R19:Y19) -> 0 | G18: =IF(F18<=$AO$19,"Bajo",IF(F18<=$AO$20,"Regular",IF(F18<=$AO$21,"Alto",0))) -> 0 | H18: =SUM(B18:F18) -> 0 | I18: =IF(H18<=$BA$19,"Bajo",IF(H18<=$BA$20,"Regular",IF(H18<=$BA$21,"Alto",0))) -> 0 | P18: Desde | Q18: Hasta | AB18: Desde | AC18: Hasta | AN18: Desde | AO18: Hasta | AZ18: Desde | BA18: Hasta
A19: Docente 16 | B19: =SUM('Inteligencia emocional'!B20:I20) -> 0 | C19: =IF(B19<=$Q$19,"Bajo",IF(B19<=$Q$20,"Regular",IF(B19<=$Q$21,"Alto",0))) -> 0 | D19: =SUM('Inteligencia emocional'!J20:Q20) -> 0 | E19: =IF(D19<=$AC$19,"Bajo",IF(D19<=$AC$20,"Regular",IF(D19<=$AC$21,"Alto",0))) -> 0 | F19: =SUM('Inteligencia emocional'!R20:Y20) -> 0 | G19: =IF(F19<=$AO$19,"Bajo",IF(F19<=$AO$20,"Regular",IF(F19<=$AO$21,"Alto",0))) -> 0 | H19: =SUM(B19:F19) -> 0 | I19: =IF(H19<=$BA$19,"Bajo",IF(H19<=$BA$20,"Regular",IF(H19<=$BA$21,"Alto",0))) -> 0 | O19: Bajo | P19: =N11 -> 0 | Q19: =P19+N13 -> 0 | R19: =COUNTIF($C$4:$C$358,$O19) -> 0 | S19: =R19/R22 -> 0 | AA19: Bajo | AB19: =Z11 -> 0 | AC19: =AB19+Z13 -> 0 | AD19: =COUNTIF($E$4:$E$358,$AA19) -> 0 | AE19: =AD19/AD22 -> 0 | AM19: Bajo | AN19: =AL11 -> 0 | AO19: =AN19+AL13 -> 0 | AP19: =COUNTIF($G$4:$G$358,$AM19) -> 0 | AQ19: =AP19/AP22 -> 0 | AY19: Bajo | AZ19: =AX11 -> 0 | BA19: =AZ19+AX13 - 1 -> 0 | BB19: =COUNTIF($I$4:$I$358,$AY19) -> 0 | BC19: =BB19/BB22 -> 0
A20: Docente 17 | B20: =SUM('Inteligencia emocional'!B21:I21) -> 0 | C20: =IF(B20<=$Q$19,"Bajo",IF(B20<=$Q$20,"Regular",IF(B20<=$Q$21,"Alto",0))) -> 0 | D20: =SUM('Inteligencia emocional'!J21:Q21) -> 0 | E20: =IF(D20<=$AC$19,"Bajo",IF(D20<=$AC$20,"Regular",IF(D20<=$AC$21,"Alto",0))) -> 0 | F20: =SUM('Inteligencia emocional'!R21:Y21) -> 0 | G20: =IF(F20<=$AO$19,"Bajo",IF(F20<=$AO$20,"Regular",IF(F20<=$AO$21,"Alto",0))) -> 0 | H20: =SUM(B20:F20) -> 0 | I20: =IF(H20<=$BA$19,"Bajo",IF(H20<=$BA$20,"Regular",IF(H20<=$BA$21,"Alto",0))) -> 0 | O20: Regular | P20: =Q19+ 1 -> 0 | Q20: =P20+N13 -> 0 | R20: =COUNTIF($C$4:$C$358,$O20) -> 0 | S20: =R20/R22 -> 0 | AA20: Regular | AB20: =AC19+ 1 -> 0 | AC20: =AB20+Z13 -> 0 | AD20: =COUNTIF($E$4:$E$358,$AA20) -> 0 | AE20: =AD20/AD22 -> 0 | AM20: Regular | AN20: =AO19+ 1 -> 0 | AO20: =AN20+AL13 -> 0 | AP20: =COUNTIF($G$4:$G$358,$AM20) -> 0 | AQ20: =AP20/AP22 -> 0 | AY20: Regular | AZ20: =BA19+ 1 -> 0 | BA20: =AZ20+AX13 - 1 -> 0 | BB20: =COUNTIF($I$4:$I$358,$AY20) -> 0 | BC20: =BB20/BB22 -> 0
A21: Docente 18 | B21: =SUM('Inteligencia emocional'!B22:I22) -> 0 | C21: =IF(B21<=$Q$19,"Bajo",IF(B21<=$Q$20,"Regular",IF(B21<=$Q$21,"Alto",0))) -> 0 | D21: =SUM('Inteligencia emocional'!J22:Q22) -> 0 | E21: =IF(D21<=$AC$19,"Bajo",IF(D21<=$AC$20,"Regular",IF(D21<=$AC$21,"Alto",0))) -> 0 | F21: =SUM('Inteligencia emocional'!R22:Y22) -> 0 | G21: =IF(F21<=$AO$19,"Bajo",IF(F21<=$AO$20,"Regular",IF(F21<=$AO$21,"Alto",0))) -> 0 | H21: =SUM(B21:F21) -> 0 | I21: =IF(H21<=$BA$19,"Bajo",IF(H21<=$BA$20,"Regular",IF(H21<=$BA$21,"Alto",0))) -> 0 | O21: Alto | P21: =Q20+ 1 -> 0 | Q21: =N10 -> 0 | R21: =COUNTIF($C$4:$C$358,$O21) -> 0 | S21: =R21/R22 -> 0 | AA21: Alto | AB21: =AC20+ 1 -> 0 | AC21: =Z10 -> 0 | AD21: =COUNTIF($E$4:$E$358,$AA21) -> 0 | AE21: =AD21/AD22 -> 0 | AM21: Alto | AN21: =AO20+ 1 -> 0 | AO21: =AL10 -> 0 | AP21: =COUNTIF($G$4:$G$358,$AM21) -> 0 | AQ21: =AP21/AP22 -> 0 | AY21: Alto | AZ21: =BA20+ 1 -> 0 | BA21: =AX10 -> 0 | BB21: =COUNTIF($I$4:$I$358,$AY21) -> 0 | BC21: =BB21/BB22 -> 0
A22: Docente 19 | B22: =SUM('Inteligencia emocional'!B23:I23) -> 0 | C22: =IF(B22<=$Q$19,"Bajo",IF(B22<=$Q$20,"Regular",IF(B22<=$Q$21,"Alto",0))) -> 0 | D22: =SUM('Inteligencia emocional'!J23:Q23) -> 0 | E22: =IF(D22<=$AC$19,"Bajo",IF(D22<=$AC$20,"Regular",IF(D22<=$AC$21,"Alto",0))) -> 0 | F22: =SUM('Inteligencia emocional'!R23:Y23) -> 0 | G22: =IF(F22<=$AO$19,"Bajo",IF(F22<=$AO$20,"Regular",IF(F22<=$AO$21,"Alto",0))) -> 0 | H22: =SUM(B22:F22) -> 0 | I22: =IF(H22<=$BA$19,"Bajo",IF(H22<=$BA$20,"Regular",IF(H22<=$BA$21,"Alto",0))) -> 0 | O22: Total | R22: =SUM(R19:R21) -> 0 | S22: =SUM(S19:S21) -> 0 | AA22: Total | AD22: =SUM(AD19:AD21) -> 0 | AE22: =SUM(AE19:AE21) -> 0 | AM22: Total | AP22: =SUM(AP19:AP21) -> 0 | AQ22: =SUM(AQ19:AQ21) -> 0 | AY22: Total | BB22: =SUM(BB19:BB21) -> 0 | BC22: =SUM(BC19:BC21) -> 0
A23: Docente 20 | B23: =SUM('Inteligencia emocional'!B24:I24) -> 0 | C23: =IF(B23<=$Q$19,"Bajo",IF(B23<=$Q$20,"Regular",IF(B23<=$Q$21,"Alto",0))) -> 0 | D23: =SUM('Inteligencia emocional'!J24:Q24) -> 0 | E23: =IF(D23<=$AC$19,"Bajo",IF(D23<=$AC$20,"Regular",IF(D23<=$AC$21,"Alto",0))) -> 0 | F23: =SUM('Inteligencia emocional'!R24:Y24) -> 0 | G23: =IF(F23<=$AO$19,"Bajo",IF(F23<=$AO$20,"Regular",IF(F23<=$AO$21,"Alto",0))) -> 0 | H23: =SUM(B23:F23) -> 0 | I23: =IF(H23<=$BA$19,"Bajo",IF(H23<=$BA$20,"Regular",IF(H23<=$BA$21,"Alto",0))) -> 0 | O23: Fuente: Encuesta aplicada | AA23: Fuente: Encuesta aplicada | AM23: Fuente: Encuesta aplicada | AY23: Fuente: Encuesta aplicada
A24: Docente 21 | B24: =SUM('Inteligencia emocional'!B25:I25) -> 0 | C24: =IF(B24<=$Q$19,"Bajo",IF(B24<=$Q$20,"Regular",IF(B24<=$Q$21,"Alto",0))) -> 0 | D24: =SUM('Inteligencia emocional'!J25:Q25) -> 0 | E24: =IF(D24<=$AC$19,"Bajo",IF(D24<=$AC$20,"Regular",IF(D24<=$AC$21,"Alto",0))) -> 0 | F24: =SUM('Inteligencia emocional'!R25:Y25) -> 0 | G24: =IF(F24<=$AO$19,"Bajo",IF(F24<=$AO$20,"Regular",IF(F24<=$AO$21,"Alto",0))) -> 0 | H24: =SUM(B24:F24) -> 0 | I24: =IF(H24<=$BA$19,"Bajo",IF(H24<=$BA$20,"Regular",IF(H24<=$BA$21,"Alto",0))) -> 0 | O24: Elaboración: Propia | AA24: Elaboración: Propia | AM24: Elaboración: Propia | AY24: Elaboración: Propia
A25: Docente 22 | B25: =SUM('Inteligencia emocional'!B26:I26) -> 0 | C25: =IF(B25<=$Q$19,"Bajo",IF(B25<=$Q$20,"Regular",IF(B25<=$Q$21,"Alto",0))) -> 0 | D25: =SUM('Inteligencia emocional'!J26:Q26) -> 0 | E25: =IF(D25<=$AC$19,"Bajo",IF(D25<=$AC$20,"Regular",IF(D25<=$AC$21,"Alto",0))) -> 0 | F25: =SUM('Inteligencia emocional'!R26:Y26) -> 0 | G25: =IF(F25<=$AO$19,"Bajo",IF(F25<=$AO$20,"Regular",IF(F25<=$AO$21,"Alto",0))) -> 0 | H25: =SUM(B25:F25) -> 0 | I25: =IF(H25<=$BA$19,"Bajo",IF(H25<=$BA$20,"Regular",IF(H25<=$BA$21,"Alto",0))) -> 0
A26: Docente 23 | B26: =SUM('Inteligencia emocional'!B27:I27) -> 0 | C26: =IF(B26<=$Q$19,"Bajo",IF(B26<=$Q$20,"Regular",IF(B26<=$Q$21,"Alto",0))) -> 0 | D26: =SUM('Inteligencia emocional'!J27:Q27) -> 0 | E26: =IF(D26<=$AC$19,"Bajo",IF(D26<=$AC$20,"Regular",IF(D26<=$AC$21,"Alto",0))) -> 0 | F26: =SUM('Inteligencia emocional'!R27:Y27) -> 0 | G26: =IF(F26<=$AO$19,"Bajo",IF(F26<=$AO$20,"Regular",IF(F26<=$AO$21,"Alto",0))) -> 0 | H26: =SUM(B26:F26) -> 0 | I26: =IF(H26<=$BA$19,"Bajo",IF(H26<=$BA$20,"Regular",IF(H26<=$BA$21,"Alto",0))) -> 0
A27: Docente 24 | B27: =SUM('Inteligencia emocional'!B28:I28) -> 0 | C27: =IF(B27<=$Q$19,"Bajo",IF(B27<=$Q$20,"Regular",IF(B27<=$Q$21,"Alto",0))) -> 0 | D27: =SUM('Inteligencia emocional'!J28:Q28) -> 0 | E27: =IF(D27<=$AC$19,"Bajo",IF(D27<=$AC$20,"Regular",IF(D27<=$AC$21,"Alto",0))) -> 0 | F27: =SUM('Inteligencia emocional'!R28:Y28) -> 0 | G27: =IF(F27<=$AO$19,"Bajo",IF(F27<=$AO$20,"Regular",IF(F27<=$AO$21,"Alto",0))) -> 0 | H27: =SUM(B27:F27) -> 0 | I27: =IF(H27<=$BA$19,"Bajo",IF(H27<=$BA$20,"Regular",IF(H27<=$BA$21,"Alto",0))) -> 0
A28: Docente 25 | B28: =SUM('Inteligencia emocional'!B29:I29) -> 0 | C28: =IF(B28<=$Q$19,"Bajo",IF(B28<=$Q$20,"Regular",IF(B28<=$Q$21,"Alto",0))) -> 0 | D28: =SUM('Inteligencia emocional'!J29:Q29) -> 0 | E28: =IF(D28<=$AC$19,"Bajo",IF(D28<=$AC$20,"Regular",IF(D28<=$AC$21,"Alto",0))) -> 0 | F28: =SUM('Inteligencia emocional'!R29:Y29) -> 0 | G28: =IF(F28<=$AO$19,"Bajo",IF(F28<=$AO$20,"Regular",IF(F28<=$AO$21,"Alto",0))) -> 0 | H28: =SUM(B28:F28) -> 0 | I28: =IF(H28<=$BA$19,"Bajo",IF(H28<=$BA$20,"Regular",IF(H28<=$BA$21,"Alto",0))) -> 0
A29: Docente 26 | B29: =SUM('Inteligencia emocional'!B30:I30) -> 0 | C29: =IF(B29<=$Q$19,"Bajo",IF(B29<=$Q$20,"Regular",IF(B29<=$Q$21,"Alto",0))) -> 0 | D29: =SUM('Inteligencia emocional'!J30:Q30) -> 0 | E29: =IF(D29<=$AC$19,"Bajo",IF(D29<=$AC$20,"Regular",IF(D29<=$AC$21,"Alto",0))) -> 0 | F29: =SUM('Inteligencia emocional'!R30:Y30) -> 0 | G29: =IF(F29<=$AO$19,"Bajo",IF(F29<=$AO$20,"Regular",IF(F29<=$AO$21,"Alto",0))) -> 0 | H29: =SUM(B29:F29) -> 0 | I29: =IF(H29<=$BA$19,"Bajo",IF(H29<=$BA$20,"Regular",IF(H29<=$BA$21,"Alto",0))) -> 0
A30: Docente 27 | B30: =SUM('Inteligencia emocional'!B31:I31) -> 0 | C30: =IF(B30<=$Q$19,"Bajo",IF(B30<=$Q$20,"Regular",IF(B30<=$Q$21,"Alto",0))) -> 0 | D30: =SUM('Inteligencia emocional'!J31:Q31) -> 0 | E30: =IF(D30<=$AC$19,"Bajo",IF(D30<=$AC$20,"Regular",IF(D30<=$AC$21,"Alto",0))) -> 0 | F30: =SUM('Inteligencia emocional'!R31:Y31) -> 0 | G30: =IF(F30<=$AO$19,"Bajo",IF(F30<=$AO$20,"Regular",IF(F30<=$AO$21,"Alto",0))) -> 0 | H30: =SUM(B30:F30) -> 0 | I30: =IF(H30<=$BA$19,"Bajo",IF(H30<=$BA$20,"Regular",IF(H30<=$BA$21,"Alto",0))) -> 0
A31: Docente 28 | B31: =SUM('Inteligencia emocional'!B32:I32) -> 0 | C31: =IF(B31<=$Q$19,"Bajo",IF(B31<=$Q$20,"Regular",IF(B31<=$Q$21,"Alto",0))) -> 0 | D31: =SUM('Inteligencia emocional'!J32:Q32) -> 0 | E31: =IF(D31<=$AC$19,"Bajo",IF(D31<=$AC$20,"Regular",IF(D31<=$AC$21,"Alto",0))) -> 0 | F31: =SUM('Inteligencia emocional'!R32:Y32) -> 0 | G31: =IF(F31<=$AO$19,"Bajo",IF(F31<=$AO$20,"Regular",IF(F31<=$AO$21,"Alto",0))) -> 0 | H31: =SUM(B31:F31) -> 0 | I31: =IF(H31<=$BA$19,"Bajo",IF(H31<=$BA$20,"Regular",IF(H31<=$BA$21,"Alto",0))) -> 0
A32: Docente 29 | B32: =SUM('Inteligencia emocional'!B33:I33) -> 0 | C32: =IF(B32<=$Q$19,"Bajo",IF(B32<=$Q$20,"Regular",IF(B32<=$Q$21,"Alto",0))) -> 0 | D32: =SUM('Inteligencia emocional'!J33:Q33) -> 0 | E32: =IF(D32<=$AC$19,"Bajo",IF(D32<=$AC$20,"Regular",IF(D32<=$AC$21,"Alto",0))) -> 0 | F32: =SUM('Inteligencia emocional'!R33:Y33) -> 0 | G32: =IF(F32<=$AO$19,"Bajo",IF(F32<=$AO$20,"Regular",IF(F32<=$AO$21,"Alto",0))) -> 0 | H32: =SUM(B32:F32) -> 0 | I32: =IF(H32<=$BA$19,"Bajo",IF(H32<=$BA$20,"Regular",IF(H32<=$BA$21,"Alto",0))) -> 0
A33: Docente 30 | B33: =SUM('Inteligencia emocional'!B34:I34) -> 0 | C33: =IF(B33<=$Q$19,"Bajo",IF(B33<=$Q$20,"Regular",IF(B33<=$Q$21,"Alto",0))) -> 0 | D33: =SUM('Inteligencia emocional'!J34:Q34) -> 0 | E33: =IF(D33<=$AC$19,"Bajo",IF(D33<=$AC$20,"Regular",IF(D33<=$AC$21,"Alto",0))) -> 0 | F33: =SUM('Inteligencia emocional'!R34:Y34) -> 0 | G33: =IF(F33<=$AO$19,"Bajo",IF(F33<=$AO$20,"Regular",IF(F33<=$AO$21,"Alto",0))) -> 0 | H33: =SUM(B33:F33) -> 0 | I33: =IF(H33<=$BA$19,"Bajo",IF(H33<=$BA$20,"Regular",IF(H33<=$BA$21,"Alto",0))) -> 0
A34: Docente 31 | B34: =SUM('Inteligencia emocional'!B35:I35) -> 0 | C34: =IF(B34<=$Q$19,"Bajo",IF(B34<=$Q$20,"Regular",IF(B34<=$Q$21,"Alto",0))) -> 0 | D34: =SUM('Inteligencia emocional'!J35:Q35) -> 0 | E34: =IF(D34<=$AC$19,"Bajo",IF(D34<=$AC$20,"Regular",IF(D34<=$AC$21,"Alto",0))) -> 0 | F34: =SUM('Inteligencia emocional'!R35:Y35) -> 0 | G34: =IF(F34<=$AO$19,"Bajo",IF(F34<=$AO$20,"Regular",IF(F34<=$AO$21,"Alto",0))) -> 0 | H34: =SUM(B34:F34) -> 0 | I34: =IF(H34<=$BA$19,"Bajo",IF(H34<=$BA$20,"Regular",IF(H34<=$BA$21,"Alto",0))) -> 0
A35: Docente 32 | B35: =SUM('Inteligencia emocional'!B36:I36) -> 0 | C35: =IF(B35<=$Q$19,"Bajo",IF(B35<=$Q$20,"Regular",IF(B35<=$Q$21,"Alto",0))) -> 0 | D35: =SUM('Inteligencia emocional'!J36:Q36) -> 0 | E35: =IF(D35<=$AC$19,"Bajo",IF(D35<=$AC$20,"Regular",IF(D35<=$AC$21,"Alto",0))) -> 0 | F35: =SUM('Inteligencia emocional'!R36:Y36) -> 0 | G35: =IF(F35<=$AO$19,"Bajo",IF(F35<=$AO$20,"Regular",IF(F35<=$AO$21,"Alto",0))) -> 0 | H35: =SUM(B35:F35) -> 0 | I35: =IF(H35<=$BA$19,"Bajo",IF(H35<=$BA$20,"Regular",IF(H35<=$BA$21,"Alto",0))) -> 0
A36: Docente 33 | B36: =SUM('Inteligencia emocional'!B37:I37) -> 0 | C36: =IF(B36<=$Q$19,"Bajo",IF(B36<=$Q$20,"Regular",IF(B36<=$Q$21,"Alto",0))) -> 0 | D36: =SUM('Inteligencia emocional'!J37:Q37) -> 0 | E36: =IF(D36<=$AC$19,"Bajo",IF(D36<=$AC$20,"Regular",IF(D36<=$AC$21,"Alto",0))) -> 0 | F36: =SUM('Inteligencia emocional'!R37:Y37) -> 0 | G36: =IF(F36<=$AO$19,"Bajo",IF(F36<=$AO$20,"Regular",IF(F36<=$AO$21,"Alto",0))) -> 0 | H36: =SUM(B36:F36) -> 0 | I36: =IF(H36<=$BA$19,"Bajo",IF(H36<=$BA$20,"Regular",IF(H36<=$BA$21,"Alto",0))) -> 0
... A42: Docente 39 | B42: =SUM('Inteligencia emocional'!B43:I43) -> 0 | C42: =IF(B42<=$Q$19,"Bajo",IF(B42<=$Q$20,"Regular",IF(B42<=$Q$21,"Alto",0))) -> 0 | D42: =SUM('Inteligencia emocional'!J43:Q43) -> 0 | E42: =IF(D42<=$AC$19,"Bajo",IF(D42<=$AC$20,"Regular",IF(D42<=$AC$21,"Alto",0))) -> 0 | F42: =SUM('Inteligencia emocional'!R43:Y43) -> 0 | G42: =IF(F42<=$AO$19,"Bajo",IF(F42<=$AO$20,"Regular",IF(F42<=$AO$21,"Alto",0))) -> 0 | H42: =SUM(B42:F42) -> 0 | I42: =IF(H42<=$BA$19,"Bajo",IF(H42<=$BA$20,"Regular",IF(H42<=$BA$21,"Alto",0))) -> 0
A43: Docente 40 | B43: =SUM('Inteligencia emocional'!B44:I44) -> 0 | C43: =IF(B43<=$Q$19,"Bajo",IF(B43<=$Q$20,"Regular",IF(B43<=$Q$21,"Alto",0))) -> 0 | D43: =SUM('Inteligencia emocional'!J44:Q44) -> 0 | E43: =IF(D43<=$AC$19,"Bajo",IF(D43<=$AC$20,"Regular",IF(D43<=$AC$21,"Alto",0))) -> 0 | F43: =SUM('Inteligencia emocional'!R44:Y44) -> 0 | G43: =IF(F43<=$AO$19,"Bajo",IF(F43<=$AO$20,"Regular",IF(F43<=$AO$21,"Alto",0))) -> 0 | H43: =SUM(B43:F43) -> 0 | I43: =IF(H43<=$BA$19,"Bajo",IF(H43<=$BA$20,"Regular",IF(H43<=$BA$21,"Alto",0))) -> 0 | O43: Figura.1 | AA43: Figura.2 | AM43: Figura.3 | AY43: Figura.4
A44: Docente 41 | B44: =SUM('Inteligencia emocional'!B45:I45) -> 0 | C44: =IF(B44<=$Q$19,"Bajo",IF(B44<=$Q$20,"Regular",IF(B44<=$Q$21,"Alto",0))) -> 0 | D44: =SUM('Inteligencia emocional'!J45:Q45) -> 0 | E44: =IF(D44<=$AC$19,"Bajo",IF(D44<=$AC$20,"Regular",IF(D44<=$AC$21,"Alto",0))) -> 0 | F44: =SUM('Inteligencia emocional'!R45:Y45) -> 0 | G44: =IF(F44<=$AO$19,"Bajo",IF(F44<=$AO$20,"Regular",IF(F44<=$AO$21,"Alto",0))) -> 0 | H44: =SUM(B44:F44) -> 0 | I44: =IF(H44<=$BA$19,"Bajo",IF(H44<=$BA$20,"Regular",IF(H44<=$BA$21,"Alto",0))) -> 0 | O44: Percepción emocional | AA44: Comprensión emocional | AM44: Regulación emocional | AY44: Percepción emocional
A45: Docente 42 | B45: =SUM('Inteligencia emocional'!B46:I46) -> 0 | C45: =IF(B45<=$Q$19,"Bajo",IF(B45<=$Q$20,"Regular",IF(B45<=$Q$21,"Alto",0))) -> 0 | D45: =SUM('Inteligencia emocional'!J46:Q46) -> 0 | E45: =IF(D45<=$AC$19,"Bajo",IF(D45<=$AC$20,"Regular",IF(D45<=$AC$21,"Alto",0))) -> 0 | F45: =SUM('Inteligencia emocional'!R46:Y46) -> 0 | G45: =IF(F45<=$AO$19,"Bajo",IF(F45<=$AO$20,"Regular",IF(F45<=$AO$21,"Alto",0))) -> 0 | H45: =SUM(B45:F45) -> 0 | I45: =IF(H45<=$BA$19,"Bajo",IF(H45<=$BA$20,"Regular",IF(H45<=$BA$21,"Alto",0))) -> 0
...

Sheet Tabulacion por item
D4: Item 1 | M4: Item 2 | V4: Item 3 | AE4: Item 4 | AN4: Item 5 | AW4: Item 6 | BF4: Item 7 | BO4: Item 8 | BX4: Item 9 | CG4: Item 10 | CP4: Item 11 | CY4: Item 12 | DH4: Item 13 | DQ4: Item 14 | DZ4: Item 15 | EI4: Item 16 | ER4: Item 17 | FA4: Item 18 | FJ4: Item 19 | FS4: Item 20 | GB4: Item 21 | GK4: Item 22 | GT4: Item 23 | HC4: Item 24
D5: Tabla 1 | M5: Tabla 2 | V5: Tabla 3 | AE5: Tabla 4 | AN5: Tabla 5 | AW5: Tabla 6 | BF5: Tabla 7 | BO5: Tabla 8 | BX5: Tabla 9 | CG5: Tabla 10 | CP5: Tabla 11 | CY5: Tabla 12 | DH5: Tabla 13 | DQ5: Tabla 14 | DZ5: Tabla 15 | EI5: Tabla 16 | ER5: Tabla 17 | FA5: Tabla 18 | FJ5: Tabla 19 | FS5: Tabla 20 | GB5: Tabla 21 | GK5: Tabla 22 | GT5: Tabla 23 | HC5: Tabla 24
D6: .
E7: Frec. | F7: % | N7: Frec. | O7: % | W7: Frec. | X7: % | AF7: Frec. | AG7: % | AO7: Frec. | AP7: % | AX7: Frec. | AY7: % | BG7: Frec. | BH7: % | BP7: Frec. | BQ7: % | BY7: Frec. | BZ7: % | CH7: Frec. | CI7: % | CQ7: Frec. | CR7: % | CZ7: Frec. | DA7: % | DI7: Frec. | DJ7: % | DR7: Frec. | DS7: % | EA7: Frec. | EB7: % | EJ7: Frec. | EK7: % | ES7: Frec. | ET7: % | FB7: Frec. | FC7: % | FK7: Frec. | FL7: % | FT7: Frec. | FU7: % | GC7: Frec. | GD7: % | GL7: Frec. | GM7: % | GU7: Frec. | GV7: % | HD7: Frec. | HE7: %
D8: =('Inteligencia emocional'!A366) -> 0 | E8: =('Inteligencia emocional'!B366) -> 0 | F8: =('Inteligencia emocional'!B372) -> 0 | M8: =('Inteligencia emocional'!A366) -> 0 | N8: =('Inteligencia emocional'!C366) -> 0 | O8: =('Inteligencia emocional'!C372) -> 0 | V8: =('Inteligencia emocional'!A366) -> 0 | W8: =('Inteligencia emocional'!D366) -> 0 | X8: =('Inteligencia emocional'!D372) -> 0 | AE8: =('Inteligencia emocional'!A366) -> 0 | AF8: =('Inteligencia emocional'!E366) -> 0 | AG8: =('Inteligencia emocional'!E372) -> 0 | AN8: =('Inteligencia emocional'!A366) -> 0 | AO8: =('Inteligencia emocional'!F366) -> 0 | AP8: =('Inteligencia emocional'!F372) -> 0 | AW8: =('Inteligencia emocional'!A366) -> 0 | AX8: =('Inteligencia emocional'!G366) -> 0 | AY8: =('Inteligencia emocional'!G372) -> 0 | BF8: =('Inteligencia emocional'!A366) -> 0 | BG8: =('Inteligencia emocional'!H366) -> 0 | BH8: =('Inteligencia emocional'!H372) -> 0 | BO8: =('Inteligencia emocional'!A366) -> 0 | BP8: =('Inteligencia emocional'!I366) -> 0 | BQ8: =('Inteligencia emocional'!I372) -> 0 | BX8: =('Inteligencia emocional'!A366) -> 0 | BY8: =('Inteligencia emocional'!J366) -> 0 | BZ8: =('Inteligencia emocional'!J372) -> 0 | CG8: =('Inteligencia emocional'!A366) -> 0 | CH8: =('Inteligencia emocional'!K366) -> 0 | CI8: =('Inteligencia emocional'!K372) -> 0 | CP8: =('Inteligencia emocional'!A366) -> 0 | CQ8: =('Inteligencia emocional'!L366) -> 0 | CR8: =('Inteligencia emocional'!L372) -> 0 | CY8: =('Inteligencia emocional'!A366) -> 0 | CZ8: =('Inteligencia emocional'!M366) -> 0 | DA8: =('Inteligencia emocional'!M372) -> 0 | DH8: =('Inteligencia emocional'!A366) -> 0 | DI8: =('Inteligencia emocional'!N366) -> 0 | DJ8: =('Inteligencia emocional'!N372) -> 0 | DQ8: =('Inteligencia emocional'!A366) -> 0 | DR8: =('Inteligencia emocional'!O366) -> 0 | DS8: =('Inteligencia emocional'!O372) -> 0 | DZ8: =('Inteligencia emocional'!A366) -> 0 | EA8: =('Inteligencia emocional'!P366) -> 0 | EB8: =('Inteligencia emocional'!P372) -> 0 | EI8: =('Inteligencia emocional'!A366) -> 0 | EJ8: =('Inteligencia emocional'!Q366) -> 0 | EK8: =('Inteligencia emocional'!Q372) -> 0 | ER8: =('Inteligencia emocional'!A366) -> 0 | ES8: =('Inteligencia emocional'!R366) -> 0 | ET8: =('Inteligencia emocional'!R372) -> 0 | FA8: =('Inteligencia emocional'!A366) -> 0 | FB8: =('Inteligencia emocional'!S366) -> 0 | FC8: =('Inteligencia emocional'!S372) -> 0 | FJ8: =('Inteligencia emocional'!A366) -> 0 | FK8: =('Inteligencia emocional'!T366) -> 0 | FL8: =('Inteligencia emocional'!T372) -> 0 | FS8: =('Inteligencia emocional'!A366) -> 0 | FT8: =('Inteligencia emocional'!U366) -> 0 | FU8: =('Inteligencia emocional'!U372) -> 0 | GB8: =('Inteligencia emocional'!A366) -> 0 | GC8: =('Inteligencia emocional'!V366) -> 0 | GD8: =('Inteligencia emocional'!V372) -> 0 | GK8: =('Inteligencia emocional'!A366) -> 0 | GL8: =('Inteligencia emocional'!W366) -> 0 | GM8: =('Inteligencia emocional'!W372) -> 0 | GT8: =('Inteligencia emocional'!A366) -> 0 | GU8: =('Inteligencia emocional'!X366) -> 0 | GV8: =('Inteligencia emocional'!X372) -> 0 | HC8: =('Inteligencia emocional'!A366) -> 0 | HD8: =('Inteligencia emocional'!Y366) -> 0 | HE8: =('Inteligencia emocional'!Y372) -> 0
D9: =('Inteligencia emocional'!A367) -> 0 | E9: =('Inteligencia emocional'!B367) -> 0 | F9: =('Inteligencia emocional'!B373) -> 0 | M9: =('Inteligencia emocional'!A367) -> 0 | N9: =('Inteligencia emocional'!C367) -> 0 | O9: =('Inteligencia emocional'!C373) -> 0 | V9: =('Inteligencia emocional'!A367) -> 0 | W9: =('Inteligencia emocional'!D367) -> 0 | X9: =('Inteligencia emocional'!D373) -> 0 | AE9: =('Inteligencia emocional'!A367) -> 0 | AF9: =('Inteligencia emocional'!E367) -> 0 | AG9: =('Inteligencia emocional'!E373) -> 0 | AN9: =('Inteligencia emocional'!A367) -> 0 | AO9: =('Inteligencia emocional'!F367) -> 0 | AP9: =('Inteligencia emocional'!F373) -> 0 | AW9: =('Inteligencia emocional'!A367) -> 0 | AX9: =('Inteligencia emocional'!G367) -> 0 | AY9: =('Inteligencia emocional'!G373) -> 0 | BF9: =('Inteligencia emocional'!A367) -> 0 | BG9: =('Inteligencia emocional'!H367) -> 0 | BH9: =('Inteligencia emocional'!H373) -> 0 | BO9: =('Inteligencia emocional'!A367) -> 0 | BP9: =('Inteligencia emocional'!I367) -> 0 | BQ9: =('Inteligencia emocional'!I373) -> 0 | BX9: =('Inteligencia emocional'!A367) -> 0 | BY9: =('Inteligencia emocional'!J367) -> 0 | BZ9: =('Inteligencia emocional'!J373) -> 0 | CG9: =('Inteligencia emocional'!A367) -> 0 | CH9: =('Inteligencia emocional'!K367) -> 0 | CI9: =('Inteligencia emocional'!K373) -> 0 | CP9: =('Inteligencia emocional'!A367) -> 0 | CQ9: =('Inteligencia emocional'!L367) -> 0 | CR9: =('Inteligencia emocional'!L373) -> 0 | CY9: =('Inteligencia emocional'!A367) -> 0 | CZ9: =('Inteligencia emocional'!M367) -> 0 | DA9: =('Inteligencia emocional'!M373) -> 0 | DH9: =('Inteligencia emocional'!A367) -> 0 | DI9: =('Inteligencia emocional'!N367) -> 0 | DJ9: =('Inteligencia emocional'!N373) -> 0 | DQ9: =('Inteligencia emocional'!A367) -> 0 | DR9: =('Inteligencia emocional'!O367) -> 0 | DS9: =('Inteligencia emocional'!O373) -> 0 | DZ9: =('Inteligencia emocional'!A367) -> 0 | EA9: =('Inteligencia emocional'!P367) -> 0 | EB9: =('Inteligencia emocional'!P373) -> 0 | EI9: =('Inteligencia emocional'!A367) -> 0 | EJ9: =('Inteligencia emocional'!Q367) -> 0 | EK9: =('Inteligencia emocional'!Q373) -> 0 | ER9: =('Inteligencia emocional'!A367) -> 0 | ES9: =('Inteligencia emocional'!R367) -> 0 | ET9: =('Inteligencia emocional'!R373) -> 0 | FA9: =('Inteligencia emocional'!A367) -> 0 | FB9: =('Inteligencia emocional'!S367) -> 0 | FC9: =('Inteligencia emocional'!S373) -> 0 | FJ9: =('Inteligencia emocional'!A367) -> 0 | FK9: =('Inteligencia emocional'!T367) -> 0 | FL9: =('Inteligencia emocional'!T373) -> 0 | FS9: =('Inteligencia emocional'!A367) -> 0 | FT9: =('Inteligencia emocional'!U367) -> 0 | FU9: =('Inteligencia emocional'!U373) -> 0 | GB9: =('Inteligencia emocional'!A367) -> 0 | GC9: =('Inteligencia emocional'!V367) -> 0 | GD9: =('Inteligencia emocional'!V373) -> 0 | GK9: =('Inteligencia emocional'!A367) -> 0 | GL9: =('Inteligencia emocional'!W367) -> 0 | GM9: =('Inteligencia emocional'!W373) -> 0 | GT9: =('Inteligencia emocional'!A367) -> 0 | GU9: =('Inteligencia emocional'!X367) -> 0 | GV9: =('Inteligencia emocional'!X373) -> 0 | HC9: =('Inteligencia emocional'!A367) -> 0 | HD9: =('Inteligencia emocional'!Y367) -> 0 | HE9: =('Inteligencia emocional'!Y373) -> 0
D10: =('Inteligencia emocional'!A368) -> 0 | E10: =('Inteligencia emocional'!B368) -> 0 | F10: =('Inteligencia emocional'!B374) -> 0 | M10: =('Inteligencia emocional'!A368) -> 0 | N10: =('Inteligencia emocional'!C368) -> 0 | O10: =('Inteligencia emocional'!C374) -> 0 | V10: =('Inteligencia emocional'!A368) -> 0 | W10: =('Inteligencia emocional'!D368) -> 0 | X10: =('Inteligencia emocional'!D374) -> 0 | AE10: =('Inteligencia emocional'!A368) -> 0 | AF10: =('Inteligencia emocional'!E368) -> 0 | AG10: =('Inteligencia emocional'!E374) -> 0 | AN10: =('Inteligencia emocional'!A368) -> 0 | AO10: =('Inteligencia emocional'!F368) -> 0 | AP10: =('Inteligencia emocional'!F374) -> 0 | AW10: =('Inteligencia emocional'!A368) -> 0 | AX10: =('Inteligencia emocional'!G368) -> 0 | AY10: =('Inteligencia emocional'!G374) -> 0 | BF10: =('Inteligencia emocional'!A368) -> 0 | BG10: =('Inteligencia emocional'!H368) -> 0 | BH10: =('Inteligencia emocional'!H374) -> 0 | BO10: =('Inteligencia emocional'!A368) -> 0 | BP10: =('Inteligencia emocional'!I368) -> 0 | BQ10: =('Inteligencia emocional'!I374) -> 0 | BX10: =('Inteligencia emocional'!A368) -> 0 | BY10: =('Inteligencia emocional'!J368) -> 0 | BZ10: =('Inteligencia emocional'!J374) -> 0 | CG10: =('Inteligencia emocional'!A368) -> 0 | CH10: =('Inteligencia emocional'!K368) -> 0 | CI10: =('Inteligencia emocional'!K374) -> 0 | CP10: =('Inteligencia emocional'!A368) -> 0 | CQ10: =('Inteligencia emocional'!L368) -> 0 | CR10: =('Inteligencia emocional'!L374) -> 0 | CY10: =('Inteligencia emocional'!A368) -> 0 | CZ10: =('Inteligencia emocional'!M368) -> 0 | DA10: =('Inteligencia emocional'!M374) -> 0 | DH10: =('Inteligencia emocional'!A368) -> 0 | DI10: =('Inteligencia emocional'!N368) -> 0 | DJ10: =('Inteligencia emocional'!N374) -> 0 | DQ10: =('Inteligencia emocional'!A368) -> 0 | DR10: =('Inteligencia emocional'!O368) -> 0 | DS10: =('Inteligencia emocional'!O374) -> 0 | DZ10: =('Inteligencia emocional'!A368) -> 0 | EA10: =('Inteligencia emocional'!P368) -> 0 | EB10: =('Inteligencia emocional'!P374) -> 0 | EI10: =('Inteligencia emocional'!A368) -> 0 | EJ10: =('Inteligencia emocional'!Q368) -> 0 | EK10: =('Inteligencia emocional'!Q374) -> 0 | ER10: =('Inteligencia emocional'!A368) -> 0 | ES10: =('Inteligencia emocional'!R368) -> 0 | ET10: =('Inteligencia emocional'!R374) -> 0 | FA10: =('Inteligencia emocional'!A368) -> 0 | FB10: =('Inteligencia emocional'!S368) -> 0 | FC10: =('Inteligencia emocional'!S374) -> 0 | FJ10: =('Inteligencia emocional'!A368) -> 0 | FK10: =('Inteligencia emocional'!T368) -> 0 | FL10: =('Inteligencia emocional'!T374) -> 0 | FS10: =('Inteligencia emocional'!A368) -> 0 | FT10: =('Inteligencia emocional'!U368) -> 0 | FU10: =('Inteligencia emocional'!U374) -> 0 | GB10: =('Inteligencia emocional'!A368) -> 0 | GC10: =('Inteligencia emocional'!V368) -> 0 | GD10: =('Inteligencia emocional'!V374) -> 0 | GK10: =('Inteligencia emocional'!A368) -> 0 | GL10: =('Inteligencia emocional'!W368) -> 0 | GM10: =('Inteligencia emocional'!W374) -> 0 | GT10: =('Inteligencia emocional'!A368) -> 0 | GU10: =('Inteligencia emocional'!X368) -> 0 | GV10: =('Inteligencia emocional'!X374) -> 0 | HC10: =('Inteligencia emocional'!A368) -> 0 | HD10: =('Inteligencia emocional'!Y368) -> 0 | HE10: =('Inteligencia emocional'!Y374) -> 0
D11: =('Inteligencia emocional'!A369) -> 0 | E11: =('Inteligencia emocional'!B369) -> 0 | F11: =('Inteligencia emocional'!B375) -> 0 | M11: =('Inteligencia emocional'!A369) -> 0 | N11: =('Inteligencia emocional'!C369) -> 0 | O11: =('Inteligencia emocional'!C375) -> 0 | V11: =('Inteligencia emocional'!A369) -> 0 | W11: =('Inteligencia emocional'!D369) -> 0 | X11: =('Inteligencia emocional'!D375) -> 0 | AE11: =('Inteligencia emocional'!A369) -> 0 | AF11: =('Inteligencia emocional'!E369) -> 0 | AG11: =('Inteligencia emocional'!E375) -> 0 | AN11: =('Inteligencia emocional'!A369) -> 0 | AO11: =('Inteligencia emocional'!F369) -> 0 | AP11: =('Inteligencia emocional'!F375) -> 0 | AW11: =('Inteligencia emocional'!A369) -> 0 | AX11: =('Inteligencia emocional'!G369) -> 0 | AY11: =('Inteligencia emocional'!G375) -> 0 | BF11: =('Inteligencia emocional'!A369) -> 0 | BG11: =('Inteligencia emocional'!H369) -> 0 | BH11: =('Inteligencia emocional'!H375) -> 0 | BO11: =('Inteligencia emocional'!A369) -> 0 | BP11: =('Inteligencia emocional'!I369) -> 0 | BQ11: =('Inteligencia emocional'!I375) -> 0 | BX11: =('Inteligencia emocional'!A369) -> 0 | BY11: =('Inteligencia emocional'!J369) -> 0 | BZ11: =('Inteligencia emocional'!J375) -> 0 | CG11: =('Inteligencia emocional'!A369) -> 0 | CH11: =('Inteligencia emocional'!K369) -> 0 | CI11: =('Inteligencia emocional'!K375) -> 0 | CP11: =('Inteligencia emocional'!A369) -> 0 | CQ11: =('Inteligencia emocional'!L369) -> 0 | CR11: =('Inteligencia emocional'!L375) -> 0 | CY11: =('Inteligencia emocional'!A369) -> 0 | CZ11: =('Inteligencia emocional'!M369) -> 0 | DA11: =('Inteligencia emocional'!M375) -> 0 | DH11: =('Inteligencia emocional'!A369) -> 0 | DI11: =('Inteligencia emocional'!N369) -> 0 | DJ11: =('Inteligencia emocional'!N375) -> 0 | DQ11: =('Inteligencia emocional'!A369) -> 0 | DR11: =('Inteligencia emocional'!O369) -> 0 | DS11: =('Inteligencia emocional'!O375) -> 0 | DZ11: =('Inteligencia emocional'!A369) -> 0 | EA11: =('Inteligencia emocional'!P369) -> 0 | EB11: =('Inteligencia emocional'!P375) -> 0 | EI11: =('Inteligencia emocional'!A369) -> 0 | EJ11: =('Inteligencia emocional'!Q369) -> 0 | EK11: =('Inteligencia emocional'!Q375) -> 0 | ER11: =('Inteligencia emocional'!A369) -> 0 | ES11: =('Inteligencia emocional'!R369) -> 0 | ET11: =('Inteligencia emocional'!R375) -> 0 | FA11: =('Inteligencia emocional'!A369) -> 0 | FB11: =('Inteligencia emocional'!S369) -> 0 | FC11: =('Inteligencia emocional'!S375) -> 0 | FJ11: =('Inteligencia emocional'!A369) -> 0 | FK11: =('Inteligencia emocional'!T369) -> 0 | FL11: =('Inteligencia emocional'!T375) -> 0 | FS11: =('Inteligencia emocional'!A369) -> 0 | FT11: =('Inteligencia emocional'!U369) -> 0 | FU11: =('Inteligencia emocional'!U375) -> 0 | GB11: =('Inteligencia emocional'!A369) -> 0 | GC11: =('Inteligencia emocional'!V369) -> 0 | GD11: =('Inteligencia emocional'!V375) -> 0 | GK11: =('Inteligencia emocional'!A369) -> 0 | GL11: =('Inteligencia emocional'!W369) -> 0 | GM11: =('Inteligencia emocional'!W375) -> 0 | GT11: =('Inteligencia emocional'!A369) -> 0 | GU11: =('Inteligencia emocional'!X369) -> 0 | GV11: =('Inteligencia emocional'!X375) -> 0 | HC11: =('Inteligencia emocional'!A369) -> 0 | HD11: =('Inteligencia emocional'!Y369) -> 0 | HE11: =('Inteligencia emocional'!Y375) -> 0
D12: =('Inteligencia emocional'!A370) -> 0 | E12: =('Inteligencia emocional'!B370) -> 0 | F12: =('Inteligencia emocional'!B376) -> 0 | M12: =('Inteligencia emocional'!A370) -> 0 | N12: =('Inteligencia emocional'!C370) -> 0 | O12: =('Inteligencia emocional'!C376) -> 0 | V12: =('Inteligencia emocional'!A370) -> 0 | W12: =('Inteligencia emocional'!D370) -> 0 | X12: =('Inteligencia emocional'!D376) -> 0 | AE12: =('Inteligencia emocional'!A370) -> 0 | AF12: =('Inteligencia emocional'!E370) -> 0 | AG12: =('Inteligencia emocional'!E376) -> 0 | AN12: =('Inteligencia emocional'!A370) -> 0 | AO12: =('Inteligencia emocional'!F370) -> 0 | AP12: =('Inteligencia emocional'!F376) -> 0 | AW12: =('Inteligencia emocional'!A370) -> 0 | AX12: =('Inteligencia emocional'!G370) -> 0 | AY12: =('Inteligencia emocional'!G376) -> 0 | BF12: =('Inteligencia emocional'!A370) -> 0 | BG12: =('Inteligencia emocional'!H370) -> 0 | BH12: =('Inteligencia emocional'!H376) -> 0 | BO12: =('Inteligencia emocional'!A370) -> 0 | BP12: =('Inteligencia emocional'!I370) -> 0 | BQ12: =('Inteligencia emocional'!I376) -> 0 | BX12: =('Inteligencia emocional'!A370) -> 0 | BY12: =('Inteligencia emocional'!J370) -> 0 | BZ12: =('Inteligencia emocional'!J376) -> 0 | CG12: =('Inteligencia emocional'!A370) -> 0 | CH12: =('Inteligencia emocional'!K370) -> 0 | CI12: =('Inteligencia emocional'!K376) -> 0 | CP12: =('Inteligencia emocional'!A370) -> 0 | CQ12: =('Inteligencia emocional'!L370) -> 0 | CR12: =('Inteligencia emocional'!L376) -> 0 | CY12: =('Inteligencia emocional'!A370) -> 0 | CZ12: =('Inteligencia emocional'!M370) -> 0 | DA12: =('Inteligencia emocional'!M376) -> 0 | DH12: =('Inteligencia emocional'!A370) -> 0 | DI12: =('Inteligencia emocional'!N370) -> 0 | DJ12: =('Inteligencia emocional'!N376) -> 0 | DQ12: =('Inteligencia emocional'!A370) -> 0 | DR12: =('Inteligencia emocional'!O370) -> 0 | DS12: =('Inteligencia emocional'!O376) -> 0 | DZ12: =('Inteligencia emocional'!A370) -> 0 | EA12: =('Inteligencia emocional'!P370) -> 0 | EB12: =('Inteligencia emocional'!P376) -> 0 | EI12: =('Inteligencia emocional'!A370) -> 0 | EJ12: =('Inteligencia emocional'!Q370) -> 0 | EK12: =('Inteligencia emocional'!Q376) -> 0 | ER12: =('Inteligencia emocional'!A370) -> 0 | ES12: =('Inteligencia emocional'!R370) -> 0 | ET12: =('Inteligencia emocional'!R376) -> 0 | FA12: =('Inteligencia emocional'!A370) -> 0 | FB12: =('Inteligencia emocional'!S370) -> 0 | FC12: =('Inteligencia emocional'!S376) -> 0 | FJ12: =('Inteligencia emocional'!A370) -> 0 | FK12: =('Inteligencia emocional'!T370) -> 0 | FL12: =('Inteligencia emocional'!T376) -> 0 | FS12: =('Inteligencia emocional'!A370) -> 0 | FT12: =('Inteligencia emocional'!U370) -> 0 | FU12: =('Inteligencia emocional'!U376) -> 0 | GB12: =('Inteligencia emocional'!A370) -> 0 | GC12: =('Inteligencia emocional'!V370) -> 0 | GD12: =('Inteligencia emocional'!V376) -> 0 | GK12: =('Inteligencia emocional'!A370) -> 0 | GL12: =('Inteligencia emocional'!W370) -> 0 | GM12: =('Inteligencia emocional'!W376) -> 0 | GT12: =('Inteligencia emocional'!A370) -> 0 | GU12: =('Inteligencia emocional'!X370) -> 0 | GV12: =('Inteligencia emocional'!X376) -> 0 | HC12: =('Inteligencia emocional'!A370) -> 0 | HD12: =('Inteligencia emocional'!Y370) -> 0 | HE12: =('Inteligencia emocional'!Y376) -> 0
