Workbook

Sheet Clima institucional
A1: Dimension 1
B3: Estructuración Organizacional | F3: Relaciones Interpersonales | J3: Identidad Institucional | N3: Total | O3: Valoración
B4: PRG.1 | C4: PRG.2 | D4: PRG.3 | E4: PRG.4 | F4: PRG.5 | G4: PRG.6 | H4: PRG.7 | I4: PRG.8 | J4: PRG.9 | K4: PRG.10 | L4: PRG.11 | M4: PRG.12
A5: Docentes 1 | B5: 3 | C5: 1 | D5: 4 | E5: 1 | F5: 4 | G5: 4 | H5: 3 | I5: 4 | J5: 3 | K5: 4 | L5: 2 | M5: 4 | N5: 37
A6: Docentes 2 | B6: 2 | C6: 2 | D6: 2 | E6: 2 | F6: 2 | G6: 3 | H6: 3 | I6: 3 | J6: 3 | K6: 3 | L6: 3 | M6: 4 | N6: 32
A7: Docentes 3 | B7: 3 | C7: 2 | D7: 2 | E7: 1 | F7: 3 | G7: 3 | H7: 3 | I7: 2 | J7: 2 | K7: 3 | L7: 2 | M7: 3 | N7: 29
A8: Docentes 4 | B8: 1 | C8: 1 | D8: 1 | E8: 2 | F8: 1 | G8: 1 | H8: 2 | I8: 1 | J8: 1 | K8: 1 | L8: 1 | M8: 1 | N8: 14
A9: Docentes 5 | B9: 1 | C9: 1 | D9: 1 | E9: 2 | F9: 1 | G9: 1 | H9: 2 | I9: 2 | J9: 1 | K9: 1 | L9: 1 | M9: 1 | N9: 15
A10: Docentes 6 | B10: 1 | C10: 2 | D10: 1 | E10: 3 | F10: 2 | G10: 1 | H10: 2 | I10: 2 | J10: 2 | K10: 2 | L10: 2 | M10: 2 | N10: 22
A11: Docentes 7 | B11: 1 | C11: 2 | D11: 1 | E11: 3 | F11: 1 | G11: 2 | H11: 1 | I11: 1 | J11: 1 | K11: 1 | L11: 1 | M11: 1 | N11: 16
A12: Docentes 8 | B12: 4 | C12: 2 | D12: 5 | E12: 2 | F12: 3 | G12: 5 | H12: 3 | I12: 5 | J12: 5 | K12: 5 | L12: 4 | M12: 5 | N12: 48
A13: Docentes 9 | B13: 1 | C13: 3 | D13: 1 | E13: 1 | F13: 2 | G13: 2 | H13: 2 | I13: 1 | J13: 1 | K13: 2 | L13: 2 | M13: 1 | N13: 19
A14: Docentes 10 | B14: 1 | C14: 1 | D14: 2 | E14: 3 | F14: 1 | G14: 1 | H14: 2 | I14: 2 | J14: 1 | K14: 2 | L14: 1 | M14: 1 | N14: 18
A15: Docentes 11 | B15: 5 | C15: 3 | D15: 5 | E15: 2 | F15: 5 | G15: 5 | H15: 2 | I15: 4 | J15: 4 | K15: 4 | L15: 3 | M15: 4 | N15: 46
A16: Docentes 12 | B16: 1 | C16: 2 | D16: 1 | E16: 2 | F16: 1 | G16: 1 | H16: 2 | I16: 1 | J16: 1 | K16: 1 | L16: 1 | M16: 1 | N16: 15
... A24: Docentes 20 | B24: 1 | C24: 2 | D24: 2 | E24: 3 | F24: 1 | G24: 1 | H24: 1 | I24: 1 | J24: 1 | K24: 1 | L24: 2 | M24: 1 | N24: 17
A25: TOTAL | B25: =SUM(B5:B24) -> 38 | C25: =SUM(C5:C24) -> 36 | D25: =SUM(D5:D24) -> 43 | E25: =SUM(E5:E24) -> 40 | F25: =SUM(F5:F24) -> 42 | G25: =SUM(G5:G24) -> 44 | H25: =SUM(H5:H24) -> 42 | I25: =SUM(I5:I24) -> 44 | ... N25: =SUM(N5:N24) -> 494
A26: MODA | B26: =MODE(B5:B24) -> 1 | C26: =MODE(C5:C24) -> 2 | D26: =MODE(D5:D24) -> 2 | E26: =MODE(E5:E24) -> 2 | F26: =MODE(F5:F24) -> 2 | G26: =MODE(G5:G24) -> 1 | H26: =MODE(H5:H24) -> 2 | I26: =MODE(I5:I24) -> 2 | ... N26: =MODE(N5:N24) -> 15
A27: MEDIA | B27: =(B25/20) -> 1.9 | C27: =(C25/20) -> 1.8 | D27: =(D25/20) -> 2.15 | E27: =(E25/20) -> 2 | F27: =(F25/20) -> 2.1 | G27: =(G25/20) -> 2.2 | H27: =(H25/20) -> 2.1 | I27: =(I25/20) -> 2.2 | ... N27: =(N25/20) -> 24.7
A28: MEDIANA | B28: =MEDIAN(B5:B24) -> 1.5 | C28: =MEDIAN(C5:C24) -> 2 | D28: =MEDIAN(D5:D24) -> 2 | E28: =MEDIAN(E5:E24) -> 2 | F28: =MEDIAN(F5:F24) -> 2 | G28: =MEDIAN(G5:G24) -> 2 | H28: =MEDIAN(H5:H24) -> 2 | I28: =MEDIAN(I5:I24) -> 2 | ... N28: =MEDIAN(N5:N24) -> 22
A29: Desv.Est | B29: =ROUND(STDEV(B5:B24),2) -> 1.17 | C29: =ROUND(STDEV(C5:C24),2) -> 0.7 | D29: =ROUND(STDEV(D5:D24),2) -> 1.31 | E29: =ROUND(STDEV(E5:E24),2) -> 0.79 | F29: =ROUND(STDEV(F5:F24),2) -> 1.17 | G29: =ROUND(STDEV(G5:G24),2) -> 1.36 | H29: =ROUND(STDEV(H5:H24),2) -> 0.79 | I29: =ROUND(STDEV(I5:I24),2) -> 1.32 | ... N29: =ROUND(STDEV(N5:N24),2) -> 11.19
A30: Coef. Varia. | B30: =(B29/B27) -> 0.61578947 | C30: =(C29/C27) -> 0.38888889 | D30: =(D29/D27) -> 0.60930233 | E30: =(E29/E27) -> 0.395 | F30: =(F29/F27) -> 0.55714286 | G30: =(G29/G27) -> 0.61818182 | H30: =(H29/H27) -> 0.37619048 | I30: =(I29/I27) -> 0.6 | ... N30: =(N29/N27) -> 0.45303644
A31: Nunca | B31: =COUNTIF($B$5:$B$24,$A1020) -> 10 | C31: =COUNTIF($C$5:$C$24,$A1020) -> 7 | D31: =COUNTIF($D$5:$D$24,$A1020) -> 7 | E31: =COUNTIF($E$5:$E$24,$A1020) -> 6 | F31: =COUNTIF($F$5:$F$24,$A1020) -> 7 | G31: =COUNTIF($G$5:$G$24,$A1020) -> 8 | H31: =COUNTIF($H$5:$H$24,$A1020) -> 5 | I31: =COUNTIF($I$5:$I$24,$A1020) -> 7 | J31: =COUNTIF($J$5:$J$24,$A1020) -> 9 | K31: =COUNTIF($K$5:$K$24,$A1020) -> 8 | L31: =COUNTIF($L$5:$L$24,$A1020) -> 8 | M31: =COUNTIF($M$5:$M$24,$A1020) -> 9
A32: Casi Nunca | B32: =COUNTIF($B$5:$B$24,$A1021) -> 5 | C32: =COUNTIF($C$5:$C$24,$A1021) -> 10 | D32: =COUNTIF($D$5:$D$24,$A1021) -> 9 | E32: =COUNTIF($E$5:$E$24,$A1021) -> 8 | F32: =COUNTIF($F$5:$F$24,$A1021) -> 8 | G32: =COUNTIF($G$5:$G$24,$A1021) -> 6 | H32: =COUNTIF($H$5:$H$24,$A1021) -> 8 | I32: =COUNTIF($I$5:$I$24,$A1021) -> 8 | J32: =COUNTIF($J$5:$J$24,$A1021) -> 5 | K32: =COUNTIF($K$5:$K$24,$A1021) -> 6 | L32: =COUNTIF($L$5:$L$24,$A1021) -> 8 | M32: =COUNTIF($M$5:$M$24,$A1021) -> 5
A33: A veces | B33: =COUNTIF($B$5:$B$24,$A1022) -> 3 | C33: =COUNTIF($C$5:$C$24,$A1022) -> 3 | D33: =COUNTIF($D$5:$D$24,$A1022) -> 0 | E33: =COUNTIF($E$5:$E$24,$A1022) -> 6 | F33: =COUNTIF($F$5:$F$24,$A1022) -> 2 | G33: =COUNTIF($G$5:$G$24,$A1022) -> 2 | H33: =COUNTIF($H$5:$H$24,$A1022) -> 7 | I33: =COUNTIF($I$5:$I$24,$A1022) -> 1 | J33: =COUNTIF($J$5:$J$24,$A1022) -> 4 | K33: =COUNTIF($K$5:$K$24,$A1022) -> 2 | L33: =COUNTIF($L$5:$L$24,$A1022) -> 2 | M33: =COUNTIF($M$5:$M$24,$A1022) -> 1
A34: Casi siempre | B34: =COUNTIF($B$5:$B$24,$A1023) -> 1 | C34: =COUNTIF($C$5:$C$24,$A1023) -> 0 | D34: =COUNTIF($D$5:$D$24,$A1023) -> 2 | E34: =COUNTIF($E$5:$E$24,$A1023) -> 0 | F34: =COUNTIF($F$5:$F$24,$A1023) -> 2 | G34: =COUNTIF($G$5:$G$24,$A1023) -> 2 | H34: =COUNTIF($H$5:$H$24,$A1023) -> 0 | I34: =COUNTIF($I$5:$I$24,$A1023) -> 2 | J34: =COUNTIF($J$5:$J$24,$A1023) -> 1 | K34: =COUNTIF($K$5:$K$24,$A1023) -> 3 | L34: =COUNTIF($L$5:$L$24,$A1023) -> 2 | M34: =COUNTIF($M$5:$M$24,$A1023) -> 3
A35: Siempre | B35: =COUNTIF($B$5:$B$24,$A1024) -> 1 | C35: =COUNTIF($C$5:$C$24,$A1024) -> 0 | D35: =COUNTIF($D$5:$D$24,$A1024) -> 2 | E35: =COUNTIF($E$5:$E$24,$A1024) -> 0 | F35: =COUNTIF($F$5:$F$24,$A1024) -> 1 | G35: =COUNTIF($G$5:$G$24,$A1024) -> 2 | H35: =COUNTIF($H$5:$H$24,$A1024) -> 0 | I35: =COUNTIF($I$5:$I$24,$A1024) -> 2 | J35: =COUNTIF($J$5:$J$24,$A1024) -> 1 | K35: =COUNTIF($K$5:$K$24,$A1024) -> 1 | L35: =COUNTIF($L$5:$L$24,$A1024) -> 0 | M35: =COUNTIF($M$5:$M$24,$A1024) -> 2
A36: Total | B36: =SUM($B31:$B35) -> 20 | C36: =SUM($C31:$C35) -> 20 | D36: =SUM($D31:$D35) -> 20 | E36: =SUM($E31:$E35) -> 20 | F36: =SUM($F31:$F35) -> 20 | G36: =SUM($G31:$G35) -> 20 | H36: =SUM($H31:$H35) -> 20 | I36: =SUM($I31:$I35) -> 20 | J36: =SUM($J31:$J35) -> 20 | K36: =SUM($K31:$K35) -> 20 | L36: =SUM($L31:$L35) -> 20 | M36: =SUM($M31:$M35) -> 20
A37: Nunca% | B37: =($B31/$B36) -> 0.5 | C37: =($C31/$C36) -> 0.35 | D37: =($D31/$D36) -> 0.35 | E37: =($E31/$E36) -> 0.3 | F37: =($F31/$F36) -> 0.35 | G37: =($G31/$G36) -> 0.4 | H37: =($H31/$H36) -> 0.25 | I37: =($I31/$I36) -> 0.35 | J37: =($J31/$J36) -> 0.45 | K37: =($K31/$K36) -> 0.4 | L37: =($L31/$L36) -> 0.4 | M37: =($M31/$M36) -> 0.45
A38: Casi Nunca% | B38: =($B32/$B36) -> 0.25 | C38: =($C32/$C36) -> 0.5 | D38: =($D32/$D36) -> 0.45 | E38: =($E32/$E36) -> 0.4 | F38: =($F32/$F36) -> 0.4 | G38: =($G32/$G36) -> 0.3 | H38: =($H32/$H36) -> 0.4 | I38: =($I32/$I36) -> 0.4 | J38: =($J32/$J36) -> 0.25 | K38: =($K32/$K36) -> 0.3 | L38: =($L32/$L36) -> 0.4 | M38: =($M32/$M36) -> 0.25
A39: A veces% | B39: =($B33/$B36) -> 0.15 | C39: =($C33/$C36) -> 0.15 | D39: =($D33/$D36) -> 0 | E39: =($E33/$E36) -> 0.3 | F39: =($F33/$F36) -> 0.1 | G39: =($G33/$G36) -> 0.1 | H39: =($H33/$H36) -> 0.35 | I39: =($I33/$I36) -> 0.05 | J39: =($J33/$J36) -> 0.2 | K39: =($K33/$K36) -> 0.1 | L39: =($L33/$L36) -> 0.1 | M39: =($M33/$M36) -> 0.05
A40: Casi siempre% | B40: =($B34/$B36) -> 0.05 | C40: =($C34/$C36) -> 0 | D40: =($D34/$D36) -> 0.1 | E40: =($E34/$E36) -> 0 | F40: =($F34/$F36) -> 0.1 | G40: =($G34/$G36) -> 0.1 | H40: =($H34/$H36) -> 0 | I40: =($I34/$I36) -> 0.1 | J40: =($J34/$J36) -> 0.05 | K40: =($K34/$K36) -> 0.15 | L40: =($L34/$L36) -> 0.1 | M40: =($M34/$M36) -> 0.15
A41: Siempre% | B41: =($B35/$B36) -> 0.05 | C41: =($C35/$C36) -> 0 | D41: =($D35/$D36) -> 0.1 | E41: =($E35/$E36) -> 0 | F41: =($F35/$F36) -> 0.05 | G41: =($G35/$G36) -> 0.1 | H41: =($H35/$H36) -> 0 | I41: =($I35/$I36) -> 0.1 | J41: =($J35/$J36) -> 0.05 | K41: =($K35/$K36) -> 0.05 | L41: =($L35/$L36) -> 0 | M41: =($M35/$M36) -> 0.1
A42: Total % | B42: =SUM($B37:$B41) -> 1 | C42: =SUM($C37:$C41) -> 1 | D42: =SUM($D37:$D41) -> 1 | E42: =SUM($E37:$E41) -> 1 | F42: =SUM($F37:$F41) -> 1 | G42: =SUM($G37:$G41) -> 1 | H42: =SUM($H37:$H41) -> 1 | I42: =SUM($I37:$I41) -> 1 | J42: =SUM($J37:$J41) -> 1 | K42: =SUM($K37:$K41) -> 1 | L42: =SUM($L37:$L41) -> 1 | M42: =SUM($M37:$M41) -> 1
A1020: 1
A1021: 2
A1022: 3
A1023: 4
A1024: 5
B1025: =SUM($B1020:$B1024) -> 0 | C1025: =SUM($C1020:$C1024) -> 0 | D1025: =SUM($D1020:$D1024) -> 0 | E1025: =SUM($E1020:$E1024) -> 0 | F1025: =SUM($F1020:$F1024) -> 0 | G1025: =SUM($G1020:$G1024) -> 0 | H1025: =SUM($H1020:$H1024) -> 0 | I1025: =SUM($I1020:$I1024) -> 0 | J1025: =SUM($J1020:$J1024) -> 0 | K1025: =SUM($K1020:$K1024) -> 0 | L1025: =SUM($L1020:$L1024) -> 0 | M1025: =SUM($M1020:$M1024) -> 0
...

Sheet Por Valoracion (3) Dimension
A1: Dimension 1
A2: Nº de Personas | B2: Estructuración Organizacional | D2: Relaciones Interpersonales | F2: Identidad Institucional | H2: Clima institucional
B3: Suma Total | C3: Valoración | D3: Suma Total | E3: Valoración | F3: Suma Total | G3: Valoración | H3: Suma Total | I3: Valoración
A4: Docentes 1 | B4: =SUM('Clima institucional'!B5:E5) -> 9 | C4: =IF(B4<=$Q$19,"Inadecuado",IF(B4<=$Q$20,"Regular",IF(B4<=$Q$21,"Adecuado",0))) -> Inadecuado | D4: =SUM('Clima institucional'!F5:I5) -> 15 | E4: =IF(D4<=$AC$19,"Inadecuado",IF(D4<=$AC$20,"Regular",IF(D4<=$AC$21,"Adecuado",0))) -> Regular | F4: =SUM('Clima institucional'!J5:M5) -> 13 | G4: =IF(F4<=$AO$19,"Inadecuado",IF(F4<=$AO$20,"Regular",IF(F4<=$AO$21,"Adecuado",0))) -> Regular | H4: =SUM(B4:F4) -> 37 | I4: =IF(H4<=$BA$19,"Inadecuado",IF(H4<=$BA$20,"Regular",IF(H4<=$BA$21,"Adecuado",0))) -> Regular | M4: Variable | N4: Clima institucional | Y4: Variable | Z4: Clima institucional | AK4: Variable | AL4: Clima institucional | AW4: Variable | AX4: Clima institucional
A5: Docentes 2 | B5: =SUM('Clima institucional'!B6:E6) -> 8 | C5: =IF(B5<=$Q$19,"Inadecuado",IF(B5<=$Q$20,"Regular",IF(B5<=$Q$21,"Adecuado",0))) -> Inadecuado | D5: =SUM('Clima institucional'!F6:I6) -> 11 | E5: =IF(D5<=$AC$19,"Inadecuado",IF(D5<=$AC$20,"Regular",IF(D5<=$AC$21,"Adecuado",0))) -> Regular | F5: =SUM('Clima institucional'!J6:M6) -> 13 | G5: =IF(F5<=$AO$19,"Inadecuado",IF(F5<=$AO$20,"Regular",IF(F5<=$AO$21,"Adecuado",0))) -> Regular | H5: =SUM(B5:F5) -> 32 | I5: =IF(H5<=$BA$19,"Inadecuado",IF(H5<=$BA$20,"Regular",IF(H5<=$BA$21,"Adecuado",0))) -> Regular | M5: Nombre de la Dimensión | N5: =B2 -> Estructuración Organizacional | Y5: Nombre de la Dimensión | Z5: =D2 -> Relaciones Interpersonales | AK5: Nombre de la Dimensión | AL5: =F2 -> Identidad Institucional
A6: Docentes 3 | B6: =SUM('Clima institucional'!B7:E7) -> 8 | C6: =IF(B6<=$Q$19,"Inadecuado",IF(B6<=$Q$20,"Regular",IF(B6<=$Q$21,"Adecuado",0))) -> Inadecuado | D6: =SUM('Clima institucional'!F7:I7) -> 11 | E6: =IF(D6<=$AC$19,"Inadecuado",IF(D6<=$AC$20,"Regular",IF(D6<=$AC$21,"Adecuado",0))) -> Regular | F6: =SUM('Clima institucional'!J7:M7) -> 10 | G6: =IF(F6<=$AO$19,"Inadecuado",IF(F6<=$AO$20,"Regular",IF(F6<=$AO$21,"Adecuado",0))) -> Regular | H6: =SUM(B6:F6) -> 29 | I6: =IF(H6<=$BA$19,"Inadecuado",IF(H6<=$BA$20,"Regular",IF(H6<=$BA$21,"Adecuado",0))) -> Regular | M6: Cantidad de Escalas Valorativas | N6: 3 | Y6: Cantidad de Escalas Valorativas | Z6: 3 | AK6: Cantidad de Escalas Valorativas | AL6: 3 | AW6: Cantidad de Escalas Valorativas | AX6: 3
A7: Docentes 4 | B7: =SUM('Clima institucional'!B8:E8) -> 5 | C7: =IF(B7<=$Q$19,"Inadecuado",IF(B7<=$Q$20,"Regular",IF(B7<=$Q$21,"Adecuado",0))) -> Inadecuado | D7: =SUM('Clima institucional'!F8:I8) -> 5 | E7: =IF(D7<=$AC$19,"Inadecuado",IF(D7<=$AC$20,"Regular",IF(D7<=$AC$21,"Adecuado",0))) -> Inadecuado | F7: =SUM('Clima institucional'!J8:M8) -> 4 | G7: =IF(F7<=$AO$19,"Inadecuado",IF(F7<=$AO$20,"Regular",IF(F7<=$AO$21,"Adecuado",0))) -> Inadecuado | H7: =SUM(B7:F7) -> 14 | I7: =IF(H7<=$BA$19,"Inadecuado",IF(H7<=$BA$20,"Regular",IF(H7<=$BA$21,"Adecuado",0))) -> Inadecuado | M7: Nº de Peguntas | N7: 4 | Y7: Nº de Peguntas | Z7: 4 | AK7: Nº de Peguntas | AL7: 4 | AW7: Nº de Peguntas | AX7: 12
A8: Docentes 5 | B8: =SUM('Clima institucional'!B9:E9) -> 5 | C8: =IF(B8<=$Q$19,"Inadecuado",IF(B8<=$Q$20,"Regular",IF(B8<=$Q$21,"Adecuado",0))) -> Inadecuado | D8: =SUM('Clima institucional'!F9:I9) -> 6 | E8: =IF(D8<=$AC$19,"Inadecuado",IF(D8<=$AC$20,"Regular",IF(D8<=$AC$21,"Adecuado",0))) -> Inadecuado | F8: =SUM('Clima institucional'!J9:M9) -> 4 | G8: =IF(F8<=$AO$19,"Inadecuado",IF(F8<=$AO$20,"Regular",IF(F8<=$AO$21,"Adecuado",0))) -> Inadecuado | H8: =SUM(B8:F8) -> 15 | I8: =IF(H8<=$BA$19,"Inadecuado",IF(H8<=$BA$20,"Regular",IF(H8<=$BA$21,"Adecuado",0))) -> Inadecuado | M8: Valor Mínimo por item | N8: 1 | Y8: Valor Mínimo por item | Z8: 1 | AK8: Valor Mínimo por item | AL8: 1 | AW8: Valor Mínimo por item | AX8: 1
A9: Docentes 6 | B9: =SUM('Clima institucional'!B10:E10) -> 7 | C9: =IF(B9<=$Q$19,"Inadecuado",IF(B9<=$Q$20,"Regular",IF(B9<=$Q$21,"Adecuado",0))) -> Inadecuado | D9: =SUM('Clima institucional'!F10:I10) -> 7 | E9: =IF(D9<=$AC$19,"Inadecuado",IF(D9<=$AC$20,"Regular",IF(D9<=$AC$21,"Adecuado",0))) -> Inadecuado | F9: =SUM('Clima institucional'!J10:M10) -> 8 | G9: =IF(F9<=$AO$19,"Inadecuado",IF(F9<=$AO$20,"Regular",IF(F9<=$AO$21,"Adecuado",0))) -> Inadecuado | H9: =SUM(B9:F9) -> 22 | I9: =IF(H9<=$BA$19,"Inadecuado",IF(H9<=$BA$20,"Regular",IF(H9<=$BA$21,"Adecuado",0))) -> Inadecuado | M9: Valor Máximo por item | N9: 5 | Y9: Valor Máximo por item | Z9: 5 | AK9: Valor Máximo por item | AL9: 5 | AW9: Valor Máximo por item | AX9: 5
A10: Docentes 7 | B10: =SUM('Clima institucional'!B11:E11) -> 7 | C10: =IF(B10<=$Q$19,"Inadecuado",IF(B10<=$Q$20,"Regular",IF(B10<=$Q$21,"Adecuado",0))) -> Inadecuado | D10: =SUM('Clima institucional'!F11:I11) -> 5 | E10: =IF(D10<=$AC$19,"Inadecuado",IF(D10<=$AC$20,"Regular",IF(D10<=$AC$21,"Adecuado",0))) -> Inadecuado | F10: =SUM('Clima institucional'!J11:M11) -> 4 | G10: =IF(F10<=$AO$19,"Inadecuado",IF(F10<=$AO$20,"Regular",IF(F10<=$AO$21,"Adecuado",0))) -> Inadecuado | H10: =SUM(B10:F10) -> 16 | I10: =IF(H10<=$BA$19,"Inadecuado",IF(H10<=$BA$20,"Regular",IF(H10<=$BA$21,"Adecuado",0))) -> Inadecuado | M10: Máximo | N10: =N7*N9 -> 20 | Y10: Máximo | Z10: =Z7*Z9 -> 20 | AK10: Máximo | AL10: =AL7*AL9 -> 20 | AW10: Máximo | AX10: =AX7*AX9 -> 60
A11: Docentes 8 | B11: =SUM('Clima institucional'!B12:E12) -> 13 | C11: =IF(B11<=$Q$19,"Inadecuado",IF(B11<=$Q$20,"Regular",IF(B11<=$Q$21,"Adecuado",0))) -> Regular | D11: =SUM('Clima institucional'!F12:I12) -> 16 | E11: =IF(D11<=$AC$19,"Inadecuado",IF(D11<=$AC$20,"Regular",IF(D11<=$AC$21,"Adecuado",0))) -> Adecuado | F11: =SUM('Clima institucional'!J12:M12) -> 19 | G11: =IF(F11<=$AO$19,"Inadecuado",IF(F11<=$AO$20,"Regular",IF(F11<=$AO$21,"Adecuado",0))) -> Adecuado | H11: =SUM(B11:F11) -> 48 | I11: =IF(H11<=$BA$19,"Inadecuado",IF(H11<=$BA$20,"Regular",IF(H11<=$BA$21,"Adecuado",0))) -> Adecuado | M11: Mínimo | N11: =N8*N7 -> 4 | Y11: Mínimo | Z11: =Z8*Z7 -> 4 | AK11: Mínimo | AL11: =AL8*AL7 -> 4 | AW11: Mínimo | AX11: =AX8*AX7 -> 12
A12: Docentes 9 | B12: =SUM('Clima institucional'!B13:E13) -> 6 | C12: =IF(B12<=$Q$19,"Inadecuado",IF(B12<=$Q$20,"Regular",IF(B12<=$Q$21,"Adecuado",0))) -> Inadecuado | D12: =SUM('Clima institucional'!F13:I13) -> 7 | E12: =IF(D12<=$AC$19,"Inadecuado",IF(D12<=$AC$20,"Regular",IF(D12<=$AC$21,"Adecuado",0))) -> Inadecuado | F12: =SUM('Clima institucional'!J13:M13) -> 6 | G12: =IF(F12<=$AO$19,"Inadecuado",IF(F12<=$AO$20,"Regular",IF(F12<=$AO$21,"Adecuado",0))) -> Inadecuado | H12: =SUM(B12:F12) -> 19 | I12: =IF(H12<=$BA$19,"Inadecuado",IF(H12<=$BA$20,"Regular",IF(H12<=$BA$21,"Adecuado",0))) -> Inadecuado | M12: Rango | N12: =N10-N11 -> 16 | Y12: Rango | Z12: =Z10-Z11 -> 16 | AK12: Rango | AL12: =AL10-AL11 -> 16 | AW12: Rango | AX12: =AX10-AX11 -> 48
A13: Docentes 10 | B13: =SUM('Clima institucional'!B14:E14) -> 7 | C13: =IF(B13<=$Q$19,"Inadecuado",IF(B13<=$Q$20,"Regular",IF(B13<=$Q$21,"Adecuado",0))) -> Inadecuado | D13: =SUM('Clima institucional'!F14:I14) -> 6 | E13: =IF(D13<=$AC$19,"Inadecuado",IF(D13<=$AC$20,"Regular",IF(D13<=$AC$21,"Adecuado",0))) -> Inadecuado | F13: =SUM('Clima institucional'!J14:M14) -> 5 | G13: =IF(F13<=$AO$19,"Inadecuado",IF(F13<=$AO$20,"Regular",IF(F13<=$AO$21,"Adecuado",0))) -> Inadecuado | H13: =SUM(B13:F13) -> 18 | I13: =IF(H13<=$BA$19,"Inadecuado",IF(H13<=$BA$20,"Regular",IF(H13<=$BA$21,"Adecuado",0))) -> Inadecuado | M13: Amplitud del Intervalo | N13: =ROUND(N12/N6,0) -> 5 | Y13: Amplitud del Intervalo | Z13: =ROUND(Z12/Z6,0) -> 5 | AK13: Amplitud del Intervalo | AL13: =ROUND(AL12/AL6,0) -> 5 | AW13: Amplitud del Intervalo | AX13: =ROUND(AX12/AX6,0) -> 16
A14: Docentes 11 | B14: =SUM('Clima institucional'!B15:E15) -> 15 | C14: =IF(B14<=$Q$19,"Inadecuado",IF(B14<=$Q$20,"Regular",IF(B14<=$Q$21,"Adecuado",0))) -> Regular | D14: =SUM('Clima institucional'!F15:I15) -> 16 | E14: =IF(D14<=$AC$19,"Inadecuado",IF(D14<=$AC$20,"Regular",IF(D14<=$AC$21,"Adecuado",0))) -> Adecuado | F14: =SUM('Clima institucional'!J15:M15) -> 15 | G14: =IF(F14<=$AO$19,"Inadecuado",IF(F14<=$AO$20,"Regular",IF(F14<=$AO$21,"Adecuado",0))) -> Regular | H14: =SUM(B14:F14) -> 46 | I14: =IF(H14<=$BA$19,"Inadecuado",IF(H14<=$BA$20,"Regular",IF(H14<=$BA$21,"Adecuado",0))) -> Adecuado
A15: Docentes 12 | B15: =SUM('Clima institucional'!B16:E16) -> 6 | C15: =IF(B15<=$Q$19,"Inadecuado",IF(B15<=$Q$20,"Regular",IF(B15<=$Q$21,"Adecuado",0))) -> Inadecuado | D15: =SUM('Clima institucional'!F16:I16) -> 5 | E15: =IF(D15<=$AC$19,"Inadecuado",IF(D15<=$AC$20,"Regular",IF(D15<=$AC$21,"Adecuado",0))) -> Inadecuado | F15: =SUM('Clima institucional'!J16:M16) -> 4 | G15: =IF(F15<=$AO$19,"Inadecuado",IF(F15<=$AO$20,"Regular",IF(F15<=$AO$21,"Adecuado",0))) -> Inadecuado | H15: =SUM(B15:F15) -> 15 | I15: =IF(H15<=$BA$19,"Inadecuado",IF(H15<=$BA$20,"Regular",IF(H15<=$BA$21,"Adecuado",0))) -> Inadecuado | O15: Tabla 1 | AA15: Tabla 2 | AM15: Tabla 3 | AY15: Tabla 4
A16: Docentes 13 | B16: =SUM('Clima institucional'!B17:E17) -> 7 | C16: =IF(B16<=$Q$19,"Inadecuado",IF(B16<=$Q$20,"Regular",IF(B16<=$Q$21,"Adecuado",0))) -> Inadecuado | D16: =SUM('Clima institucional'!F17:I17) -> 8 | E16: =IF(D16<=$AC$19,"Inadecuado",IF(D16<=$AC$20,"Regular",IF(D16<=$AC$21,"Adecuado",0))) -> Inadecuado | F16: =SUM('Clima institucional'!J17:M17) -> 8 | G16: =IF(F16<=$AO$19,"Inadecuado",IF(F16<=$AO$20,"Regular",IF(F16<=$AO$21,"Adecuado",0))) -> Inadecuado | H16: =SUM(B16:F16) -> 23 | I16: =IF(H16<=$BA$19,"Inadecuado",IF(H16<=$BA$20,"Regular",IF(H16<=$BA$21,"Adecuado",0))) -> Inadecuado | O16: =N5 -> Estructuración Organizacional | AA16: =Z5 -> Relaciones Interpersonales | AM16: =AL5 -> Identidad Institucional | AY16: Clima institucional
A17: Docentes 14 | B17: =SUM('Clima institucional'!B18:E18) -> 13 | C17: =IF(B17<=$Q$19,"Inadecuado",IF(B17<=$Q$20,"Regular",IF(B17<=$Q$21,"Adecuado",0))) -> Regular | D17: =SUM('Clima institucional'!F18:I18) -> 16 | E17: =IF(D17<=$AC$19,"Inadecuado",IF(D17<=$AC$20,"Regular",IF(D17<=$AC$21,"Adecuado",0))) -> Adecuado | F17: =SUM('Clima institucional'!J18:M18) -> 16 | G17: =IF(F17<=$AO$19,"Inadecuado",IF(F17<=$AO$20,"Regular",IF(F17<=$AO$21,"Adecuado",0))) -> Adecuado | H17: =SUM(B17:F17) -> 45 | I17: =IF(H17<=$BA$19,"Inadecuado",IF(H17<=$BA$20,"Regular",IF(H17<=$BA$21,"Adecuado",0))) -> Adecuado | O17: Calificación | P17: Rango | R17: Frec. | S17: % | AA17: Calificación | AB17: Rango | AD17: Frec. | AE17: % | AM17: Calificación | AN17: Rango | AP17: Frec. | AQ17: % | AY17: Calificación | AZ17: Rango | BB17: Frec. | BC17: %
A18: Docentes 15 | B18: =SUM('Clima institucional'!B19:E19) -> 7 | C18: =IF(B18<=$Q$19,"Inadecuado",IF(B18<=$Q$20,"Regular",IF(B18<=$Q$21,"Adecuado",0))) -> Inadecuado | D18: =SUM('Clima institucional'!F19:I19) -> 7 | E18: =IF(D18<=$AC$19,"Inadecuado",IF(D18<=$AC$20,"Regular",IF(D18<=$AC$21,"Adecuado",0))) -> Inadecuado | F18: =SUM('Clima institucional'!J19:M19) -> 9 | G18: =IF(F18<=$AO$19,"Inadecuado",IF(F18<=$AO$20,"Regular",IF(F18<=$AO$21,"Adecuado",0))) -> Inadecuado | H18: =SUM(B18:F18) -> 23 | I18: =IF(H18<=$BA$19,"Inadecuado",IF(H18<=$BA$20,"Regular",IF(H18<=$BA$21,"Adecuado",0))) -> Inadecuado | P18: Desde | Q18: Hasta | AB18: Desde | AC18: Hasta | AN18: Desde | AO18: Hasta | AZ18: Desde | BA18: Hasta
A19: Docentes 16 | B19: =SUM('Clima institucional'!B20:E20) -> 5 | C19: =IF(B19<=$Q$19,"Inadecuado",IF(B19<=$Q$20,"Regular",IF(B19<=$Q$21,"Adecuado",0))) -> Inadecuado | D19: =SUM('Clima institucional'!F20:I20) -> 7 | E19: =IF(D19<=$AC$19,"Inadecuado",IF(D19<=$AC$20,"Regular",IF(D19<=$AC$21,"Adecuado",0))) -> Inadecuado | F19: =SUM('Clima institucional'!J20:M20) -> 4 | G19: =IF(F19<=$AO$19,"Inadecuado",IF(F19<=$AO$20,"Regular",IF(F19<=$AO$21,"Adecuado",0))) -> Inadecuado | H19: =SUM(B19:F19) -> 16 | I19: =IF(H19<=$BA$19,"Inadecuado",IF(H19<=$BA$20,"Regular",IF(H19<=$BA$21,"Adecuado",0))) -> Inadecuado | O19: Inadecuado | P19: =N11 -> 4 | Q19: =P19+N13 -> 9 | R19: =COUNTIF($C$4:$C$23,$O19) -> 17 | S19: =R19/R22 -> 0.85 | AA19: Inadecuado | AB19: =Z11 -> 4 | AC19: =AB19+Z13 -> 9 | AD19: =COUNTIF($E$4:$E$23,$AA19) -> 14 | AE19: =AD19/AD22 -> 0.7 | AM19: Inadecuado | AN19: =AL11 -> 4 | AO19: =AN19+AL13 -> 9 | AP19: =COUNTIF($G$4:$G$23,$AM19) -> 14 | AQ19: =AP19/AP22 -> 0.7 | AY19: Inadecuado | AZ19: 12 | BA19: 27 | BB19: 14 | BC19: 0.7
A20: Docentes 17 | B20: =SUM('Clima institucional'!B21:E21) -> 8 | C20: =IF(B20<=$Q$19,"Inadecuado",IF(B20<=$Q$20,"Regular",IF(B20<=$Q$21,"Adecuado",0))) -> Inadecuado | D20: =SUM('Clima institucional'!F21:I21) -> 9 | E20: =IF(D20<=$AC$19,"Inadecuado",IF(D20<=$AC$20,"Regular",IF(D20<=$AC$21,"Adecuado",0))) -> Inadecuado | F20: =SUM('Clima institucional'!J21:M21) -> 7 | G20: =IF(F20<=$AO$19,"Inadecuado",IF(F20<=$AO$20,"Regular",IF(F20<=$AO$21,"Adecuado",0))) -> Inadecuado | H20: =SUM(B20:F20) -> 24 | I20: =IF(H20<=$BA$19,"Inadecuado",IF(H20<=$BA$20,"Regular",IF(H20<=$BA$21,"Adecuado",0))) -> Inadecuado | O20: Regular | P20: =Q19+ 1 -> 10 | Q20: =P20+N13 -> 15 | R20: =COUNTIF($C$4:$C$23,$O20) -> 3 | S20: =R20/R22 -> 0.15 | AA20: Regular | AB20: =AC19+ 1 -> 10 | AC20: =AB20+Z13 -> 15 | AD20: =COUNTIF($E$4:$E$23,$AA20) -> 3 | AE20: =AD20/AD22 -> 0.15 | AM20: Regular | AN20: =AO19+ 1 -> 10 | AO20: =AN20+AL13 -> 15 | AP20: =COUNTIF($G$4:$G$23,$AM20) -> 4 | AQ20: =AP20/AP22 -> 0.2 | AY20: Regular | AZ20: 28 | BA20: 43 | BB20: 3 | BC20: 0.15
A21: Docentes 18 | B21: =SUM('Clima institucional'!B22:E22) -> 5 | C21: =IF(B21<=$Q$19,"Inadecuado",IF(B21<=$Q$20,"Regular",IF(B21<=$Q$21,"Adecuado",0))) -> Inadecuado | D21: =SUM('Clima institucional'!F22:I22) -> 4 | E21: =IF(D21<=$AC$19,"Inadecuado",IF(D21<=$AC$20,"Regular",IF(D21<=$AC$21,"Adecuado",0))) -> Inadecuado | F21: =SUM('Clima institucional'!J22:M22) -> 4 | G21: =IF(F21<=$AO$19,"Inadecuado",IF(F21<=$AO$20,"Regular",IF(F21<=$AO$21,"Adecuado",0))) -> Inadecuado | H21: =SUM(B21:F21) -> 13 | I21: =IF(H21<=$BA$19,"Inadecuado",IF(H21<=$BA$20,"Regular",IF(H21<=$BA$21,"Adecuado",0))) -> Inadecuado | O21: Adecuado | P21: =Q20+ 1 -> 16 | Q21: =N10 -> 20 | R21: =COUNTIF($C$4:$C$23,$O21) -> 0 | S21: =R21/R22 -> 0 | AA21: Adecuado | AB21: =AC20+ 1 -> 16 | AC21: =Z10 -> 20 | AD21: =COUNTIF($E$4:$E$23,$AA21) -> 3 | AE21: =AD21/AD22 -> 0.15 | AM21: Adecuado | AN21: =AO20+ 1 -> 16 | AO21: =AL10 -> 20 | AP21: =COUNTIF($G$4:$G$23,$AM21) -> 2 | AQ21: =AP21/AP22 -> 0.1 | AY21: Adecuado | AZ21: 44 | BA21: 60 | BB21: 3 | BC21: 0.15
A22: Docentes 19 | B22: =SUM('Clima institucional'!B23:E23) -> 8 | C22: =IF(B22<=$Q$19,"Inadecuado",IF(B22<=$Q$20,"Regular",IF(B22<=$Q$21,"Adecuado",0))) -> Inadecuado | D22: =SUM('Clima institucional'!F23:I23) -> 7 | E22: =IF(D22<=$AC$19,"Inadecuado",IF(D22<=$AC$20,"Regular",IF(D22<=$AC$21,"Adecuado",0))) -> Inadecuado | F22: =SUM('Clima institucional'!J23:M23) -> 7 | G22: =IF(F22<=$AO$19,"Inadecuado",IF(F22<=$AO$20,"Regular",IF(F22<=$AO$21,"Adecuado",0))) -> Inadecuado | H22: =SUM(B22:F22) -> 22 | I22: =IF(H22<=$BA$19,"Inadecuado",IF(H22<=$BA$20,"Regular",IF(H22<=$BA$21,"Adecuado",0))) -> Inadecuado | O22: Total | R22: =SUM(R19:R21) -> 20 | S22: =SUM(S19:S21) -> 1 | AA22: Total | AD22: =SUM(AD19:AD21) -> 20 | AE22: =SUM(AE19:AE21) -> 1 | AM22: Total | AP22: =SUM(AP19:AP21) -> 20 | AQ22: =SUM(AQ19:AQ21) -> 1 | AY22: Total | BB22: 20 | BC22: 1
A23: Docentes 20 | B23: =SUM('Clima institucional'!B24:E24) -> 8 | C23: =IF(B23<=$Q$19,"Inadecuado",IF(B23<=$Q$20,"Regular",IF(B23<=$Q$21,"Adecuado",0))) -> Inadecuado | D23: =SUM('Clima institucional'!F24:I24) -> 4 | E23: =IF(D23<=$AC$19,"Inadecuado",IF(D23<=$AC$20,"Regular",IF(D23<=$AC$21,"Adecuado",0))) -> Inadecuado | F23: =SUM('Clima institucional'!J24:M24) -> 5 | G23: =IF(F23<=$AO$19,"Inadecuado",IF(F23<=$AO$20,"Regular",IF(F23<=$AO$21,"Adecuado",0))) -> Inadecuado | H23: =SUM(B23:F23) -> 17 | I23: =IF(H23<=$BA$19,"Inadecuado",IF(H23<=$BA$20,"Regular",IF(H23<=$BA$21,"Adecuado",0))) -> Inadecuado | O23: Fuente: Encuesta aplicada | AA23: Fuente: Encuesta aplicada | AM23: Fuente: Encuesta aplicada | AY23: Fuente: Encuesta aplicada
O24: Elaboración: Propia | AA24: Elaboración: Propia | AM24: Elaboración: Propia | AY24: Elaboración: Propia
O43: Figura.1 | AA43: Figura.2 | AM43: Figura.3 | AY43: Figura.4
O44: Estructuración Organizacional | AA44: Relaciones Interpersonales | AM44: Identidad Institucional | AY44: Estructuración Organizacional
M47: =CONCATENATE("en la ",O15," y ",O43," se puede observar que la variable ",L901," en base a su dimensión ",L902," tiene una calificación de ",M904," por el ",ROUND(L904*100,0),"% ","de los resultados, ","los cuales fueron extraídos de las encuestas ejecutadas a los ",N902,", estos resultados son afectados debido a que, ",U1016," ",M1016,",","asi mismo ",U1017," ",M1017,", de nuevo ",U1018," ",M1018, ", ","y ",M1019," ",U1019,", ","por todo ello la dimensión ",L902," es ",M904,".") -> en la Tabla 1 y Figura.1 se puede observar que la variable Clima institucional en base a su dimensión Estructuración Organizacional tiene una calificación de Inadecuado por el 85% de los resultados, los cuales fueron extraídos de las encuestas ejecutadas a los Docentess, estos resultados son afectados debido a que, el 75% calificó como Nunca y Casi Nunca .,asi mismo el 85% de los evaluó como Nunca y Casi Nunca 0, de nuevo el 80% evaluó como Nunca y Casi Nunca 0, y 0 el 70% de los calificó como Nunca y Casi Nunca, por todo ello la dimensión Estructuración Organizacional es Inadecuado. | Y47: =CONCATENATE("en la ",AA15," y ",AA43," se puede observar que la variable ",X901," en base a su dimensión ",X902," tiene una calificación de ",Y904," por el ",ROUND(X904*100,0),"% ","de los resultados, ","los cuales fueron extraídos de las encuestas ejecutadas a los ",Z902,", estos resultados son afectados debido a que, ",AG1016," ",Y1016,",","asi mismo ",AG1017," ",Y1017,", así ",AG1018," ",Y1018, ", ","y ",Y1019," ",AG1019,", ","por todo ello la dimensión ",X902," es ",Y904,".") -> en la Tabla 2 y Figura.2 se puede observar que la variable Clima institucional en base a su dimensión Relaciones Interpersonales tiene una calificación de Inadecuado por el 70% de los resultados, los cuales fueron extraídos de las encuestas ejecutadas a los Docentess, estos resultados son afectados debido a que, el 75% mencionó como Nunca y Casi Nunca 0,asi mismo el 70% de los determinó como Nunca y Casi Nunca 0, así el 65% mencionó como Nunca y Casi Nunca 0, y 0 el 75% de los evaluó como Nunca y Casi Nunca, por todo ello la dimensión Relaciones Interpersonales es Inadecuado. | AK47: =CONCATENATE("en la ",AM15," y ",AM43," se puede observar que la variable ",AJ901," en base a su dimensión ",AJ902," tiene una calificación de ",AK904," por el ",ROUND(AJ904*100,0),"% ","de los resultados, ","los cuales fueron extraídos de las encuestas ejecutadas a los ",AL902,", estos resultados son afectados debido a que, ",AS1016," ",AK1016,",","asi mismo ",AS1017," ",AK1017,", sin embargo ",AS1018," ",AK1018, ", ","y ",AK1019," ",AS1019,", ","por todo ello la dimensión ",AJ902," es ",AK904,".") -> en la Tabla 3 y Figura.3 se puede observar que la variable Clima institucional en base a su dimensión Identidad Institucional tiene una calificación de Inadecuado por el 70% de los resultados, los cuales fueron extraídos de las encuestas ejecutadas a los Docentess, estos resultados son afectados debido a que, el 70% percibió como Nunca y Casi Nunca 0,asi mismo el 70% de los apreció como Nunca y Casi Nunca 0, sin embargo el 80% mencionó como Nunca y Casi Nunca 0, y 0 el 70% de los Tuvo una percepción de como Nunca y Casi Nunca, por todo ello la dimensión Identidad Institucional es Inadecuado. | AW47: =CONCATENATE("En la ",AY15," y ",AY43," se puede evidenciar que la variable ",AV901," es calificado como ",AW904," por el ",ROUND(AV904*100,0),"% de los resultados, mismos que son originados porque; ",BI1016," ",BI1017," ",BI1018,BI1019,BI1020,BI1021,BI1022,BI1023,BI1024,BI1025,BI1026," se concluye que la variable ",AV901,"tiene un valor de ",AW904,".") -> En la Tabla 4 y Figura.4 se puede evidenciar que la variable Clima institucional es calificado como Inadecuado por el 70% de los resultados, mismos que son originados porque; el 85% de los Resultados Tuvo una percepción de a la dimensión Estructuración Organizacional como Inadecuado, por otro lado el 70% de los Resultados apreció a la dimensión Relaciones Interpersonales como Inadecuado, ademas el 70% de los Docentess consideró a la dimensión Identidad Institucional como Inadecuado, por consecuencia se concluye que la variable Clima institucionaltiene un valor de Inadecuado.
K901: Variable | L901: =(N4) -> Clima institucional | N901: Unidades de Medida | W901: Variable | X901: =(Z4) -> Clima institucional | Z901: Unidades de Medida | AI901: Variable | AJ901: =(AL4) -> Clima institucional | AL901: Unidades de Medida | AU901: Variable | AV901: =(AX4) -> Clima institucional | AX901: Unidades de Medida
K902: Dimensión | L902: =(N5) -> Estructuración Organizacional | N902: Docentess | W902: Dimensión | X902: =(Z5) -> Relaciones Interpersonales | Z902: Docentess | AI902: Dimensión | AJ902: =(AL5) -> Identidad Institucional | AL902: Docentess | AU902: Dimensión | AV902: =(AX5) -> 0 | AX902: Docentess
K904: Valoración de la variable | L904: =MAX(S19:S21) -> 0.85 | M904: =IF(L2104=S19,O19,IF(L2104=S20,O20,IF(L2104=S21,O21,"algo esta mal"))) -> Inadecuado | W904: Valoración de la variable | X904: =MAX(AE19:AE21) -> 0.7 | Y904: =IF(X2104=AE19,AA19,IF(X2104=AE20,AA20,IF(X2104=AE21,AA21,"algo esta mal"))) -> Inadecuado | AI904: Valoración de la variable | AJ904: =MAX(AQ19:AQ21) -> 0.7 | AK904: =IF(AJ2104=AQ19,AM19,IF(AJ2104=AQ20,AM20,IF(AJ2104=AQ21,AM21,"algo esta mal"))) -> Inadecuado | AU904: Valoración de la variable | AV904: =MAX(BC19:BC21) -> 0.7 | AW904: =IF(AV2104=BC19,AY19,IF(AV2104=BC20,AY20,IF(AV2104=BC21,AY21,"algo esta mal"))) -> Inadecuado
M905: Preguntas Originales | N905: Enunciados Para Palafraseo | O905: Nunca | P905: Casi Nunca | Q905: A veces | R905: Casi siempre | S905: Siempre | Y905: Preguntas Originales | Z905: Enunciados Para Palafraseo | AA905: Nunca | AB905: Casi Nunca | AC905: A veces | AD905: Casi siempre | AE905: Siempre | AK905: Preguntas Originales | AL905: Enunciados Para Palafraseo | AM905: Nunca | AN905: Casi Nunca | AO905: A veces | AP905: Casi siempre | AQ905: Siempre
M906: . | N906: . | O906: =('Clima institucional'!B37) -> 0.5 | P906: =('Clima institucional'!B38) -> 0.25 | Q906: =('Clima institucional'!B39) -> 0.15 | R906: =('Clima institucional'!B40) -> 0.05 | S906: =('Clima institucional'!B41) -> 0.05 | AA906: =('Clima institucional'!F37) -> 0.35 | AB906: =('Clima institucional'!F38) -> 0.4 | AC906: =('Clima institucional'!F39) -> 0.1 | AD906: =('Clima institucional'!F40) -> 0.1 | AE906: =('Clima institucional'!F41) -> 0.05 | AM906: =('Clima institucional'!J37) -> 0.45 | AN906: =('Clima institucional'!J38) -> 0.25 | AO906: =('Clima institucional'!J39) -> 0.2 | AP906: =('Clima institucional'!J40) -> 0.05 | AQ906: =('Clima institucional'!J41) -> 0.05
O907: =('Clima institucional'!C37) -> 0.35 | P907: =('Clima institucional'!C38) -> 0.5 | Q907: =('Clima institucional'!C39) -> 0.15 | R907: =('Clima institucional'!C40) -> 0 | S907: =('Clima institucional'!C41) -> 0 | AA907: =('Clima institucional'!G37) -> 0.4 | AB907: =('Clima institucional'!G38) -> 0.3 | AC907: =('Clima institucional'!G39) -> 0.1 | AD907: =('Clima institucional'!G40) -> 0.1 | AE907: =('Clima institucional'!G41) -> 0.1 | AM907: =('Clima institucional'!K37) -> 0.4 | AN907: =('Clima institucional'!K38) -> 0.3 | AO907: =('Clima institucional'!K39) -> 0.1 | AP907: =('Clima institucional'!K40) -> 0.15 | AQ907: =('Clima institucional'!K41) -> 0.05
O908: =('Clima institucional'!D37) -> 0.35 | P908: =('Clima institucional'!D38) -> 0.45 | Q908: =('Clima institucional'!D39) -> 0 | R908: =('Clima institucional'!D40) -> 0.1 | S908: =('Clima institucional'!D41) -> 0.1 | AA908: =('Clima institucional'!H37) -> 0.25 | AB908: =('Clima institucional'!H38) -> 0.4 | AC908: =('Clima institucional'!H39) -> 0.35 | AD908: =('Clima institucional'!H40) -> 0 | AE908: =('Clima institucional'!H41) -> 0 | AM908: =('Clima institucional'!L37) -> 0.4 | AN908: =('Clima institucional'!L38) -> 0.4 | AO908: =('Clima institucional'!L39) -> 0.1 | AP908: =('Clima institucional'!L40) -> 0.1 | AQ908: =('Clima institucional'!L41) -> 0
O909: =('Clima institucional'!E37) -> 0.3 | P909: =('Clima institucional'!E38) -> 0.4 | Q909: =('Clima institucional'!E39) -> 0.3 | R909: =('Clima institucional'!E40) -> 0 | S909: =('Clima institucional'!E41) -> 0 | AA909: =('Clima institucional'!I37) -> 0.35 | AB909: =('Clima institucional'!I38) -> 0.4 | AC909: =('Clima institucional'!I39) -> 0.05 | AD909: =('Clima institucional'!I40) -> 0.1 | AE909: =('Clima institucional'!I41) -> 0.1 | AM909: =('Clima institucional'!M37) -> 0.45 | AN909: =('Clima institucional'!M38) -> 0.25 | AO909: =('Clima institucional'!M39) -> 0.05 | AP909: =('Clima institucional'!M40) -> 0.15 | AQ909: =('Clima institucional'!M41) -> 0.1
M1015: Enunciados Para Palafraseo | N1015: =CONCATENATE(O905," y ",P905) -> Nunca y Casi Nunca | O1015: =(Q905) -> A veces | P1015: =CONCATENATE(R905," y ",S905) -> Casi siempre y Siempre | Q1015: MÁXIMO | R1015: Valores | S1015: codificación de verbos aleatorios para concatenar | T1015: verbo | U1015: Concatenación | Y1015: Enunciados Para Palafraseo | Z1015: =CONCATENATE(AA905," y ",AB905) -> Nunca y Casi Nunca | AA1015: =(AC905) -> A veces | AB1015: =CONCATENATE(AD905," y ",AE905) -> Casi siempre y Siempre | AC1015: MÁXIMO | AD1015: Valores | AE1015: codificación de verbos aleatorios para concatenar | AF1015: verbo | AG1015: Concatenación | AK1015: Enunciados Para Palafraseo | AL1015: =CONCATENATE(AM905," y ",AN905) -> Nunca y Casi Nunca | AM1015: =(AO905) -> A veces | AN1015: =CONCATENATE(AP905," y ",AQ905) -> Casi siempre y Siempre | AO1015: MÁXIMO | AP1015: Valores | AQ1015: codificación de verbos aleatorios para concatenar | AR1015: verbo | AS1015: Concatenación | AW1015: dimensión | AX1015: Inadecuado | AY1015: Regular | AZ1015: Adecuado | BA1015: MÁXIMO | BB1015: Valor | BC1015: codificación de verbos | BD1015: Verbo | BE1015: codificación de conectores | BF1015: Conectores | BG1015: codificación de unidades de medida | BH1015: Unidades de medida | BI1015: Concatenación
M1016: =(N906) -> . | N1016: =SUM(O906:P906) -> 0.75 | O1016: =(Q906) -> 0.15 | P1016: =SUM(R906:S906) -> 0.1 | Q1016: =MAX(N1016:P1016) -> 0.75 | R1016: =IF(Q1016=N1016,$N$1015,IF(Q1016=O1016,$O$1015,IF(Q1016=P1016,$P$1015,"ALGO ESTA MAL"))) -> Nunca y Casi Nunca | S1016: =RANDBETWEEN(1,10) -> 2 | T1016: =IF(S1016=$T$1100,$U$1100,IF(S1016=$T$1101,$U$1101,IF(S1016=$T$1102,$U$1102,IF(S1016=$T$1103,$U$1103,IF(S1016=$T$1104,$U$1104,IF(S1016=$T$1105,$U$1105,IF(S1016=$T$1106,$U$1106,IF(S1016=$T$1107,$U$1107,IF(S1016=$T$1108,$U$1108,IF(S1016=$T$1109,$U$1109,"algo esta mal")))))))))) -> calificó | U1016: =CONCATENATE("el ",ROUND(Q1016*100,0),"% ",T1016," como ",R1016 ) -> el 75% calificó como Nunca y Casi Nunca | Y1016: =(Z906) -> 0 | Z1016: =SUM(AA906:AB906) -> 0.75 | AA1016: =(AC906) -> 0.1 | AB1016: =SUM(AD906:AE906) -> 0.15 | AC1016: =MAX(Z1016:AB1016) -> 0.75 | AD1016: =IF(AC1016=Z1016,$Z$1015,IF(AC1016=AA1016,$AA$1015,IF(AC1016=AB1016,$AB$1015,"ALGO ESTA MAL"))) -> Nunca y Casi Nunca | AE1016: =RANDBETWEEN(1,10) -> 7 | AF1016: =IF(AE1016=$AF$1100,$AG$1100,IF(AE1016=$AF$1101,$AG$1101,IF(AE1016=$AF$1102,$AG$1102,IF(AE1016=$AF$1103,$AG$1103,IF(AE1016=$AF$1104,$AG$1104,IF(AE1016=$AF$1105,$AG$1105,IF(AE1016=$AF$1106,$AG$1106,IF(AE1016=$AF$1107,$AG$1107,IF(AE1016=$AF$1108,$AG$1108,IF(AE1016=$AF$1109,$AG$1109,"algo esta mal")))))))))) -> mencionó | AG1016: =CONCATENATE("el ",ROUND(AC1016*100,0),"% ",AF1016," como ",AD1016 ) -> el 75% mencionó como Nunca y Casi Nunca | AK1016: =(AL906) -> 0 | AL1016: =SUM(AM906:AN906) -> 0.7 | AM1016: =(AO906) -> 0.2 | AN1016: =SUM(AP906:AQ906) -> 0.1 | AO1016: =MAX(AL1016:AN1016) -> 0.7 | AP1016: =IF(AO1016=AL1016,$AL$1015,IF(AO1016=AM1016,$AM$1015,IF(AO1016=AN1016,$AN$1015,"ALGO ESTA MAL"))) -> Nunca y Casi Nunca | AQ1016: =RANDBETWEEN(1,10) -> 9 | AR1016: =IF(AQ1016=$AR$1100,$AS$1100,IF(AQ1016=$AR$1101,$AS$1101,IF(AQ1016=$AR$1102,$AS$1102,IF(AQ1016=$AR$1103,$AS$1103,IF(AQ1016=$AR$1104,$AS$1104,IF(AQ1016=$AR$1105,$AS$1105,IF(AQ1016=$AR$1106,$AS$1106,IF(AQ1016=$AR$1107,$AS$1107,IF(AQ1016=$AR$1108,$AS$1108,IF(AQ1016=$AR$1109,$AS$1109,"algo esta mal")))))))))) -> percibió | AS1016: =CONCATENATE("el ",ROUND(AO1016*100,0),"% ",AR1016," como ",AP1016 ) -> el 70% percibió como Nunca y Casi Nunca | AW1016: =(O16) -> Estructuración Organizacional | AX1016: =(S19) -> 0.85 | AY1016: =(S20) -> 0.15 | AZ1016: =(S21) -> 0 | BA1016: =MAX(AX1016:AZ1016) -> 0.85 | BB1016: =IF(BA1016=AX1016,$AX$1015,IF(BA1016=AY1016,$AY$1015,IF(BA1016=AZ1016,$AZ$1015,"algo esta mal"))) -> Inadecuado | BC1016: =RANDBETWEEN(1,10) -> 10 | BD1016: =IF(BC1016=$BD$1100,$BE$1100,IF(BC1016=$BD$1101,$BE$1101,IF(BC1016=$BD$1102,$BE$1102,IF(BC1016=$BD$1103,$BE$1103,IF(BC1016=$BD$1104,$BE$1104,IF(BC1016=$BD$1105,$BE$1105,IF(BC1016=$BD$1106,$BE$1106,IF(BC1016=$BD$1107,$BE$1107,IF(BC1016=$BD$1108,$BE$1108,IF(BC1016=$BD$1109,$BE$1109,"algo esta mal")))))))))) -> Tuvo una percepción de | BE1016: =RANDBETWEEN(1,7) -> 2 | BF1016: =IF(BE1016=$BD$1110,$BE$1110,IF(BE1016=$BD$1111,$BE$1111,IF(BE1016=$BD$1112,$BE$1112,IF(BE1016=$BD$1113,$BE$1113,IF(BE1016=$BD$1114,$BE$1114,IF(BE1016=$BD$1115,$BE$1115,IF(BE1016=$BD$1116,$BE$1116,IF(BE1016=$BD$1047,$BE$1047,IF(BE1016=$BD$1048,$BE$1048,IF(BE1016=$BD$1049,$BE$1049,"algo esta mal")))))))))) -> por otro lado | BG1016: =RANDBETWEEN(1,2) -> 2 | BH1016: =IF(BG1016=$BD$1120,$BE$1120,IF(BG1016=$BD$1121,$BE$1121,"algo esta mal")) -> Resultados | BI1016: =CONCATENATE("el ",ROUND(BA1016*100,0),"% de los ",BH1016," ",BD1016," a la dimensión ",AW1016," como ",BB1016,", ",BF1016) -> el 85% de los Resultados Tuvo una percepción de a la dimensión Estructuración Organizacional como Inadecuado, por otro lado
M1017: =(N907) -> 0 | N1017: =SUM(O907:P907) -> 0.85 | O1017: =(Q907) -> 0.15 | P1017: =SUM(R907:S907) -> 0 | Q1017: =MAX(N1017:P1017) -> 0.85 | R1017: =IF(Q1017=N1017,$N$1015,IF(Q1017=O1017,$O$1015,IF(Q1017=P1017,$P$1015,"ALGO ESTA MAL"))) -> Nunca y Casi Nunca | S1017: =RANDBETWEEN(1,10) -> 5 | T1017: =IF(S1017=$T$1100,$U$1100,IF(S1017=$T$1101,$U$1101,IF(S1017=$T$1102,$U$1102,IF(S1017=$T$1103,$U$1103,IF(S1017=$T$1104,$U$1104,IF(S1017=$T$1105,$U$1105,IF(S1017=$T$1106,$U$1106,IF(S1017=$T$1107,$U$1107,IF(S1017=$T$1108,$U$1108,IF(S1017=$T$1109,$U$1109,"algo esta mal")))))))))) -> evaluó | U1017: =CONCATENATE("el ",ROUND(Q1017*100,0),"% de los ",T1017," como ",R1017) -> el 85% de los evaluó como Nunca y Casi Nunca | Y1017: =(Z907) -> 0 | Z1017: =SUM(AA907:AB907) -> 0.7 | AA1017: =(AC907) -> 0.1 | AB1017: =SUM(AD907:AE907) -> 0.2 | AC1017: =MAX(Z1017:AB1017) -> 0.7 | AD1017: =IF(AC1017=Z1017,$Z$1015,IF(AC1017=AA1017,$AA$1015,IF(AC1017=AB1017,$AB$1015,"ALGO ESTA MAL"))) -> Nunca y Casi Nunca | AE1017: =RANDBETWEEN(1,10) -> 6 | AF1017: =IF(AE1017=$AF$1100,$AG$1100,IF(AE1017=$AF$1101,$AG$1101,IF(AE1017=$AF$1102,$AG$1102,IF(AE1017=$AF$1103,$AG$1103,IF(AE1017=$AF$1104,$AG$1104,IF(AE1017=$AF$1105,$AG$1105,IF(AE1017=$AF$1106,$AG$1106,IF(AE1017=$AF$1107,$AG$1107,IF(AE1017=$AF$1108,$AG$1108,IF(AE1017=$AF$1109,$AG$1109,"algo esta mal")))))))))) -> determinó | AG1017: =CONCATENATE("el ",ROUND(AC1017*100,0),"% de los ",AF1017," como ",AD1017) -> el 70% de los determinó como Nunca y Casi Nunca | AK1017: =(AL907) -> 0 | AL1017: =SUM(AM907:AN907) -> 0.7 | AM1017: =(AO907) -> 0.1 | AN1017: =SUM(AP907:AQ907) -> 0.2 | AO1017: =MAX(AL1017:AN1017) -> 0.7 | AP1017: =IF(AO1017=AL1017,$AL$1015,IF(AO1017=AM1017,$AM$1015,IF(AO1017=AN1017,$AN$1015,"ALGO ESTA MAL"))) -> Nunca y Casi Nunca | AQ1017: =RANDBETWEEN(1,10) -> 8 | AR1017: =IF(AQ1017=$AR$1100,$AS$1100,IF(AQ1017=$AR$1101,$AS$1101,IF(AQ1017=$AR$1102,$AS$1102,IF(AQ1017=$AR$1103,$AS$1103,IF(AQ1017=$AR$1104,$AS$1104,IF(AQ1017=$AR$1105,$AS$1105,IF(AQ1017=$AR$1106,$AS$1106,IF(AQ1017=$AR$1107,$AS$1107,IF(AQ1017=$AR$1108,$AS$1108,IF(AQ1017=$AR$1109,$AS$1109,"algo esta mal")))))))))) -> apreció | AS1017: =CONCATENATE("el ",ROUND(AO1017*100,0),"% de los ",AR1017," como ",AP1017) -> el 70% de los apreció como Nunca y Casi Nunca | AW1017: =(AA16) -> Relaciones Interpersonales | AX1017: =(AE19) -> 0.7 | AY1017: =(AE20) -> 0.15 | AZ1017: =(AE21) -> 0.15 | BA1017: =MAX(AX1017:AZ1017) -> 0.7 | BB1017: =IF(BA1017=AX1017,$AX$1015,IF(BA1017=AY1017,$AY$1015,IF(BA1017=AZ1017,$AZ$1015,"algo esta mal"))) -> Inadecuado | BC1017: =RANDBETWEEN(1,10) -> 8 | BD1017: =IF(BC1017=$BD$1100,$BE$1100,IF(BC1017=$BD$1101,$BE$1101,IF(BC1017=$BD$1102,$BE$1102,IF(BC1017=$BD$1103,$BE$1103,IF(BC1017=$BD$1104,$BE$1104,IF(BC1017=$BD$1105,$BE$1105,IF(BC1017=$BD$1106,$BE$1106,IF(BC1017=$BD$1107,$BE$1107,IF(BC1017=$BD$1108,$BE$1108,IF(BC1017=$BD$1109,$BE$1109,"algo esta mal")))))))))) -> apreció | BE1017: =RANDBETWEEN(1,7) -> 4 | BF1017: =IF(BE1017=$BD$1110,$BE$1110,IF(BE1017=$BD$1111,$BE$1111,IF(BE1017=$BD$1112,$BE$1112,IF(BE1017=$BD$1113,$BE$1113,IF(BE1017=$BD$1114,$BE$1114,IF(BE1017=$BD$1115,$BE$1115,IF(BE1017=$BD$1116,$BE$1116,IF(BE1017=$BD$1047,$BE$1047,IF(BE1017=$BD$1048,$BE$1048,IF(BE1017=$BD$1049,$BE$1049,"algo esta mal")))))))))) -> ademas | BG1017: =RANDBETWEEN(1,2) -> 2 | BH1017: =IF(BG1017=$BD$1120,$BE$1120,IF(BG1017=$BD$1121,$BE$1121,"algo esta mal")) -> Resultados | BI1017: =CONCATENATE("el ",ROUND(BA1017*100,0),"% de los ",BH1017," ",BD1017," a la dimensión ",AW1017," como ",BB1017,", ",BF1017) -> el 70% de los Resultados apreció a la dimensión Relaciones Interpersonales como Inadecuado, ademas
M1018: =(N908) -> 0 | N1018: =SUM(O908:P908) -> 0.8 | O1018: =(Q908) -> 0 | P1018: =SUM(R908:S908) -> 0.2 | Q1018: =MAX(N1018:P1018) -> 0.8 | R1018: =IF(Q1018=N1018,$N$1015,IF(Q1018=O1018,$O$1015,IF(Q1018=P1018,$P$1015,"ALGO ESTA MAL"))) -> Nunca y Casi Nunca | S1018: =RANDBETWEEN(1,10) -> 5 | T1018: =IF(S1018=$T$1100,$U$1100,IF(S1018=$T$1101,$U$1101,IF(S1018=$T$1102,$U$1102,IF(S1018=$T$1103,$U$1103,IF(S1018=$T$1104,$U$1104,IF(S1018=$T$1105,$U$1105,IF(S1018=$T$1106,$U$1106,IF(S1018=$T$1107,$U$1107,IF(S1018=$T$1108,$U$1108,IF(S1018=$T$1109,$U$1109,"algo esta mal")))))))))) -> evaluó | U1018: =CONCATENATE("el ",ROUND(Q1018*100,0),"% ",T1018," como ",R1018 ) -> el 80% evaluó como Nunca y Casi Nunca | Y1018: =(Z908) -> 0 | Z1018: =SUM(AA908:AB908) -> 0.65 | AA1018: =(AC908) -> 0.35 | AB1018: =SUM(AD908:AE908) -> 0 | AC1018: =MAX(Z1018:AB1018) -> 0.65 | AD1018: =IF(AC1018=Z1018,$Z$1015,IF(AC1018=AA1018,$AA$1015,IF(AC1018=AB1018,$AB$1015,"ALGO ESTA MAL"))) -> Nunca y Casi Nunca | AE1018: =RANDBETWEEN(1,10) -> 7 | AF1018: =IF(AE1018=$AF$1100,$AG$1100,IF(AE1018=$AF$1101,$AG$1101,IF(AE1018=$AF$1102,$AG$1102,IF(AE1018=$AF$1103,$AG$1103,IF(AE1018=$AF$1104,$AG$1104,IF(AE1018=$AF$1105,$AG$1105,IF(AE1018=$AF$1106,$AG$1106,IF(AE1018=$AF$1107,$AG$1107,IF(AE1018=$AF$1108,$AG$1108,IF(AE1018=$AF$1109,$AG$1109,"algo esta mal")))))))))) -> mencionó | AG1018: =CONCATENATE("el ",ROUND(AC1018*100,0),"% ",AF1018," como ",AD1018 ) -> el 65% mencionó como Nunca y Casi Nunca | AK1018: =(AL908) -> 0 | AL1018: =SUM(AM908:AN908) -> 0.8 | AM1018: =(AO908) -> 0.1 | AN1018: =SUM(AP908:AQ908) -> 0.1 | AO1018: =MAX(AL1018:AN1018) -> 0.8 | AP1018: =IF(AO1018=AL1018,$AL$1015,IF(AO1018=AM1018,$AM$1015,IF(AO1018=AN1018,$AN$1015,"ALGO ESTA MAL"))) -> Nunca y Casi Nunca | AQ1018: =RANDBETWEEN(1,10) -> 7 | AR1018: =IF(AQ1018=$AR$1100,$AS$1100,IF(AQ1018=$AR$1101,$AS$1101,IF(AQ1018=$AR$1102,$AS$1102,IF(AQ1018=$AR$1103,$AS$1103,IF(AQ1018=$AR$1104,$AS$1104,IF(AQ1018=$AR$1105,$AS$1105,IF(AQ1018=$AR$1106,$AS$1106,IF(AQ1018=$AR$1107,$AS$1107,IF(AQ1018=$AR$1108,$AS$1108,IF(AQ1018=$AR$1109,$AS$1109,"algo esta mal")))))))))) -> mencionó | AS1018: =CONCATENATE("el ",ROUND(AO1018*100,0),"% ",AR1018," como ",AP1018 ) -> el 80% mencionó como Nunca y Casi Nunca | AW1018: =(AM16) -> Identidad Institucional | AX1018: =(AQ19) -> 0.7 | AY1018: =(AQ20) -> 0.2 | AZ1018: =(AQ21) -> 0.1 | BA1018: =MAX(AX1018:AZ1018) -> 0.7 | BB1018: =IF(BA1018=AX1018,$AX$1015,IF(BA1018=AY1018,$AY$1015,IF(BA1018=AZ1018,$AZ$1015,"algo esta mal"))) -> Inadecuado | BC1018: =RANDBETWEEN(1,10) -> 3 | BD1018: =IF(BC1018=$BD$1100,$BE$1100,IF(BC1018=$BD$1101,$BE$1101,IF(BC1018=$BD$1102,$BE$1102,IF(BC1018=$BD$1103,$BE$1103,IF(BC1018=$BD$1104,$BE$1104,IF(BC1018=$BD$1105,$BE$1105,IF(BC1018=$BD$1106,$BE$1106,IF(BC1018=$BD$1107,$BE$1107,IF(BC1018=$BD$1108,$BE$1108,IF(BC1018=$BD$1109,$BE$1109,"algo esta mal")))))))))) -> consideró | BE1018: =RANDBETWEEN(1,7) -> 7 | BF1018: =IF(BE1018=$BD$1110,$BE$1110,IF(BE1018=$BD$1111,$BE$1111,IF(BE1018=$BD$1112,$BE$1112,IF(BE1018=$BD$1113,$BE$1113,IF(BE1018=$BD$1114,$BE$1114,IF(BE1018=$BD$1115,$BE$1115,IF(BE1018=$BD$1116,$BE$1116,IF(BE1018=$BD$1047,$BE$1047,IF(BE1018=$BD$1048,$BE$1048,IF(BE1018=$BD$1049,$BE$1049,"algo esta mal")))))))))) -> por consecuencia | BG1018: =RANDBETWEEN(1,2) -> 1 | BH1018: =IF(BG1018=$BD$1120,$BE$1120,IF(BG1018=$BD$1121,$BE$1121,"algo esta mal")) -> Docentess | BI1018: =CONCATENATE("el ",ROUND(BA1018*100,0),"% de los ",BH1018," ",BD1018," a la dimensión ",AW1018," como ",BB1018,", ",BF1018) -> el 70% de los Docentess consideró a la dimensión Identidad Institucional como Inadecuado, por consecuencia
M1019: =(N909) -> 0 | N1019: =SUM(O909:P909) -> 0.7 | O1019: =(Q909) -> 0.3 | P1019: =SUM(R909:S909) -> 0 | Q1019: =MAX(N1019:P1019) -> 0.7 | R1019: =IF(Q1019=N1019,$N$1015,IF(Q1019=O1019,$O$1015,IF(Q1019=P1019,$P$1015,"ALGO ESTA MAL"))) -> Nunca y Casi Nunca | S1019: =RANDBETWEEN(1,10) -> 2 | T1019: =IF(S1019=$T$1100,$U$1100,IF(S1019=$T$1101,$U$1101,IF(S1019=$T$1102,$U$1102,IF(S1019=$T$1103,$U$1103,IF(S1019=$T$1104,$U$1104,IF(S1019=$T$1105,$U$1105,IF(S1019=$T$1106,$U$1106,IF(S1019=$T$1107,$U$1107,IF(S1019=$T$1108,$U$1108,IF(S1019=$T$1109,$U$1109,"algo esta mal")))))))))) -> calificó | U1019: =CONCATENATE("el ",ROUND(Q1019*100,0),"% de los ",T1019," como ",R1019) -> el 70% de los calificó como Nunca y Casi Nunca | Y1019: =(Z909) -> 0 | Z1019: =SUM(AA909:AB909) -> 0.75 | AA1019: =(AC909) -> 0.05 | AB1019: =SUM(AD909:AE909) -> 0.2 | AC1019: =MAX(Z1019:AB1019) -> 0.75 | AD1019: =IF(AC1019=Z1019,$Z$1015,IF(AC1019=AA1019,$AA$1015,IF(AC1019=AB1019,$AB$1015,"ALGO ESTA MAL"))) -> Nunca y Casi Nunca | AE1019: =RANDBETWEEN(1,10) -> 5 | AF1019: =IF(AE1019=$AF$1100,$AG$1100,IF(AE1019=$AF$1101,$AG$1101,IF(AE1019=$AF$1102,$AG$1102,IF(AE1019=$AF$1103,$AG$1103,IF(AE1019=$AF$1104,$AG$1104,IF(AE1019=$AF$1105,$AG$1105,IF(AE1019=$AF$1106,$AG$1106,IF(AE1019=$AF$1107,$AG$1107,IF(AE1019=$AF$1108,$AG$1108,IF(AE1019=$AF$1109,$AG$1109,"algo esta mal")))))))))) -> evaluó | AG1019: =CONCATENATE("el ",ROUND(AC1019*100,0),"% de los ",AF1019," como ",AD1019) -> el 75% de los evaluó como Nunca y Casi Nunca | AK1019: =(AL909) -> 0 | AL1019: =SUM(AM909:AN909) -> 0.7 | AM1019: =(AO909) -> 0.05 | AN1019: =SUM(AP909:AQ909) -> 0.25 | AO1019: =MAX(AL1019:AN1019) -> 0.7 | AP1019: =IF(AO1019=AL1019,$AL$1015,IF(AO1019=AM1019,$AM$1015,IF(AO1019=AN1019,$AN$1015,"ALGO ESTA MAL"))) -> Nunca y Casi Nunca | AQ1019: =RANDBETWEEN(1,10) -> 10 | AR1019: =IF(AQ1019=$AR$1100,$AS$1100,IF(AQ1019=$AR$1101,$AS$1101,IF(AQ1019=$AR$1102,$AS$1102,IF(AQ1019=$AR$1103,$AS$1103,IF(AQ1019=$AR$1104,$AS$1104,IF(AQ1019=$AR$1105,$AS$1105,IF(AQ1019=$AR$1106,$AS$1106,IF(AQ1019=$AR$1107,$AS$1107,IF(AQ1019=$AR$1108,$AS$1108,IF(AQ1019=$AR$1109,$AS$1109,"algo esta mal")))))))))) -> Tuvo una percepción de | AS1019: =CONCATENATE("el ",ROUND(AO1019*100,0),"% de los ",AR1019," como ",AP1019) -> el 70% de los Tuvo una percepción de como Nunca y Casi Nunca
...

Sheet Tabulacion por item
D4: Pregunta 1 | M4: Pregunta 2 | V4: Pregunta 3 | AE4: Pregunta 4 | AN4: Pregunta 5 | AW4: Pregunta 6 | BF4: Pregunta 7 | BO4: Pregunta 8 | BX4: Pregunta 9 | CG4: Pregunta 10 | CP4: Pregunta 11 | CY4: Pregunta 12
D5: Tabla 1 | M5: Tabla 2 | V5: Tabla 3 | AE5: Tabla 4 | AN5: Tabla 5 | AW5: Tabla 6 | BF5: Tabla 7 | BO5: Tabla 8 | BX5: Tabla 9 | CG5: Tabla 10 | CP5: Tabla 11 | CY5: Tabla 12
D6: .
E7: Frec. | F7: % | N7: Frec. | O7: % | W7: Frec. | X7: % | AF7: Frec. | AG7: % | AO7: Frec. | AP7: % | AX7: Frec. | AY7: % | BG7: Frec. | BH7: % | BP7: Frec. | BQ7: % | BY7: Frec. | BZ7: % | CH7: Frec. | CI7: % | CQ7: Frec. | CR7: % | CZ7: Frec. | DA7: %
D8: =('Clima institucional'!A31) -> Nunca | E8: =('Clima institucional'!B31) -> 10 | F8: =('Clima institucional'!B37) -> 0.5 | M8: =('Clima institucional'!A31) -> Nunca | N8: =('Clima institucional'!C31) -> 7 | O8: =('Clima institucional'!C37) -> 0.35 | V8: =('Clima institucional'!A31) -> Nunca | W8: =('Clima institucional'!D31) -> 7 | X8: =('Clima institucional'!D37) -> 0.35 | AE8: =('Clima institucional'!A31) -> Nunca | AF8: =('Clima institucional'!E31) -> 6 | AG8: =('Clima institucional'!E37) -> 0.3 | AN8: =('Clima institucional'!A31) -> Nunca | AO8: =('Clima institucional'!F31) -> 7 | AP8: =('Clima institucional'!F37) -> 0.35 | AW8: =('Clima institucional'!A31) -> Nunca | AX8: =('Clima institucional'!G31) -> 8 | AY8: =('Clima institucional'!G37) -> 0.4 | BF8: =('Clima institucional'!A31) -> Nunca | BG8: =('Clima institucional'!H31) -> 5 | BH8: =('Clima institucional'!H37) -> 0.25 | BO8: =('Clima institucional'!A31) -> Nunca | BP8: =('Clima institucional'!I31) -> 7 | BQ8: =('Clima institucional'!I37) -> 0.35 | BX8: =('Clima institucional'!A31) -> Nunca | BY8: =('Clima institucional'!J31) -> 9 | BZ8: =('Clima institucional'!J37) -> 0.45 | CG8: =('Clima institucional'!A31) -> Nunca | CH8: =('Clima institucional'!K31) -> 8 | CI8: =('Clima institucional'!K37) -> 0.4 | CP8: =('Clima institucional'!A31) -> Nunca | CQ8: =('Clima institucional'!L31) -> 8 | CR8: =('Clima institucional'!L37) -> 0.4 | CY8: =('Clima institucional'!A31) -> Nunca | CZ8: =('Clima institucional'!M31) -> 9 | DA8: =('Clima institucional'!M37) -> 0.45
D9: =('Clima institucional'!A32) -> Casi Nunca | E9: =('Clima institucional'!B32) -> 5 | F9: =('Clima institucional'!B38) -> 0.25 | M9: =('Clima institucional'!A32) -> Casi Nunca | N9: =('Clima institucional'!C32) -> 10 | O9: =('Clima institucional'!C38) -> 0.5 | V9: =('Clima institucional'!A32) -> Casi Nunca | W9: =('Clima institucional'!D32) -> 9 | X9: =('Clima institucional'!D38) -> 0.45 | AE9: =('Clima institucional'!A32) -> Casi Nunca | AF9: =('Clima institucional'!E32) -> 8 | AG9: =('Clima institucional'!E38) -> 0.4 | AN9: =('Clima institucional'!A32) -> Casi Nunca | AO9: =('Clima institucional'!F32) -> 8 | AP9: =('Clima institucional'!F38) -> 0.4 | AW9: =('Clima institucional'!A32) -> Casi Nunca | AX9: =('Clima institucional'!G32) -> 6 | AY9: =('Clima institucional'!G38) -> 0.3 | BF9: =('Clima institucional'!A32) -> Casi Nunca | BG9: =('Clima institucional'!H32) -> 8 | BH9: =('Clima institucional'!H38) -> 0.4 | BO9: =('Clima institucional'!A32) -> Casi Nunca | BP9: =('Clima institucional'!I32) -> 8 | BQ9: =('Clima institucional'!I38) -> 0.4 | BX9: =('Clima institucional'!A32) -> Casi Nunca | BY9: =('Clima institucional'!J32) -> 5 | BZ9: =('Clima institucional'!J38) -> 0.25 | CG9: =('Clima institucional'!A32) -> Casi Nunca | CH9: =('Clima institucional'!K32) -> 6 | CI9: =('Clima institucional'!K38) -> 0.3 | CP9: =('Clima institucional'!A32) -> Casi Nunca | CQ9: =('Clima institucional'!L32) -> 8 | CR9: =('Clima institucional'!L38) -> 0.4 | CY9: =('Clima institucional'!A32) -> Casi Nunca | CZ9: =('Clima institucional'!M32) -> 5 | DA9: =('Clima institucional'!M38) -> 0.25
D10: =('Clima institucional'!A33) -> A veces | E10: =('Clima institucional'!B33) -> 3 | F10: =('Clima institucional'!B39) -> 0.15 | M10: =('Clima institucional'!A33) -> A veces | N10: =('Clima institucional'!C33) -> 3 | O10: =('Clima institucional'!C39) -> 0.15 | V10: =('Clima institucional'!A33) -> A veces | W10: =('Clima institucional'!D33) -> 0 | X10: =('Clima institucional'!D39) -> 0 | AE10: =('Clima institucional'!A33) -> A veces | AF10: =('Clima institucional'!E33) -> 6 | AG10: =('Clima institucional'!E39) -> 0.3 | AN10: =('Clima institucional'!A33) -> A veces | AO10: =('Clima institucional'!F33) -> 2 | AP10: =('Clima institucional'!F39) -> 0.1 | AW10: =('Clima institucional'!A33) -> A veces | AX10: =('Clima institucional'!G33) -> 2 | AY10: =('Clima institucional'!G39) -> 0.1 | BF10: =('Clima institucional'!A33) -> A veces | BG10: =('Clima institucional'!H33) -> 7 | BH10: =('Clima institucional'!H39) -> 0.35 | BO10: =('Clima institucional'!A33) -> A veces | BP10: =('Clima institucional'!I33) -> 1 | BQ10: =('Clima institucional'!I39) -> 0.05 | BX10: =('Clima institucional'!A33) -> A veces | BY10: =('Clima institucional'!J33) -> 4 | BZ10: =('Clima institucional'!J39) -> 0.2 | CG10: =('Clima institucional'!A33) -> A veces | CH10: =('Clima institucional'!K33) -> 2 | CI10: =('Clima institucional'!K39) -> 0.1 | CP10: =('Clima institucional'!A33) -> A veces | CQ10: =('Clima institucional'!L33) -> 2 | CR10: =('Clima institucional'!L39) -> 0.1 | CY10: =('Clima institucional'!A33) -> A veces | CZ10: =('Clima institucional'!M33) -> 1 | DA10: =('Clima institucional'!M39) -> 0.05
D11: =('Clima institucional'!A34) -> Casi siempre | E11: =('Clima institucional'!B34) -> 1 | F11: =('Clima institucional'!B40) -> 0.05 | M11: =('Clima institucional'!A34) -> Casi siempre | N11: =('Clima institucional'!C34) -> 0 | O11: =('Clima institucional'!C40) -> 0 | V11: =('Clima institucional'!A34) -> Casi siempre | W11: =('Clima institucional'!D34) -> 2 | X11: =('Clima institucional'!D40) -> 0.1 | AE11: =('Clima institucional'!A34) -> Casi siempre | AF11: =('Clima institucional'!E34) -> 0 | AG11: =('Clima institucional'!E40) -> 0 | AN11: =('Clima institucional'!A34) -> Casi siempre | AO11: =('Clima institucional'!F34) -> 2 | AP11: =('Clima institucional'!F40) -> 0.1 | AW11: =('Clima institucional'!A34) -> Casi siempre | AX11: =('Clima institucional'!G34) -> 2 | AY11: =('Clima institucional'!G40) -> 0.1 | BF11: =('Clima institucional'!A34) -> Casi siempre | BG11: =('Clima institucional'!H34) -> 0 | BH11: =('Clima institucional'!H40) -> 0 | BO11: =('Clima institucional'!A34) -> Casi siempre | BP11: =('Clima institucional'!I34) -> 2 | BQ11: =('Clima institucional'!I40) -> 0.1 | BX11: =('Clima institucional'!A34) -> Casi siempre | BY11: =('Clima institucional'!J34) -> 1 | BZ11: =('Clima institucional'!J40) -> 0.05 | CG11: =('Clima institucional'!A34) -> Casi siempre | CH11: =('Clima institucional'!K34) -> 3 | CI11: =('Clima institucional'!K40) -> 0.15 | CP11: =('Clima institucional'!A34) -> Casi siempre | CQ11: =('Clima institucional'!L34) -> 2 | CR11: =('Clima institucional'!L40) -> 0.1 | CY11: =('Clima institucional'!A34) -> Casi siempre | CZ11: =('Clima institucional'!M34) -> 3 | DA11: =('Clima institucional'!M40) -> 0.15
D12: =('Clima institucional'!A35) -> Siempre | E12: =('Clima institucional'!B35) -> 1 | F12: =('Clima institucional'!B41) -> 0.05 | M12: =('Clima institucional'!A35) -> Siempre | N12: =('Clima institucional'!C35) -> 0 | O12: =('Clima institucional'!C41) -> 0 | V12: =('Clima institucional'!A35) -> Siempre | W12: =('Clima institucional'!D35) -> 2 | X12: =('Clima institucional'!D41) -> 0.1 | AE12: =('Clima institucional'!A35) -> Siempre | AF12: =('Clima institucional'!E35) -> 0 | AG12: =('Clima institucional'!E41) -> 0 | AN12: =('Clima institucional'!A35) -> Siempre | AO12: =('Clima institucional'!F35) -> 1 | AP12: =('Clima institucional'!F41) -> 0.05 | AW12: =('Clima institucional'!A35) -> Siempre | AX12: =('Clima institucional'!G35) -> 2 | AY12: =('Clima institucional'!G41) -> 0.1 | BF12: =('Clima institucional'!A35) -> Siempre | BG12: =('Clima institucional'!H35) -> 0 | BH12: =('Clima institucional'!H41) -> 0 | BO12: =('Clima institucional'!A35) -> Siempre | BP12: =('Clima institucional'!I35) -> 2 | BQ12: =('Clima institucional'!I41) -> 0.1 | BX12: =('Clima institucional'!A35) -> Siempre | BY12: =('Clima institucional'!J35) -> 1 | BZ12: =('Clima institucional'!J41) -> 0.05 | CG12: =('Clima institucional'!A35) -> Siempre | CH12: =('Clima institucional'!K35) -> 1 | CI12: =('Clima institucional'!K41) -> 0.05 | CP12: =('Clima institucional'!A35) -> Siempre | CQ12: =('Clima institucional'!L35) -> 0 | CR12: =('Clima institucional'!L41) -> 0 | CY12: =('Clima institucional'!A35) -> Siempre | CZ12: =('Clima institucional'!M35) -> 2 | DA12: =('Clima institucional'!M41) -> 0.1
D13: =('Clima institucional'!A36) -> Total | E13: =('Clima institucional'!B36) -> 20 | F13: =('Clima institucional'!B42) -> 1 | M13: =('Clima institucional'!A36) -> Total | N13: =('Clima institucional'!C36) -> 20 | O13: =('Clima institucional'!C42) -> 1 | V13: =('Clima institucional'!A36) -> Total | W13: =('Clima institucional'!D36) -> 20 | X13: =('Clima institucional'!D42) -> 1 | AE13: =('Clima institucional'!A36) -> Total | AF13: =('Clima institucional'!E36) -> 20 | AG13: =('Clima institucional'!E42) -> 1 | AN13: =('Clima institucional'!A36) -> Total | AO13: =('Clima institucional'!F36) -> 20 | AP13: =('Clima institucional'!F42) -> 1 | AW13: =('Clima institucional'!A36) -> Total | AX13: =('Clima institucional'!G36) -> 20 | AY13: =('Clima institucional'!G42) -> 1 | BF13: =('Clima institucional'!A36) -> Total | BG13: =('Clima institucional'!H36) -> 20 | BH13: =('Clima institucional'!H42) -> 1 | BO13: =('Clima institucional'!A36) -> Total | BP13: =('Clima institucional'!I36) -> 20 | BQ13: =('Clima institucional'!I42) -> 1 | BX13: =('Clima institucional'!A36) -> Total | BY13: =('Clima institucional'!J36) -> 20 | BZ13: =('Clima institucional'!J42) -> 1 | CG13: =('Clima institucional'!A36) -> Total | CH13: =('Clima institucional'!K36) -> 20 | CI13: =('Clima institucional'!K42) -> 1 | CP13: =('Clima institucional'!A36) -> Total | CQ13: =('Clima institucional'!L36) -> 20 | CR13: =('Clima institucional'!L42) -> 1 | CY13: =('Clima institucional'!A36) -> Total | CZ13: =('Clima institucional'!M36) -> 20 | DA13: =('Clima institucional'!M42) -> 1
D14: Elaboración: Propia | M14: Elaboración: Propia | V14: Elaboración: Propia | AE14: Elaboración: Propia | AN14: Elaboración: Propia | AW14: Elaboración: Propia | BF14: Elaboración: Propia | BO14: Elaboración: Propia | BX14: Elaboración: Propia | CG14: Elaboración: Propia | CP14: Elaboración: Propia | CY14: Elaboración: Propia
D15: Fuente: Encuesta aplicada | M15: Fuente: Encuesta aplicada | V15: Fuente: Encuesta aplicada | AE15: Fuente: Encuesta aplicada | AN15: Fuente: Encuesta aplicada | AW15: Fuente: Encuesta aplicada | BF15: Fuente: Encuesta aplicada | BO15: Fuente: Encuesta aplicada | BX15: Fuente: Encuesta aplicada | CG15: Fuente: Encuesta aplicada | CP15: Fuente: Encuesta aplicada | CY15: Fuente: Encuesta aplicada
D33: Figura. 1 | M33: Figura. 2 | V33: Figura. 3 | AE33: Figura. 4 | AN33: Figura. 5 | AW33: Figura. 6 | BF33: Figura. 7 | BO33: Figura. 8 | BX33: Figura. 9 | CG33: Figura. 10 | CP33: Figura. 11 | CY33: Figura. 12
D34: .
