Workbook

Sheet .
A1: Dimension 1
B3: . | X3: Total | Y3: Valoración
B4: PRG.1 | C4: PRG.2 | D4: PRG.3 | E4: PRG.4 | F4: PRG.5 | G4: PRG.6 | H4: PRG.7 | I4: PRG.8 | J4: PRG.9 | K4: PRG.10 | L4: PRG.11 | M4: PRG.12 | N4: PRG.13 | O4: PRG.14 | P4: PRG.15 | Q4: PRG.16 | R4: PRG.17 | S4: PRG.18 | T4: PRG.19 | U4: PRG.20 | V4: PRG.21 | W4: PRG.22
A5: Participante 1 | B5: 3 | C5: 4 | D5: 5 | E5: 4 | F5: 5 | G5: 5 | H5: 5 | I5: 2 | J5: 5 | K5: 5 | L5: 3 | M5: 2 | N5: 5 | O5: 3 | P5: 5 | Q5: 1 | R5: 5 | S5: 5 | T5: 4 | U5: 5 | V5: 2 | W5: 4 | X5: 87
A6: Participante 2 | B6: 3 | C6: 5 | D6: 4 | E6: 3 | F6: 4 | G6: 4 | H6: 5 | I6: 2 | J6: 4 | K6: 4 | L6: 2 | M6: 2 | N6: 4 | O6: 2 | P6: 4 | Q6: 3 | R6: 3 | S6: 5 | T6: 5 | U6: 5 | V6: 3 | W6: 5 | X6: 81
A7: Participante 3 | B7: 3 | C7: 2 | D7: 3 | E7: 2 | F7: 1 | G7: 2 | H7: 2 | I7: 3 | J7: 2 | K7: 2 | L7: 3 | M7: 1 | N7: 2 | O7: 2 | P7: 2 | Q7: 2 | R7: 3 | S7: 3 | T7: 2 | U7: 2 | V7: 3 | W7: 3 | X7: 50
A8: Participante 4 | B8: 2 | C8: 2 | D8: 3 | E8: 2 | F8: 3 | G8: 2 | H8: 3 | I8: 2 | J8: 3 | K8: 1 | L8: 1 | M8: 3 | N8: 2 | O8: 3 | P8: 2 | Q8: 2 | R8: 2 | S8: 2 | T8: 2 | U8: 2 | V8: 1 | W8: 2 | X8: 47
A9: Participante 5 | B9: 1 | C9: 4 | D9: 3 | E9: 2 | F9: 2 | G9: 2 | H9: 3 | I9: 2 | J9: 3 | K9: 2 | L9: 2 | M9: 1 | N9: 3 | O9: 2 | P9: 3 | Q9: 1 | R9: 2 | S9: 3 | T9: 3 | U9: 3 | V9: 3 | W9: 3 | X9: 53
A10: Participante 6 | B10: 2 | C10: 3 | D10: 5 | E10: 5 | F10: 3 | G10: 5 | H10: 5 | I10: 1 | J10: 5 | K10: 5 | L10: 1 | M10: 2 | N10: 5 | O10: 2 | P10: 5 | Q10: 1 | R10: 5 | S10: 5 | T10: 3 | U10: 5 | V10: 2 | W10: 5 | X10: 80
A11: Participante 7 | B11: 2 | C11: 4 | D11: 3 | E11: 3 | F11: 4 | G11: 5 | H11: 4 | I11: 2 | J11: 4 | K11: 3 | L11: 1 | M11: 2 | N11: 3 | O11: 2 | P11: 5 | Q11: 2 | R11: 4 | S11: 3 | T11: 3 | U11: 4 | V11: 2 | W11: 3 | X11: 68
A12: Participante 8 | B12: 1 | C12: 3 | D12: 2 | E12: 3 | F12: 3 | G12: 3 | H12: 3 | I12: 1 | J12: 3 | K12: 2 | L12: 2 | M12: 2 | N12: 2 | O12: 3 | P12: 3 | Q12: 2 | R12: 3 | S12: 2 | T12: 2 | U12: 3 | V12: 3 | W12: 2 | X12: 53
A13: Participante 9 | B13: 2 | C13: 4 | D13: 2 | E13: 3 | F13: 4 | G13: 3 | H13: 3 | I13: 3 | J13: 3 | K13: 3 | L13: 2 | M13: 2 | N13: 2 | O13: 1 | P13: 3 | Q13: 2 | R13: 4 | S13: 4 | T13: 3 | U13: 3 | V13: 2 | W13: 4 | X13: 62
A14: Participante 10 | B14: 3 | C14: 3 | D14: 4 | E14: 3 | F14: 2 | G14: 4 | H14: 3 | I14: 1 | J14: 3 | K14: 3 | L14: 2 | M14: 1 | N14: 2 | O14: 2 | P14: 2 | Q14: 2 | R14: 4 | S14: 3 | T14: 3 | U14: 4 | V14: 3 | W14: 2 | X14: 59
A15: Participante 11 | B15: 2 | C15: 3 | D15: 2 | E15: 2 | F15: 2 | G15: 2 | H15: 3 | I15: 3 | J15: 3 | K15: 2 | L15: 3 | M15: 1 | N15: 3 | O15: 2 | P15: 3 | Q15: 2 | R15: 3 | S15: 2 | T15: 4 | U15: 4 | V15: 1 | W15: 3 | X15: 55
A16: Participante 12 | B16: 2 | C16: 2 | D16: 2 | E16: 1 | F16: 2 | G16: 1 | H16: 2 | I16: 2 | J16: 2 | K16: 2 | L16: 1 | M16: 1 | N16: 1 | O16: 2 | P16: 2 | Q16: 1 | R16: 1 | S16: 1 | T16: 1 | U16: 2 | V16: 1 | W16: 1 | X16: 33
... A24: Participante 20 | B24: 2 | C24: 2 | D24: 2 | E24: 1 | F24: 1 | G24: 2 | H24: 2 | I24: 2 | J24: 2 | K24: 2 | L24: 1 | M24: 2 | N24: 2 | O24: 2 | P24: 2 | Q24: 2 | R24: 2 | S24: 2 | T24: 1 | U24: 1 | V24: 2 | W24: 1 | X24: 38
A25: TOTAL | B25: =SUM(B5:B24) -> 0 | C25: =SUM(C5:C24) -> 0 | D25: =SUM(D5:D24) -> 0 | E25: =SUM(E5:E24) -> 0 | F25: =SUM(F5:F24) -> 0 | G25: =SUM(G5:G24) -> 0 | H25: =SUM(H5:H24) -> 0 | I25: =SUM(I5:I24) -> 0 | ... X25: =SUM(X5:X24) -> 0
A26: MODA | B26: =MODE(B5:B24) -> 0 | C26: =MODE(C5:C24) -> 0 | D26: =MODE(D5:D24) -> 0 | E26: =MODE(E5:E24) -> 0 | F26: =MODE(F5:F24) -> 0 | G26: =MODE(G5:G24) -> 0 | H26: =MODE(H5:H24) -> 0 | I26: =MODE(I5:I24) -> 0 | ... X26: =MODE(X5:X24) -> 0
A27: MEDIA | B27: =(B25/20) -> 0 | C27: =(C25/20) -> 0 | D27: =(D25/20) -> 0 | E27: =(E25/20) -> 0 | F27: =(F25/20) -> 0 | G27: =(G25/20) -> 0 | H27: =(H25/20) -> 0 | I27: =(I25/20) -> 0 | ... X27: =(X25/20) -> 0
A28: MEDIANA | B28: =MEDIAN(B5:B24) -> 0 | C28: =MEDIAN(C5:C24) -> 0 | D28: =MEDIAN(D5:D24) -> 0 | E28: =MEDIAN(E5:E24) -> 0 | F28: =MEDIAN(F5:F24) -> 0 | G28: =MEDIAN(G5:G24) -> 0 | H28: =MEDIAN(H5:H24) -> 0 | I28: =MEDIAN(I5:I24) -> 0 | ... X28: =MEDIAN(X5:X24) -> 0
A29: Desv.Est | B29: =ROUND(STDEV(B5:B24),2) -> 0 | C29: =ROUND(STDEV(C5:C24),2) -> 0 | D29: =ROUND(STDEV(D5:D24),2) -> 0 | E29: =ROUND(STDEV(E5:E24),2) -> 0 | F29: =ROUND(STDEV(F5:F24),2) -> 0 | G29: =ROUND(STDEV(G5:G24),2) -> 0 | H29: =ROUND(STDEV(H5:H24),2) -> 0 | I29: =ROUND(STDEV(I5:I24),2) -> 0 | ... X29: =ROUND(STDEV(X5:X24),2) -> 0
A30: Coef. Varia. | B30: =(B29/B27) -> 0 | C30: =(C29/C27) -> 0 | D30: =(D29/D27) -> 0 | E30: =(E29/E27) -> 0 | F30: =(F29/F27) -> 0 | G30: =(G29/G27) -> 0 | H30: =(H29/H27) -> 0 | I30: =(I29/I27) -> 0 | ... X30: =(X29/X27) -> 0
A31: . | B31: =COUNTIF($B$5:$B$24,$A1020) -> 0 | C31: =COUNTIF($C$5:$C$24,$A1020) -> 0 | D31: =COUNTIF($D$5:$D$24,$A1020) -> 0 | E31: =COUNTIF($E$5:$E$24,$A1020) -> 0 | F31: =COUNTIF($F$5:$F$24,$A1020) -> 0 | G31: =COUNTIF($G$5:$G$24,$A1020) -> 0 | H31: =COUNTIF($H$5:$H$24,$A1020) -> 0 | I31: =COUNTIF($I$5:$I$24,$A1020) -> 0 | J31: =COUNTIF($J$5:$J$24,$A1020) -> 0 | K31: =COUNTIF($K$5:$K$24,$A1020) -> 0 | L31: =COUNTIF($L$5:$L$24,$A1020) -> 0 | M31: =COUNTIF($M$5:$M$24,$A1020) -> 0 | N31: =COUNTIF($N$5:$N$24,$A1020) -> 0 | O31: =COUNTIF($O$5:$O$24,$A1020) -> 0 | P31: =COUNTIF($P$5:$P$24,$A1020) -> 0 | Q31: =COUNTIF($Q$5:$Q$24,$A1020) -> 0 | R31: =COUNTIF($R$5:$R$24,$A1020) -> 0 | S31: =COUNTIF($S$5:$S$24,$A1020) -> 0 | T31: =COUNTIF($T$5:$T$24,$A1020) -> 0 | U31: =COUNTIF($U$5:$U$24,$A1020) -> 0 | V31: =COUNTIF($V$5:$V$24,$A1020) -> 0 | W31: =COUNTIF($W$5:$W$24,$A1020) -> 0
A32: . | B32: =COUNTIF($B$5:$B$24,$A1021) -> 0 | C32: =COUNTIF($C$5:$C$24,$A1021) -> 0 | D32: =COUNTIF($D$5:$D$24,$A1021) -> 0 | E32: =COUNTIF($E$5:$E$24,$A1021) -> 0 | F32: =COUNTIF($F$5:$F$24,$A1021) -> 0 | G32: =COUNTIF($G$5:$G$24,$A1021) -> 0 | H32: =COUNTIF($H$5:$H$24,$A1021) -> 0 | I32: =COUNTIF($I$5:$I$24,$A1021) -> 0 | J32: =COUNTIF($J$5:$J$24,$A1021) -> 0 | K32: =COUNTIF($K$5:$K$24,$A1021) -> 0 | L32: =COUNTIF($L$5:$L$24,$A1021) -> 0 | M32: =COUNTIF($M$5:$M$24,$A1021) -> 0 | N32: =COUNTIF($N$5:$N$24,$A1021) -> 0 | O32: =COUNTIF($O$5:$O$24,$A1021) -> 0 | P32: =COUNTIF($P$5:$P$24,$A1021) -> 0 | Q32: =COUNTIF($Q$5:$Q$24,$A1021) -> 0 | R32: =COUNTIF($R$5:$R$24,$A1021) -> 0 | S32: =COUNTIF($S$5:$S$24,$A1021) -> 0 | T32: =COUNTIF($T$5:$T$24,$A1021) -> 0 | U32: =COUNTIF($U$5:$U$24,$A1021) -> 0 | V32: =COUNTIF($V$5:$V$24,$A1021) -> 0 | W32: =COUNTIF($W$5:$W$24,$A1021) -> 0
A33: . | B33: =COUNTIF($B$5:$B$24,$A1022) -> 0 | C33: =COUNTIF($C$5:$C$24,$A1022) -> 0 | D33: =COUNTIF($D$5:$D$24,$A1022) -> 0 | E33: =COUNTIF($E$5:$E$24,$A1022) -> 0 | F33: =COUNTIF($F$5:$F$24,$A1022) -> 0 | G33: =COUNTIF($G$5:$G$24,$A1022) -> 0 | H33: =COUNTIF($H$5:$H$24,$A1022) -> 0 | I33: =COUNTIF($I$5:$I$24,$A1022) -> 0 | J33: =COUNTIF($J$5:$J$24,$A1022) -> 0 | K33: =COUNTIF($K$5:$K$24,$A1022) -> 0 | L33: =COUNTIF($L$5:$L$24,$A1022) -> 0 | M33: =COUNTIF($M$5:$M$24,$A1022) -> 0 | N33: =COUNTIF($N$5:$N$24,$A1022) -> 0 | O33: =COUNTIF($O$5:$O$24,$A1022) -> 0 | P33: =COUNTIF($P$5:$P$24,$A1022) -> 0 | Q33: =COUNTIF($Q$5:$Q$24,$A1022) -> 0 | R33: =COUNTIF($R$5:$R$24,$A1022) -> 0 | S33: =COUNTIF($S$5:$S$24,$A1022) -> 0 | T33: =COUNTIF($T$5:$T$24,$A1022) -> 0 | U33: =COUNTIF($U$5:$U$24,$A1022) -> 0 | V33: =COUNTIF($V$5:$V$24,$A1022) -> 0 | W33: =COUNTIF($W$5:$W$24,$A1022) -> 0
A34: . | B34: =COUNTIF($B$5:$B$24,$A1023) -> 0 | C34: =COUNTIF($C$5:$C$24,$A1023) -> 0 | D34: =COUNTIF($D$5:$D$24,$A1023) -> 0 | E34: =COUNTIF($E$5:$E$24,$A1023) -> 0 | F34: =COUNTIF($F$5:$F$24,$A1023) -> 0 | G34: =COUNTIF($G$5:$G$24,$A1023) -> 0 | H34: =COUNTIF($H$5:$H$24,$A1023) -> 0 | I34: =COUNTIF($I$5:$I$24,$A1023) -> 0 | J34: =COUNTIF($J$5:$J$24,$A1023) -> 0 | K34: =COUNTIF($K$5:$K$24,$A1023) -> 0 | L34: =COUNTIF($L$5:$L$24,$A1023) -> 0 | M34: =COUNTIF($M$5:$M$24,$A1023) -> 0 | N34: =COUNTIF($N$5:$N$24,$A1023) -> 0 | O34: =COUNTIF($O$5:$O$24,$A1023) -> 0 | P34: =COUNTIF($P$5:$P$24,$A1023) -> 0 | Q34: =COUNTIF($Q$5:$Q$24,$A1023) -> 0 | R34: =COUNTIF($R$5:$R$24,$A1023) -> 0 | S34: =COUNTIF($S$5:$S$24,$A1023) -> 0 | T34: =COUNTIF($T$5:$T$24,$A1023) -> 0 | U34: =COUNTIF($U$5:$U$24,$A1023) -> 0 | V34: =COUNTIF($V$5:$V$24,$A1023) -> 0 | W34: =COUNTIF($W$5:$W$24,$A1023) -> 0
A35: . | B35: =COUNTIF($B$5:$B$24,$A1024) -> 0 | C35: =COUNTIF($C$5:$C$24,$A1024) -> 0 | D35: =COUNTIF($D$5:$D$24,$A1024) -> 0 | E35: =COUNTIF($E$5:$E$24,$A1024) -> 0 | F35: =COUNTIF($F$5:$F$24,$A1024) -> 0 | G35: =COUNTIF($G$5:$G$24,$A1024) -> 0 | H35: =COUNTIF($H$5:$H$24,$A1024) -> 0 | I35: =COUNTIF($I$5:$I$24,$A1024) -> 0 | J35: =COUNTIF($J$5:$J$24,$A1024) -> 0 | K35: =COUNTIF($K$5:$K$24,$A1024) -> 0 | L35: =COUNTIF($L$5:$L$24,$A1024) -> 0 | M35: =COUNTIF($M$5:$M$24,$A1024) -> 0 | N35: =COUNTIF($N$5:$N$24,$A1024) -> 0 | O35: =COUNTIF($O$5:$O$24,$A1024) -> 0 | P35: =COUNTIF($P$5:$P$24,$A1024) -> 0 | Q35: =COUNTIF($Q$5:$Q$24,$A1024) -> 0 | R35: =COUNTIF($R$5:$R$24,$A1024) -> 0 | S35: =COUNTIF($S$5:$S$24,$A1024) -> 0 | T35: =COUNTIF($T$5:$T$24,$A1024) -> 0 | U35: =COUNTIF($U$5:$U$24,$A1024) -> 0 | V35: =COUNTIF($V$5:$V$24,$A1024) -> 0 | W35: =COUNTIF($W$5:$W$24,$A1024) -> 0
A36: Total | B36: =SUM($B31:$B35) -> 0 | C36: =SUM($C31:$C35) -> 0 | D36: =SUM($D31:$D35) -> 0 | E36: =SUM($E31:$E35) -> 0 | F36: =SUM($F31:$F35) -> 0 | G36: =SUM($G31:$G35) -> 0 | H36: =SUM($H31:$H35) -> 0 | I36: =SUM($I31:$I35) -> 0 | J36: =SUM($J31:$J35) -> 0 | K36: =SUM($K31:$K35) -> 0 | L36: =SUM($L31:$L35) -> 0 | M36: =SUM($M31:$M35) -> 0 | N36: =SUM($N31:$N35) -> 0 | O36: =SUM($O31:$O35) -> 0 | P36: =SUM($P31:$P35) -> 0 | Q36: =SUM($Q31:$Q35) -> 0 | R36: =SUM($R31:$R35) -> 0 | S36: =SUM($S31:$S35) -> 0 | T36: =SUM($T31:$T35) -> 0 | U36: =SUM($U31:$U35) -> 0 | V36: =SUM($V31:$V35) -> 0 | W36: =SUM($W31:$W35) -> 0
A37: .% | B37: =($B31/$B36) -> 0 | C37: =($C31/$C36) -> 0 | D37: =($D31/$D36) -> 0 | E37: =($E31/$E36) -> 0 | F37: =($F31/$F36) -> 0 | G37: =($G31/$G36) -> 0 | H37: =($H31/$H36) -> 0 | I37: =($I31/$I36) -> 0 | J37: =($J31/$J36) -> 0 | K37: =($K31/$K36) -> 0 | L37: =($L31/$L36) -> 0 | M37: =($M31/$M36) -> 0 | N37: =($N31/$N36) -> 0 | O37: =($O31/$O36) -> 0 | P37: =($P31/$P36) -> 0 | Q37: =($Q31/$Q36) -> 0 | R37: =($R31/$R36) -> 0 | S37: =($S31/$S36) -> 0 | T37: =($T31/$T36) -> 0 | U37: =($U31/$U36) -> 0 | V37: =($V31/$V36) -> 0 | W37: =($W31/$W36) -> 0
A38: .% | B38: =($B32/$B36) -> 0 | C38: =($C32/$C36) -> 0 | D38: =($D32/$D36) -> 0 | E38: =($E32/$E36) -> 0 | F38: =($F32/$F36) -> 0 | G38: =($G32/$G36) -> 0 | H38: =($H32/$H36) -> 0 | I38: =($I32/$I36) -> 0 | J38: =($J32/$J36) -> 0 | K38: =($K32/$K36) -> 0 | L38: =($L32/$L36) -> 0 | M38: =($M32/$M36) -> 0 | N38: =($N32/$N36) -> 0 | O38: =($O32/$O36) -> 0 | P38: =($P32/$P36) -> 0 | Q38: =($Q32/$Q36) -> 0 | R38: =($R32/$R36) -> 0 | S38: =($S32/$S36) -> 0 | T38: =($T32/$T36) -> 0 | U38: =($U32/$U36) -> 0 | V38: =($V32/$V36) -> 0 | W38: =($W32/$W36) -> 0
A39: .% | B39: =($B33/$B36) -> 0 | C39: =($C33/$C36) -> 0 | D39: =($D33/$D36) -> 0 | E39: =($E33/$E36) -> 0 | F39: =($F33/$F36) -> 0 | G39: =($G33/$G36) -> 0 | H39: =($H33/$H36) -> 0 | I39: =($I33/$I36) -> 0 | J39: =($J33/$J36) -> 0 | K39: =($K33/$K36) -> 0 | L39: =($L33/$L36) -> 0 | M39: =($M33/$M36) -> 0 | N39: =($N33/$N36) -> 0 | O39: =($O33/$O36) -> 0 | P39: =($P33/$P36) -> 0 | Q39: =($Q33/$Q36) -> 0 | R39: =($R33/$R36) -> 0 | S39: =($S33/$S36) -> 0 | T39: =($T33/$T36) -> 0 | U39: =($U33/$U36) -> 0 | V39: =($V33/$V36) -> 0 | W39: =($W33/$W36) -> 0
A40: .% | B40: =($B34/$B36) -> 0 | C40: =($C34/$C36) -> 0 | D40: =($D34/$D36) -> 0 | E40: =($E34/$E36) -> 0 | F40: =($F34/$F36) -> 0 | G40: =($G34/$G36) -> 0 | H40: =($H34/$H36) -> 0 | I40: =($I34/$I36) -> 0 | J40: =($J34/$J36) -> 0 | K40: =($K34/$K36) -> 0 | L40: =($L34/$L36) -> 0 | M40: =($M34/$M36) -> 0 | N40: =($N34/$N36) -> 0 | O40: =($O34/$O36) -> 0 | P40: =($P34/$P36) -> 0 | Q40: =($Q34/$Q36) -> 0 | R40: =($R34/$R36) -> 0 | S40: =($S34/$S36) -> 0 | T40: =($T34/$T36) -> 0 | U40: =($U34/$U36) -> 0 | V40: =($V34/$V36) -> 0 | W40: =($W34/$W36) -> 0
A41: .% | B41: =($B35/$B36) -> 0 | C41: =($C35/$C36) -> 0 | D41: =($D35/$D36) -> 0 | E41: =($E35/$E36) -> 0 | F41: =($F35/$F36) -> 0 | G41: =($G35/$G36) -> 0 | H41: =($H35/$H36) -> 0 | I41: =($I35/$I36) -> 0 | J41: =($J35/$J36) -> 0 | K41: =($K35/$K36) -> 0 | L41: =($L35/$L36) -> 0 | M41: =($M35/$M36) -> 0 | N41: =($N35/$N36) -> 0 | O41: =($O35/$O36) -> 0 | P41: =($P35/$P36) -> 0 | Q41: =($Q35/$Q36) -> 0 | R41: =($R35/$R36) -> 0 | S41: =($S35/$S36) -> 0 | T41: =($T35/$T36) -> 0 | U41: =($U35/$U36) -> 0 | V41: =($V35/$V36) -> 0 | W41: =($W35/$W36) -> 0
A42: Total % | B42: =SUM($B37:$B41) -> 0 | C42: =SUM($C37:$C41) -> 0 | D42: =SUM($D37:$D41) -> 0 | E42: =SUM($E37:$E41) -> 0 | F42: =SUM($F37:$F41) -> 0 | G42: =SUM($G37:$G41) -> 0 | H42: =SUM($H37:$H41) -> 0 | I42: =SUM($I37:$I41) -> 0 | J42: =SUM($J37:$J41) -> 0 | K42: =SUM($K37:$K41) -> 0 | L42: =SUM($L37:$L41) -> 0 | M42: =SUM($M37:$M41) -> 0 | N42: =SUM($N37:$N41) -> 0 | O42: =SUM($O37:$O41) -> 0 | P42: =SUM($P37:$P41) -> 0 | Q42: =SUM($Q37:$Q41) -> 0 | R42: =SUM($R37:$R41) -> 0 | S42: =SUM($S37:$S41) -> 0 | T42: =SUM($T37:$T41) -> 0 | U42: =SUM($U37:$U41) -> 0 | V42: =SUM($V37:$V41) -> 0 | W42: =SUM($W37:$W41) -> 0
A1020: 1
A1021: 2
A1022: 3
A1023: 4
A1024: 5
B1025: =SUM($B1020:$B1024) -> 0 | C1025: =SUM($C1020:$C1024) -> 0 | D1025: =SUM($D1020:$D1024) -> 0 | E1025: =SUM($E1020:$E1024) -> 0 | F1025: =SUM($F1020:$F1024) -> 0 | G1025: =SUM($G1020:$G1024) -> 0 | H1025: =SUM($H1020:$H1024) -> 0 | I1025: =SUM($I1020:$I1024) -> 0 | J1025: =SUM($J1020:$J1024) -> 0 | K1025: =SUM($K1020:$K1024) -> 0 | L1025: =SUM($L1020:$L1024) -> 0 | M1025: =SUM($M1020:$M1024) -> 0 | N1025: =SUM($N1020:$N1024) -> 0 | O1025: =SUM($O1020:$O1024) -> 0 | P1025: =SUM($P1020:$P1024) -> 0 | Q1025: =SUM($Q1020:$Q1024) -> 0 | R1025: =SUM($R1020:$R1024) -> 0 | S1025: =SUM($S1020:$S1024) -> 0 | T1025: =SUM($T1020:$T1024) -> 0 | U1025: =SUM($U1020:$U1024) -> 0 | V1025: =SUM($V1020:$V1024) -> 0 | W1025: =SUM($W1020:$W1024) -> 0
...

Sheet Por Valoracion (3) Dimension
A1: Dimension 1
A2: Nº de Personas | B2: . | D2: .
B3: Suma Total | C3: Valoración | D3: Suma Total | E3: Valoración
A4: Participante 1 | B4: =SUM('.'!B5:W5) -> 0 | C4: =IF(B4<=$M$19,".",IF(B4<=$M$20,".",IF(B4<=$M$21,".",0))) -> 0 | D4: =SUM(B4:B4) -> 0 | E4: =IF(D4<=$Y$19,".",IF(D4<=$Y$20,".",IF(D4<=$Y$21,".",0))) -> 0 | I4: Variable | J4: . | U4: Variable | V4: .
A5: Participante 2 | B5: =SUM('.'!B6:W6) -> 0 | C5: =IF(B5<=$M$19,".",IF(B5<=$M$20,".",IF(B5<=$M$21,".",0))) -> 0 | D5: =SUM(B5:B5) -> 0 | E5: =IF(D5<=$Y$19,".",IF(D5<=$Y$20,".",IF(D5<=$Y$21,".",0))) -> 0 | I5: Nombre de la Dimensión | J5: =B2 -> 0
A6: Participante 3 | B6: =SUM('.'!B7:W7) -> 0 | C6: =IF(B6<=$M$19,".",IF(B6<=$M$20,".",IF(B6<=$M$21,".",0))) -> 0 | D6: =SUM(B6:B6) -> 0 | E6: =IF(D6<=$Y$19,".",IF(D6<=$Y$20,".",IF(D6<=$Y$21,".",0))) -> 0 | I6: Cantidad de Escalas Valorativas | J6: 3 | U6: Cantidad de Escalas Valorativas | V6: 3
A7: Participante 4 | B7: =SUM('.'!B8:W8) -> 0 | C7: =IF(B7<=$M$19,".",IF(B7<=$M$20,".",IF(B7<=$M$21,".",0))) -> 0 | D7: =SUM(B7:B7) -> 0 | E7: =IF(D7<=$Y$19,".",IF(D7<=$Y$20,".",IF(D7<=$Y$21,".",0))) -> 0 | I7: Nº de Peguntas | J7: 22 | U7: Nº de Peguntas | V7: 22
A8: Participante 5 | B8: =SUM('.'!B9:W9) -> 0 | C8: =IF(B8<=$M$19,".",IF(B8<=$M$20,".",IF(B8<=$M$21,".",0))) -> 0 | D8: =SUM(B8:B8) -> 0 | E8: =IF(D8<=$Y$19,".",IF(D8<=$Y$20,".",IF(D8<=$Y$21,".",0))) -> 0 | I8: Valor Mínimo por item | J8: 1 | U8: Valor Mínimo por item | V8: 1
A9: Participante 6 | B9: =SUM('.'!B10:W10) -> 0 | C9: =IF(B9<=$M$19,".",IF(B9<=$M$20,".",IF(B9<=$M$21,".",0))) -> 0 | D9: =SUM(B9:B9) -> 0 | E9: =IF(D9<=$Y$19,".",IF(D9<=$Y$20,".",IF(D9<=$Y$21,".",0))) -> 0 | I9: Valor Máximo por item | J9: 5 | U9: Valor Máximo por item | V9: 5
A10: Participante 7 | B10: =SUM('.'!B11:W11) -> 0 | C10: =IF(B10<=$M$19,".",IF(B10<=$M$20,".",IF(B10<=$M$21,".",0))) -> 0 | D10: =SUM(B10:B10) -> 0 | E10: =IF(D10<=$Y$19,".",IF(D10<=$Y$20,".",IF(D10<=$Y$21,".",0))) -> 0 | I10: Máximo | J10: =J7*J9 -> 0 | U10: Máximo | V10: =V7*V9 -> 0
A11: Participante 8 | B11: =SUM('.'!B12:W12) -> 0 | C11: =IF(B11<=$M$19,".",IF(B11<=$M$20,".",IF(B11<=$M$21,".",0))) -> 0 | D11: =SUM(B11:B11) -> 0 | E11: =IF(D11<=$Y$19,".",IF(D11<=$Y$20,".",IF(D11<=$Y$21,".",0))) -> 0 | I11: Mínimo | J11: =J8*J7 -> 0 | U11: Mínimo | V11: =V8*V7 -> 0
A12: Participante 9 | B12: =SUM('.'!B13:W13) -> 0 | C12: =IF(B12<=$M$19,".",IF(B12<=$M$20,".",IF(B12<=$M$21,".",0))) -> 0 | D12: =SUM(B12:B12) -> 0 | E12: =IF(D12<=$Y$19,".",IF(D12<=$Y$20,".",IF(D12<=$Y$21,".",0))) -> 0 | I12: Rango | J12: =J10-J11 -> 0 | U12: Rango | V12: =V10-V11 -> 0
A13: Participante 10 | B13: =SUM('.'!B14:W14) -> 0 | C13: =IF(B13<=$M$19,".",IF(B13<=$M$20,".",IF(B13<=$M$21,".",0))) -> 0 | D13: =SUM(B13:B13) -> 0 | E13: =IF(D13<=$Y$19,".",IF(D13<=$Y$20,".",IF(D13<=$Y$21,".",0))) -> 0 | I13: Amplitud del Intervalo | J13: =ROUND(J12/J6,0) -> 0 | U13: Amplitud del Intervalo | V13: =ROUND(V12/V6,0) -> 0
A14: Participante 11 | B14: =SUM('.'!B15:W15) -> 0 | C14: =IF(B14<=$M$19,".",IF(B14<=$M$20,".",IF(B14<=$M$21,".",0))) -> 0 | D14: =SUM(B14:B14) -> 0 | E14: =IF(D14<=$Y$19,".",IF(D14<=$Y$20,".",IF(D14<=$Y$21,".",0))) -> 0
A15: Participante 12 | B15: =SUM('.'!B16:W16) -> 0 | C15: =IF(B15<=$M$19,".",IF(B15<=$M$20,".",IF(B15<=$M$21,".",0))) -> 0 | D15: =SUM(B15:B15) -> 0 | E15: =IF(D15<=$Y$19,".",IF(D15<=$Y$20,".",IF(D15<=$Y$21,".",0))) -> 0 | K15: Tabla 1 | W15: Tabla 2
A16: Participante 13 | B16: =SUM('.'!B17:W17) -> 0 | C16: =IF(B16<=$M$19,".",IF(B16<=$M$20,".",IF(B16<=$M$21,".",0))) -> 0 | D16: =SUM(B16:B16) -> 0 | E16: =IF(D16<=$Y$19,".",IF(D16<=$Y$20,".",IF(D16<=$Y$21,".",0))) -> 0 | K16: =J5 -> 0 | W16: =V4 -> 0
A17: Participante 14 | B17: =SUM('.'!B18:W18) -> 0 | C17: =IF(B17<=$M$19,".",IF(B17<=$M$20,".",IF(B17<=$M$21,".",0))) -> 0 | D17: =SUM(B17:B17) -> 0 | E17: =IF(D17<=$Y$19,".",IF(D17<=$Y$20,".",IF(D17<=$Y$21,".",0))) -> 0 | K17: Calificación | L17: Rango | N17: Frec. | O17: % | W17: Calificación | X17: Rango | Z17: Frec. | AA17: %
A18: Participante 15 | B18: =SUM('.'!B19:W19) -> 0 | C18: =IF(B18<=$M$19,".",IF(B18<=$M$20,".",IF(B18<=$M$21,".",0))) -> 0 | D18: =SUM(B18:B18) -> 0 | E18: =IF(D18<=$Y$19,".",IF(D18<=$Y$20,".",IF(D18<=$Y$21,".",0))) -> 0 | L18: Desde | M18: Hasta | X18: Desde | Y18: Hasta
A19: Participante 16 | B19: =SUM('.'!B20:W20) -> 0 | C19: =IF(B19<=$M$19,".",IF(B19<=$M$20,".",IF(B19<=$M$21,".",0))) -> 0 | D19: =SUM(B19:B19) -> 0 | E19: =IF(D19<=$Y$19,".",IF(D19<=$Y$20,".",IF(D19<=$Y$21,".",0))) -> 0 | K19: . | L19: =J11 -> 0 | M19: =L19+J13 -> 0 | N19: =COUNTIF($C$4:$C$23,$K19) -> 0 | O19: =N19/N22 -> 0 | W19: . | X19: =V11 -> 0 | Y19: =X19+V13 - 1 -> 0 | Z19: =COUNTIF($E$4:$E$23,$W19) -> 0 | AA19: =Z19/Z22 -> 0
A20: Participante 17 | B20: =SUM('.'!B21:W21) -> 0 | C20: =IF(B20<=$M$19,".",IF(B20<=$M$20,".",IF(B20<=$M$21,".",0))) -> 0 | D20: =SUM(B20:B20) -> 0 | E20: =IF(D20<=$Y$19,".",IF(D20<=$Y$20,".",IF(D20<=$Y$21,".",0))) -> 0 | K20: . | L20: =M19+ 1 -> 0 | M20: =L20+J13 -> 0 | N20: =COUNTIF($C$4:$C$23,$K20) -> 0 | O20: =N20/N22 -> 0 | W20: . | X20: =Y19+ 1 -> 0 | Y20: =X20+V13 - 1 -> 0 | Z20: =COUNTIF($E$4:$E$23,$W20) -> 0 | AA20: =Z20/Z22 -> 0
A21: Participante 18 | B21: =SUM('.'!B22:W22) -> 0 | C21: =IF(B21<=$M$19,".",IF(B21<=$M$20,".",IF(B21<=$M$21,".",0))) -> 0 | D21: =SUM(B21:B21) -> 0 | E21: =IF(D21<=$Y$19,".",IF(D21<=$Y$20,".",IF(D21<=$Y$21,".",0))) -> 0 | K21: . | L21: =M20+ 1 -> 0 | M21: =J10 -> 0 | N21: =COUNTIF($C$4:$C$23,$K21) -> 0 | O21: =N21/N22 -> 0 | W21: . | X21: =Y20+ 1 -> 0 | Y21: =V10 -> 0 | Z21: =COUNTIF($E$4:$E$23,$W21) -> 0 | AA21: =Z21/Z22 -> 0
A22: Participante 19 | B22: =SUM('.'!B23:W23) -> 0 | C22: =IF(B22<=$M$19,".",IF(B22<=$M$20,".",IF(B22<=$M$21,".",0))) -> 0 | D22: =SUM(B22:B22) -> 0 | E22: =IF(D22<=$Y$19,".",IF(D22<=$Y$20,".",IF(D22<=$Y$21,".",0))) -> 0 | K22: Total | N22: =SUM(N19:N21) -> 0 | O22: =SUM(O19:O21) -> 0 | W22: Total | Z22: =SUM(Z19:Z21) -> 0 | AA22: =SUM(AA19:AA21) -> 0
A23: Participante 20 | B23: =SUM('.'!B24:W24) -> 0 | C23: =IF(B23<=$M$19,".",IF(B23<=$M$20,".",IF(B23<=$M$21,".",0))) -> 0 | D23: =SUM(B23:B23) -> 0 | E23: =IF(D23<=$Y$19,".",IF(D23<=$Y$20,".",IF(D23<=$Y$21,".",0))) -> 0 | K23: Fuente: Encuesta aplicada | W23: Fuente: Encuesta aplicada
K24: Elaboración: Propia | W24: Elaboración: Propia
K43: Figura.1 | W43: Figura.2
K44: . | W44: .
I47: =CONCATENATE("en la ",K15," y ",K43," se puede observar que la variable ",H901," en base a su dimensión ",H902," tiene una calificación de ",I904," por el ",ROUND(H904*100,0),"% ","de los resultados, ","los cuales fueron extraídos de las encuestas ejecutadas a los ",J902,", estos resultados son afectados debido a que, ",Q1016," ",I1016,",","asi mismo ",Q1017," ",I1017,", aunque ",Q1018," ",I1018,", aunque ",Q1019," ",I1019,", además ",Q1020," ",I1020,", de modo que ",Q1021," ",I1021,", aunque ",Q1022," ",I1022,", sin embargo ",Q1023," ",I1023,", aunque ",Q1024," ",I1024,", así ",Q1025," ",I1025,", además ",Q1026," ",I1026,", aunque ",Q1027," ",I1027,", sin embargo ",Q1028," ",I1028,", en cambio ",Q1029," ",I1029,", también ",Q1030," ",I1030,", mismo ",Q1031," ",I1031,", de modo que ",Q1032," ",I1032,", también ",Q1033," ",I1033,", aunque ",Q1034," ",I1034,", con motivo ",Q1035," ",I1035,", no obstante ",Q1036," ",I1036, ", ","y ",I1037," ",Q1037,", ","por todo ello la dimensión ",H902," es ",I904,".") -> 0 | U47: =CONCATENATE("En la ",W15," y ",W43," se puede evidenciar que la variable ",T901," es calificado como ",U904," por el ",ROUND(T904*100,0),"% de los resultados, mismos que son originados porque; ",AG1016," ",AG1017," ",AG1018,AG1019,AG1020,AG1021,AG1022,AG1023,AG1024,AG1025,AG1026," se concluye que la variable ",T901,"tiene un valor de ",U904,".") -> 0
G901: Variable | H901: =(J4) -> 0 | J901: Unidades de Medida | S901: Variable | T901: =(V4) -> 0 | V901: Unidades de Medida
G902: Dimensión | H902: =(J5) -> 0 | J902: Participantes | S902: Dimensión | T902: =(V5) -> 0 | V902: Participantes
G904: Valoración de la variable | H904: =MAX(O19:O21) -> 0 | I904: =IF(H2104=O19,K19,IF(H2104=O20,K20,IF(H2104=O21,K21,"algo esta mal"))) -> 0 | S904: Valoración de la variable | T904: =MAX(AA19:AA21) -> 0 | U904: =IF(T2104=AA19,W19,IF(T2104=AA20,W20,IF(T2104=AA21,W21,"algo esta mal"))) -> 0
I905: Preguntas Originales | J905: Enunciados Para Palafraseo | K905: . | L905: . | M905: . | N905: . | O905: .
I906: . | J906: . | K906: =('.'!B37) -> 0 | L906: =('.'!B38) -> 0 | M906: =('.'!B39) -> 0 | N906: =('.'!B40) -> 0 | O906: =('.'!B41) -> 0
I907: . | J907: . | K907: =('.'!C37) -> 0 | L907: =('.'!C38) -> 0 | M907: =('.'!C39) -> 0 | N907: =('.'!C40) -> 0 | O907: =('.'!C41) -> 0
K908: =('.'!D37) -> 0 | L908: =('.'!D38) -> 0 | M908: =('.'!D39) -> 0 | N908: =('.'!D40) -> 0 | O908: =('.'!D41) -> 0
K909: =('.'!E37) -> 0 | L909: =('.'!E38) -> 0 | M909: =('.'!E39) -> 0 | N909: =('.'!E40) -> 0 | O909: =('.'!E41) -> 0
K910: =('.'!F37) -> 0 | L910: =('.'!F38) -> 0 | M910: =('.'!F39) -> 0 | N910: =('.'!F40) -> 0 | O910: =('.'!F41) -> 0
K911: =('.'!G37) -> 0 | L911: =('.'!G38) -> 0 | M911: =('.'!G39) -> 0 | N911: =('.'!G40) -> 0 | O911: =('.'!G41) -> 0
K912: =('.'!H37) -> 0 | L912: =('.'!H38) -> 0 | M912: =('.'!H39) -> 0 | N912: =('.'!H40) -> 0 | O912: =('.'!H41) -> 0
K913: =('.'!I37) -> 0 | L913: =('.'!I38) -> 0 | M913: =('.'!I39) -> 0 | N913: =('.'!I40) -> 0 | O913: =('.'!I41) -> 0
K914: =('.'!J37) -> 0 | L914: =('.'!J38) -> 0 | M914: =('.'!J39) -> 0 | N914: =('.'!J40) -> 0 | O914: =('.'!J41) -> 0
...

Sheet Tabulacion por item
D4: Item 1 | M4: Item 2 | V4: Item 3 | AE4: Item 4 | AN4: Item 5 | AW4: Item 6 | BF4: Item 7 | BO4: Item 8 | BX4: Item 9 | CG4: Item 10 | CP4: Item 11 | CY4: Item 12 | DH4: Item 13 | DQ4: Item 14 | DZ4: Item 15 | EI4: Item 16 | ER4: Item 17 | FA4: Item 18 | FJ4: Item 19 | FS4: Item 20 | GB4: Item 21 | GK4: Item 22
D5: Tabla 1 | M5: Tabla 2 | V5: Tabla 3 | AE5: Tabla 4 | AN5: Tabla 5 | AW5: Tabla 6 | BF5: Tabla 7 | BO5: Tabla 8 | BX5: Tabla 9 | CG5: Tabla 10 | CP5: Tabla 11 | CY5: Tabla 12 | DH5: Tabla 13 | DQ5: Tabla 14 | DZ5: Tabla 15 | EI5: Tabla 16 | ER5: Tabla 17 | FA5: Tabla 18 | FJ5: Tabla 19 | FS5: Tabla 20 | GB5: Tabla 21 | GK5: Tabla 22
D6: . | M6: .
E7: Frec. | F7: % | N7: Frec. | O7: % | W7: Frec. | X7: % | AF7: Frec. | AG7: % | AO7: Frec. | AP7: % | AX7: Frec. | AY7: % | BG7: Frec. | BH7: % | BP7: Frec. | BQ7: % | BY7: Frec. | BZ7: % | CH7: Frec. | CI7: % | CQ7: Frec. | CR7: % | CZ7: Frec. | DA7: % | DI7: Frec. | DJ7: % | DR7: Frec. | DS7: % | EA7: Frec. | EB7: % | EJ7: Frec. | EK7: % | ES7: Frec. | ET7: % | FB7: Frec. | FC7: % | FK7: Frec. | FL7: % | FT7: Frec. | FU7: % | GC7: Frec. | GD7: % | GL7: Frec. | GM7: %
D8: =('.'!A31) -> 0 | E8: =('.'!B31) -> 0 | F8: =('.'!B37) -> 0 | M8: =('.'!A31) -> 0 | N8: =('.'!C31) -> 0 | O8: =('.'!C37) -> 0 | V8: =('.'!A31) -> 0 | W8: =('.'!D31) -> 0 | X8: =('.'!D37) -> 0 | AE8: =('.'!A31) -> 0 | AF8: =('.'!E31) -> 0 | AG8: =('.'!E37) -> 0 | AN8: =('.'!A31) -> 0 | AO8: =('.'!F31) -> 0 | AP8: =('.'!F37) -> 0 | AW8: =('.'!A31) -> 0 | AX8: =('.'!G31) -> 0 | AY8: =('.'!G37) -> 0 | BF8: =('.'!A31) -> 0 | BG8: =('.'!H31) -> 0 | BH8: =('.'!H37) -> 0 | BO8: =('.'!A31) -> 0 | BP8: =('.'!I31) -> 0 | BQ8: =('.'!I37) -> 0 | BX8: =('.'!A31) -> 0 | BY8: =('.'!J31) -> 0 | BZ8: =('.'!J37) -> 0 | CG8: =('.'!A31) -> 0 | CH8: =('.'!K31) -> 0 | CI8: =('.'!K37) -> 0 | CP8: =('.'!A31) -> 0 | CQ8: =('.'!L31) -> 0 | CR8: =('.'!L37) -> 0 | CY8: =('.'!A31) -> 0 | CZ8: =('.'!M31) -> 0 | DA8: =('.'!M37) -> 0 | DH8: =('.'!A31) -> 0 | DI8: =('.'!N31) -> 0 | DJ8: =('.'!N37) -> 0 | DQ8: =('.'!A31) -> 0 | DR8: =('.'!O31) -> 0 | DS8: =('.'!O37) -> 0 | DZ8: =('.'!A31) -> 0 | EA8: =('.'!P31) -> 0 | EB8: =('.'!P37) -> 0 | EI8: =('.'!A31) -> 0 | EJ8: =('.'!Q31) -> 0 | EK8: =('.'!Q37) -> 0 | ER8: =('.'!A31) -> 0 | ES8: =('.'!R31) -> 0 | ET8: =('.'!R37) -> 0 | FA8: =('.'!A31) -> 0 | FB8: =('.'!S31) -> 0 | FC8: =('.'!S37) -> 0 | FJ8: =('.'!A31) -> 0 | FK8: =('.'!T31) -> 0 | FL8: =('.'!T37) -> 0 | FS8: =('.'!A31) -> 0 | FT8: =('.'!U31) -> 0 | FU8: =('.'!U37) -> 0 | GB8: =('.'!A31) -> 0 | GC8: =('.'!V31) -> 0 | GD8: =('.'!V37) -> 0 | GK8: =('.'!A31) -> 0 | GL8: =('.'!W31) -> 0 | GM8: =('.'!W37) -> 0
D9: =('.'!A32) -> 0 | E9: =('.'!B32) -> 0 | F9: =('.'!B38) -> 0 | M9: =('.'!A32) -> 0 | N9: =('.'!C32) -> 0 | O9: =('.'!C38) -> 0 | V9: =('.'!A32) -> 0 | W9: =('.'!D32) -> 0 | X9: =('.'!D38) -> 0 | AE9: =('.'!A32) -> 0 | AF9: =('.'!E32) -> 0 | AG9: =('.'!E38) -> 0 | AN9: =('.'!A32) -> 0 | AO9: =('.'!F32) -> 0 | AP9: =('.'!F38) -> 0 | AW9: =('.'!A32) -> 0 | AX9: =('.'!G32) -> 0 | AY9: =('.'!G38) -> 0 | BF9: =('.'!A32) -> 0 | BG9: =('.'!H32) -> 0 | BH9: =('.'!H38) -> 0 | BO9: =('.'!A32) -> 0 | BP9: =('.'!I32) -> 0 | BQ9: =('.'!I38) -> 0 | BX9: =('.'!A32) -> 0 | BY9: =('.'!J32) -> 0 | BZ9: =('.'!J38) -> 0 | CG9: =('.'!A32) -> 0 | CH9: =('.'!K32) -> 0 | CI9: =('.'!K38) -> 0 | CP9: =('.'!A32) -> 0 | CQ9: =('.'!L32) -> 0 | CR9: =('.'!L38) -> 0 | CY9: =('.'!A32) -> 0 | CZ9: =('.'!M32) -> 0 | DA9: =('.'!M38) -> 0 | DH9: =('.'!A32) -> 0 | DI9: =('.'!N32) -> 0 | DJ9: =('.'!N38) -> 0 | DQ9: =('.'!A32) -> 0 | DR9: =('.'!O32) -> 0 | DS9: =('.'!O38) -> 0 | DZ9: =('.'!A32) -> 0 | EA9: =('.'!P32) -> 0 | EB9: =('.'!P38) -> 0 | EI9: =('.'!A32) -> 0 | EJ9: =('.'!Q32) -> 0 | EK9: =('.'!Q38) -> 0 | ER9: =('.'!A32) -> 0 | ES9: =('.'!R32) -> 0 | ET9: =('.'!R38) -> 0 | FA9: =('.'!A32) -> 0 | FB9: =('.'!S32) -> 0 | FC9: =('.'!S38) -> 0 | FJ9: =('.'!A32) -> 0 | FK9: =('.'!T32) -> 0 | FL9: =('.'!T38) -> 0 | FS9: =('.'!A32) -> 0 | FT9: =('.'!U32) -> 0 | FU9: =('.'!U38) -> 0 | GB9: =('.'!A32) -> 0 | GC9: =('.'!V32) -> 0 | GD9: =('.'!V38) -> 0 | GK9: =('.'!A32) -> 0 | GL9: =('.'!W32) -> 0 | GM9: =('.'!W38) -> 0
D10: =('.'!A33) -> 0 | E10: =('.'!B33) -> 0 | F10: =('.'!B39) -> 0 | M10: =('.'!A33) -> 0 | N10: =('.'!C33) -> 0 | O10: =('.'!C39) -> 0 | V10: =('.'!A33) -> 0 | W10: =('.'!D33) -> 0 | X10: =('.'!D39) -> 0 | AE10: =('.'!A33) -> 0 | AF10: =('.'!E33) -> 0 | AG10: =('.'!E39) -> 0 | AN10: =('.'!A33) -> 0 | AO10: =('.'!F33) -> 0 | AP10: =('.'!F39) -> 0 | AW10: =('.'!A33) -> 0 | AX10: =('.'!G33) -> 0 | AY10: =('.'!G39) -> 0 | BF10: =('.'!A33) -> 0 | BG10: =('.'!H33) -> 0 | BH10: =('.'!H39) -> 0 | BO10: =('.'!A33) -> 0 | BP10: =('.'!I33) -> 0 | BQ10: =('.'!I39) -> 0 | BX10: =('.'!A33) -> 0 | BY10: =('.'!J33) -> 0 | BZ10: =('.'!J39) -> 0 | CG10: =('.'!A33) -> 0 | CH10: =('.'!K33) -> 0 | CI10: =('.'!K39) -> 0 | CP10: =('.'!A33) -> 0 | CQ10: =('.'!L33) -> 0 | CR10: =('.'!L39) -> 0 | CY10: =('.'!A33) -> 0 | CZ10: =('.'!M33) -> 0 | DA10: =('.'!M39) -> 0 | DH10: =('.'!A33) -> 0 | DI10: =('.'!N33) -> 0 | DJ10: =('.'!N39) -> 0 | DQ10: =('.'!A33) -> 0 | DR10: =('.'!O33) -> 0 | DS10: =('.'!O39) -> 0 | DZ10: =('.'!A33) -> 0 | EA10: =('.'!P33) -> 0 | EB10: =('.'!P39) -> 0 | EI10: =('.'!A33) -> 0 | EJ10: =('.'!Q33) -> 0 | EK10: =('.'!Q39) -> 0 | ER10: =('.'!A33) -> 0 | ES10: =('.'!R33) -> 0 | ET10: =('.'!R39) -> 0 | FA10: =('.'!A33) -> 0 | FB10: =('.'!S33) -> 0 | FC10: =('.'!S39) -> 0 | FJ10: =('.'!A33) -> 0 | FK10: =('.'!T33) -> 0 | FL10: =('.'!T39) -> 0 | FS10: =('.'!A33) -> 0 | FT10: =('.'!U33) -> 0 | FU10: =('.'!U39) -> 0 | GB10: =('.'!A33) -> 0 | GC10: =('.'!V33) -> 0 | GD10: =('.'!V39) -> 0 | GK10: =('.'!A33) -> 0 | GL10: =('.'!W33) -> 0 | GM10: =('.'!W39) -> 0
D11: =('.'!A34) -> 0 | E11: =('.'!B34) -> 0 | F11: =('.'!B40) -> 0 | M11: =('.'!A34) -> 0 | N11: =('.'!C34) -> 0 | O11: =('.'!C40) -> 0 | V11: =('.'!A34) -> 0 | W11: =('.'!D34) -> 0 | X11: =('.'!D40) -> 0 | AE11: =('.'!A34) -> 0 | AF11: =('.'!E34) -> 0 | AG11: =('.'!E40) -> 0 | AN11: =('.'!A34) -> 0 | AO11: =('.'!F34) -> 0 | AP11: =('.'!F40) -> 0 | AW11: =('.'!A34) -> 0 | AX11: =('.'!G34) -> 0 | AY11: =('.'!G40) -> 0 | BF11: =('.'!A34) -> 0 | BG11: =('.'!H34) -> 0 | BH11: =('.'!H40) -> 0 | BO11: =('.'!A34) -> 0 | BP11: =('.'!I34) -> 0 | BQ11: =('.'!I40) -> 0 | BX11: =('.'!A34) -> 0 | BY11: =('.'!J34) -> 0 | BZ11: =('.'!J40) -> 0 | CG11: =('.'!A34) -> 0 | CH11: =('.'!K34) -> 0 | CI11: =('.'!K40) -> 0 | CP11: =('.'!A34) -> 0 | CQ11: =('.'!L34) -> 0 | CR11: =('.'!L40) -> 0 | CY11: =('.'!A34) -> 0 | CZ11: =('.'!M34) -> 0 | DA11: =('.'!M40) -> 0 | DH11: =('.'!A34) -> 0 | DI11: =('.'!N34) -> 0 | DJ11: =('.'!N40) -> 0 | DQ11: =('.'!A34) -> 0 | DR11: =('.'!O34) -> 0 | DS11: =('.'!O40) -> 0 | DZ11: =('.'!A34) -> 0 | EA11: =('.'!P34) -> 0 | EB11: =('.'!P40) -> 0 | EI11: =('.'!A34) -> 0 | EJ11: =('.'!Q34) -> 0 | EK11: =('.'!Q40) -> 0 | ER11: =('.'!A34) -> 0 | ES11: =('.'!R34) -> 0 | ET11: =('.'!R40) -> 0 | FA11: =('.'!A34) -> 0 | FB11: =('.'!S34) -> 0 | FC11: =('.'!S40) -> 0 | FJ11: =('.'!A34) -> 0 | FK11: =('.'!T34) -> 0 | FL11: =('.'!T40) -> 0 | FS11: =('.'!A34) -> 0 | FT11: =('.'!U34) -> 0 | FU11: =('.'!U40) -> 0 | GB11: =('.'!A34) -> 0 | GC11: =('.'!V34) -> 0 | GD11: =('.'!V40) -> 0 | GK11: =('.'!A34) -> 0 | GL11: =('.'!W34) -> 0 | GM11: =('.'!W40) -> 0
D12: =('.'!A35) -> 0 | E12: =('.'!B35) -> 0 | F12: =('.'!B41) -> 0 | M12: =('.'!A35) -> 0 | N12: =('.'!C35) -> 0 | O12: =('.'!C41) -> 0 | V12: =('.'!A35) -> 0 | W12: =('.'!D35) -> 0 | X12: =('.'!D41) -> 0 | AE12: =('.'!A35) -> 0 | AF12: =('.'!E35) -> 0 | AG12: =('.'!E41) -> 0 | AN12: =('.'!A35) -> 0 | AO12: =('.'!F35) -> 0 | AP12: =('.'!F41) -> 0 | AW12: =('.'!A35) -> 0 | AX12: =('.'!G35) -> 0 | AY12: =('.'!G41) -> 0 | BF12: =('.'!A35) -> 0 | BG12: =('.'!H35) -> 0 | BH12: =('.'!H41) -> 0 | BO12: =('.'!A35) -> 0 | BP12: =('.'!I35) -> 0 | BQ12: =('.'!I41) -> 0 | BX12: =('.'!A35) -> 0 | BY12: =('.'!J35) -> 0 | BZ12: =('.'!J41) -> 0 | CG12: =('.'!A35) -> 0 | CH12: =('.'!K35) -> 0 | CI12: =('.'!K41) -> 0 | CP12: =('.'!A35) -> 0 | CQ12: =('.'!L35) -> 0 | CR12: =('.'!L41) -> 0 | CY12: =('.'!A35) -> 0 | CZ12: =('.'!M35) -> 0 | DA12: =('.'!M41) -> 0 | DH12: =('.'!A35) -> 0 | DI12: =('.'!N35) -> 0 | DJ12: =('.'!N41) -> 0 | DQ12: =('.'!A35) -> 0 | DR12: =('.'!O35) -> 0 | DS12: =('.'!O41) -> 0 | DZ12: =('.'!A35) -> 0 | EA12: =('.'!P35) -> 0 | EB12: =('.'!P41) -> 0 | EI12: =('.'!A35) -> 0 | EJ12: =('.'!Q35) -> 0 | EK12: =('.'!Q41) -> 0 | ER12: =('.'!A35) -> 0 | ES12: =('.'!R35) -> 0 | ET12: =('.'!R41) -> 0 | FA12: =('.'!A35) -> 0 | FB12: =('.'!S35) -> 0 | FC12: =('.'!S41) -> 0 | FJ12: =('.'!A35) -> 0 | FK12: =('.'!T35) -> 0 | FL12: =('.'!T41) -> 0 | FS12: =('.'!A35) -> 0 | FT12: =('.'!U35) -> 0 | FU12: =('.'!U41) -> 0 | GB12: =('.'!A35) -> 0 | GC12: =('.'!V35) -> 0 | GD12: =('.'!V41) -> 0 | GK12: =('.'!A35) -> 0 | GL12: =('.'!W35) -> 0 | GM12: =('.'!W41) -> 0
D13: =('.'!A36) -> 0 | E13: =('.'!B36) -> 0 | F13: =('.'!B42) -> 0 | M13: =('.'!A36) -> 0 | N13: =('.'!C36) -> 0 | O13: =('.'!C42) -> 0 | V13: =('.'!A36) -> 0 | W13: =('.'!D36) -> 0 | X13: =('.'!D42) -> 0 | AE13: =('.'!A36) -> 0 | AF13: =('.'!E36) -> 0 | AG13: =('.'!E42) -> 0 | AN13: =('.'!A36) -> 0 | AO13: =('.'!F36) -> 0 | AP13: =('.'!F42) -> 0 | AW13: =('.'!A36) -> 0 | AX13: =('.'!G36) -> 0 | AY13: =('.'!G42) -> 0 | BF13: =('.'!A36) -> 0 | BG13: =('.'!H36) -> 0 | BH13: =('.'!H42) -> 0 | BO13: =('.'!A36) -> 0 | BP13: =('.'!I36) -> 0 | BQ13: =('.'!I42) -> 0 | BX13: =('.'!A36) -> 0 | BY13: =('.'!J36) -> 0 | BZ13: =('.'!J42) -> 0 | CG13: =('.'!A36) -> 0 | CH13: =('.'!K36) -> 0 | CI13: =('.'!K42) -> 0 | CP13: =('.'!A36) -> 0 | CQ13: =('.'!L36) -> 0 | CR13: =('.'!L42) -> 0 | CY13: =('.'!A36) -> 0 | CZ13: =('.'!M36) -> 0 | DA13: =('.'!M42) -> 0 | DH13: =('.'!A36) -> 0 | DI13: =('.'!N36) -> 0 | DJ13: =('.'!N42) -> 0 | DQ13: =('.'!A36) -> 0 | DR13: =('.'!O36) -> 0 | DS13: =('.'!O42) -> 0 | DZ13: =('.'!A36) -> 0 | EA13: =('.'!P36) -> 0 | EB13: =('.'!P42) -> 0 | EI13: =('.'!A36) -> 0 | EJ13: =('.'!Q36) -> 0 | EK13: =('.'!Q42) -> 0 | ER13: =('.'!A36) -> 0 | ES13: =('.'!R36) -> 0 | ET13: =('.'!R42) -> 0 | FA13: =('.'!A36) -> 0 | FB13: =('.'!S36) -> 0 | FC13: =('.'!S42) -> 0 | FJ13: =('.'!A36) -> 0 | FK13: =('.'!T36) -> 0 | FL13: =('.'!T42) -> 0 | FS13: =('.'!A36) -> 0 | FT13: =('.'!U36) -> 0 | FU13: =('.'!U42) -> 0 | GB13: =('.'!A36) -> 0 | GC13: =('.'!V36) -> 0 | GD13: =('.'!V42) -> 0 | GK13: =('.'!A36) -> 0 | GL13: =('.'!W36) -> 0 | GM13: =('.'!W42) -> 0
D14: Elaboración: Propia | M14: Elaboración: Propia | V14: Elaboración: Propia | AE14: Elaboración: Propia | AN14: Elaboración: Propia | AW14: Elaboración: Propia | BF14: Elaboración: Propia | BO14: Elaboración: Propia | BX14: Elaboración: Propia | CG14: Elaboración: Propia | CP14: Elaboración: Propia | CY14: Elaboración: Propia | DH14: Elaboración: Propia | DQ14: Elaboración: Propia | DZ14: Elaboración: Propia | EI14: Elaboración: Propia | ER14: Elaboración: Propia | FA14: Elaboración: Propia | FJ14: Elaboración: Propia | FS14: Elaboración: Propia | GB14: Elaboración: Propia | GK14: Elaboración: Propia
D15: Fuente: Encuesta aplicada | M15: Fuente: Encuesta aplicada | V15: Fuente: Encuesta aplicada | AE15: Fuente: Encuesta aplicada | AN15: Fuente: Encuesta aplicada | AW15: Fuente: Encuesta aplicada | BF15: Fuente: Encuesta aplicada | BO15: Fuente: Encuesta aplicada | BX15: Fuente: Encuesta aplicada | CG15: Fuente: Encuesta aplicada | CP15: Fuente: Encuesta aplicada | CY15: Fuente: Encuesta aplicada | DH15: Fuente: Encuesta aplicada | DQ15: Fuente: Encuesta aplicada | DZ15: Fuente: Encuesta aplicada | EI15: Fuente: Encuesta aplicada | ER15: Fuente: Encuesta aplicada | FA15: Fuente: Encuesta aplicada | FJ15: Fuente: Encuesta aplicada | FS15: Fuente: Encuesta aplicada | GB15: Fuente: Encuesta aplicada | GK15: Fuente: Encuesta aplicada
D33: Figura. 1 | M33: Figura. 2 | V33: Figura. 3 | AE33: Figura. 4 | AN33: Figura. 5 | AW33: Figura. 6 | BF33: Figura. 7 | BO33: Figura. 8 | BX33: Figura. 9 | CG33: Figura. 10 | CP33: Figura. 11 | CY33: Figura. 12 | DH33: Figura. 13 | DQ33: Figura. 14 | DZ33: Figura. 15 | EI33: Figura. 16 | ER33: Figura. 17 | FA33: Figura. 18 | FJ33: Figura. 19 | FS33: Figura. 20 | GB33: Figura. 21 | GK33: Figura. 22
D34: . | M34: .
D35: =CONCATENATE("En ","la ",D5," y ",D33," se observa los resultados del ",D4," el cual aborda ",E1062,",en donde se demuestra que el ",ROUND(F8*100,0),"%"," de los ",D1045," tienen una percepción de ",G1046,", el ",ROUND(F9*100,0),"%"," ",G1047,", un ",ROUND(F10*100,0),"%"," ",G1048,",",IF(E1049>0,CONCATENATE(" ademas el ",ROUND(F11*100,0),"%"," ",G1049,)," "),IF(E1049>0,CONCATENATE(" y ",ROUND(F12*100,0),"%",", ",G1050,)," "),"en tal sentido la mayoría de los ",D1045," es decir el ",ROUND(E1053*100,0),"%"," tienen una percepción con una inclinación a un valor ",D1056,","," para ",E1062,".") -> 0 | M35: =CONCATENATE("En ","la ",M5," y ",M33," se observa los resultados del ",M4," el cual aborda ",N1062,",en donde se demuestra que el ",ROUND(O8*100,0),"%"," de los ",M1045," tienen una percepción de ",P1046,", el ",ROUND(O9*100,0),"%"," ",P1047,", un ",ROUND(O10*100,0),"%"," ",P1048,",",IF(N1049>0,CONCATENATE(" ademas el ",ROUND(O11*100,0),"%"," ",P1049,)," "),IF(N1049>0,CONCATENATE(" y ",ROUND(O12*100,0),"%",", ",P1050,)," "),"en tal sentido la mayoría de los ",M1045," es decir el ",ROUND(N1053*100,0),"%"," tienen una percepción con una inclinación a un valor ",M1056,","," para ",N1062,".") -> 0 | V35: =CONCATENATE("En ","la ",V5," y ",V33," se observa los resultados del ",V4," el cual aborda ",W1062,",en donde se demuestra que el ",ROUND(X8*100,0),"%"," de los ",V1045," tienen una percepción de ",Y1046,", el ",ROUND(X9*100,0),"%"," ",Y1047,", un ",ROUND(X10*100,0),"%"," ",Y1048,",",IF(W1049>0,CONCATENATE(" ademas el ",ROUND(X11*100,0),"%"," ",Y1049,)," "),IF(W1049>0,CONCATENATE(" y ",ROUND(X12*100,0),"%",", ",Y1050,)," "),"en tal sentido la mayoría de los ",V1045," es decir el ",ROUND(W1053*100,0),"%"," tienen una percepción con una inclinación a un valor ",V1056,","," para ",W1062,".") -> 0 | AE35: =CONCATENATE("En ","la ",AE5," y ",AE33," se observa los resultados del ",AE4," el cual aborda ",AF1062,",en donde se demuestra que el ",ROUND(AG8*100,0),"%"," de los ",AE1045," tienen una percepción de ",AH1046,", el ",ROUND(AG9*100,0),"%"," ",AH1047,", un ",ROUND(AG10*100,0),"%"," ",AH1048,",",IF(AF1049>0,CONCATENATE(" ademas el ",ROUND(AG11*100,0),"%"," ",AH1049,)," "),IF(AF1049>0,CONCATENATE(" y ",ROUND(AG12*100,0),"%",", ",AH1050,)," "),"en tal sentido la mayoría de los ",AE1045," es decir el ",ROUND(AF1053*100,0),"%"," tienen una percepción con una inclinación a un valor ",AE1056,","," para ",AF1062,".") -> 0 | AN35: =CONCATENATE("En ","la ",AN5," y ",AN33," se observa los resultados del ",AN4," el cual aborda ",AO1062,",en donde se demuestra que el ",ROUND(AP8*100,0),"%"," de los ",AN1045," tienen una percepción de ",AQ1046,", el ",ROUND(AP9*100,0),"%"," ",AQ1047,", un ",ROUND(AP10*100,0),"%"," ",AQ1048,",",IF(AO1049>0,CONCATENATE(" ademas el ",ROUND(AP11*100,0),"%"," ",AQ1049,)," "),IF(AO1049>0,CONCATENATE(" y ",ROUND(AP12*100,0),"%",", ",AQ1050,)," "),"en tal sentido la mayoría de los ",AN1045," es decir el ",ROUND(AO1053*100,0),"%"," tienen una percepción con una inclinación a un valor ",AN1056,","," para ",AO1062,".") -> 0 | AW35: =CONCATENATE("En ","la ",AW5," y ",AW33," se observa los resultados del ",AW4," el cual aborda ",AX1062,",en donde se demuestra que el ",ROUND(AY8*100,0),"%"," de los ",AW1045," tienen una percepción de ",AZ1046,", el ",ROUND(AY9*100,0),"%"," ",AZ1047,", un ",ROUND(AY10*100,0),"%"," ",AZ1048,",",IF(AX1049>0,CONCATENATE(" ademas el ",ROUND(AY11*100,0),"%"," ",AZ1049,)," "),IF(AX1049>0,CONCATENATE(" y ",ROUND(AY12*100,0),"%",", ",AZ1050,)," "),"en tal sentido la mayoría de los ",AW1045," es decir el ",ROUND(AX1053*100,0),"%"," tienen una percepción con una inclinación a un valor ",AW1056,","," para ",AX1062,".") -> 0 | BF35: =CONCATENATE("En ","la ",BF5," y ",BF33," se observa los resultados del ",BF4," el cual aborda ",BG1062,",en donde se demuestra que el ",ROUND(BH8*100,0),"%"," de los ",BF1045," tienen una percepción de ",BI1046,", el ",ROUND(BH9*100,0),"%"," ",BI1047,", un ",ROUND(BH10*100,0),"%"," ",BI1048,",",IF(BG1049>0,CONCATENATE(" ademas el ",ROUND(BH11*100,0),"%"," ",BI1049,)," "),IF(BG1049>0,CONCATENATE(" y ",ROUND(BH12*100,0),"%",", ",BI1050,)," "),"en tal sentido la mayoría de los ",BF1045," es decir el ",ROUND(BG1053*100,0),"%"," tienen una percepción con una inclinación a un valor ",BF1056,","," para ",BG1062,".") -> 0 | BO35: =CONCATENATE("En ","la ",BO5," y ",BO33," se observa los resultados del ",BO4," el cual aborda ",BP1062,",en donde se demuestra que el ",ROUND(BQ8*100,0),"%"," de los ",BO1045," tienen una percepción de ",BR1046,", el ",ROUND(BQ9*100,0),"%"," ",BR1047,", un ",ROUND(BQ10*100,0),"%"," ",BR1048,",",IF(BP1049>0,CONCATENATE(" ademas el ",ROUND(BQ11*100,0),"%"," ",BR1049,)," "),IF(BP1049>0,CONCATENATE(" y ",ROUND(BQ12*100,0),"%",", ",BR1050,)," "),"en tal sentido la mayoría de los ",BO1045," es decir el ",ROUND(BP1053*100,0),"%"," tienen una percepción con una inclinación a un valor ",BO1056,","," para ",BP1062,".") -> 0 | BX35: =CONCATENATE("En ","la ",BX5," y ",BX33," se observa los resultados del ",BX4," el cual aborda ",BY1062,",en donde se demuestra que el ",ROUND(BZ8*100,0),"%"," de los ",BX1045," tienen una percepción de ",CA1046,", el ",ROUND(BZ9*100,0),"%"," ",CA1047,", un ",ROUND(BZ10*100,0),"%"," ",CA1048,",",IF(BY1049>0,CONCATENATE(" ademas el ",ROUND(BZ11*100,0),"%"," ",CA1049,)," "),IF(BY1049>0,CONCATENATE(" y ",ROUND(BZ12*100,0),"%",", ",CA1050,)," "),"en tal sentido la mayoría de los ",BX1045," es decir el ",ROUND(BY1053*100,0),"%"," tienen una percepción con una inclinación a un valor ",BX1056,","," para ",BY1062,".") -> 0 | CG35: =CONCATENATE("En ","la ",CG5," y ",CG33," se observa los resultados del ",CG4," el cual aborda ",CH1062,",en donde se demuestra que el ",ROUND(CI8*100,0),"%"," de los ",CG1045," tienen una percepción de ",CJ1046,", el ",ROUND(CI9*100,0),"%"," ",CJ1047,", un ",ROUND(CI10*100,0),"%"," ",CJ1048,",",IF(CH1049>0,CONCATENATE(" ademas el ",ROUND(CI11*100,0),"%"," ",CJ1049,)," "),IF(CH1049>0,CONCATENATE(" y ",ROUND(CI12*100,0),"%",", ",CJ1050,)," "),"en tal sentido la mayoría de los ",CG1045," es decir el ",ROUND(CH1053*100,0),"%"," tienen una percepción con una inclinación a un valor ",CG1056,","," para ",CH1062,".") -> 0 | CP35: =CONCATENATE("En ","la ",CP5," y ",CP33," se observa los resultados del ",CP4," el cual aborda ",CQ1062,",en donde se demuestra que el ",ROUND(CR8*100,0),"%"," de los ",CP1045," tienen una percepción de ",CS1046,", el ",ROUND(CR9*100,0),"%"," ",CS1047,", un ",ROUND(CR10*100,0),"%"," ",CS1048,",",IF(CQ1049>0,CONCATENATE(" ademas el ",ROUND(CR11*100,0),"%"," ",CS1049,)," "),IF(CQ1049>0,CONCATENATE(" y ",ROUND(CR12*100,0),"%",", ",CS1050,)," "),"en tal sentido la mayoría de los ",CP1045," es decir el ",ROUND(CQ1053*100,0),"%"," tienen una percepción con una inclinación a un valor ",CP1056,","," para ",CQ1062,".") -> 0 | CY35: =CONCATENATE("En ","la ",CY5," y ",CY33," se observa los resultados del ",CY4," el cual aborda ",CZ1062,",en donde se demuestra que el ",ROUND(DA8*100,0),"%"," de los ",CY1045," tienen una percepción de ",DB1046,", el ",ROUND(DA9*100,0),"%"," ",DB1047,", un ",ROUND(DA10*100,0),"%"," ",DB1048,",",IF(CZ1049>0,CONCATENATE(" ademas el ",ROUND(DA11*100,0),"%"," ",DB1049,)," "),IF(CZ1049>0,CONCATENATE(" y ",ROUND(DA12*100,0),"%",", ",DB1050,)," "),"en tal sentido la mayoría de los ",CY1045," es decir el ",ROUND(CZ1053*100,0),"%"," tienen una percepción con una inclinación a un valor ",CY1056,","," para ",CZ1062,".") -> 0 | DH35: =CONCATENATE("En ","la ",DH5," y ",DH33," se observa los resultados del ",DH4," el cual aborda ",DI1062,",en donde se demuestra que el ",ROUND(DJ8*100,0),"%"," de los ",DH1045," tienen una percepción de ",DK1046,", el ",ROUND(DJ9*100,0),"%"," ",DK1047,", un ",ROUND(DJ10*100,0),"%"," ",DK1048,",",IF(DI1049>0,CONCATENATE(" ademas el ",ROUND(DJ11*100,0),"%"," ",DK1049,)," "),IF(DI1049>0,CONCATENATE(" y ",ROUND(DJ12*100,0),"%",", ",DK1050,)," "),"en tal sentido la mayoría de los ",DH1045," es decir el ",ROUND(DI1053*100,0),"%"," tienen una percepción con una inclinación a un valor ",DH1056,","," para ",DI1062,".") -> 0 | DQ35: =CONCATENATE("En ","la ",DQ5," y ",DQ33," se observa los resultados del ",DQ4," el cual aborda ",DR1062,",en donde se demuestra que el ",ROUND(DS8*100,0),"%"," de los ",DQ1045," tienen una percepción de ",DT1046,", el ",ROUND(DS9*100,0),"%"," ",DT1047,", un ",ROUND(DS10*100,0),"%"," ",DT1048,",",IF(DR1049>0,CONCATENATE(" ademas el ",ROUND(DS11*100,0),"%"," ",DT1049,)," "),IF(DR1049>0,CONCATENATE(" y ",ROUND(DS12*100,0),"%",", ",DT1050,)," "),"en tal sentido la mayoría de los ",DQ1045," es decir el ",ROUND(DR1053*100,0),"%"," tienen una percepción con una inclinación a un valor ",DQ1056,","," para ",DR1062,".") -> 0 | DZ35: =CONCATENATE("En ","la ",DZ5," y ",DZ33," se observa los resultados del ",DZ4," el cual aborda ",EA1062,",en donde se demuestra que el ",ROUND(EB8*100,0),"%"," de los ",DZ1045," tienen una percepción de ",EC1046,", el ",ROUND(EB9*100,0),"%"," ",EC1047,", un ",ROUND(EB10*100,0),"%"," ",EC1048,",",IF(EA1049>0,CONCATENATE(" ademas el ",ROUND(EB11*100,0),"%"," ",EC1049,)," "),IF(EA1049>0,CONCATENATE(" y ",ROUND(EB12*100,0),"%",", ",EC1050,)," "),"en tal sentido la mayoría de los ",DZ1045," es decir el ",ROUND(EA1053*100,0),"%"," tienen una percepción con una inclinación a un valor ",DZ1056,","," para ",EA1062,".") -> 0 | EI35: =CONCATENATE("En ","la ",EI5," y ",EI33," se observa los resultados del ",EI4," el cual aborda ",EJ1062,",en donde se demuestra que el ",ROUND(EK8*100,0),"%"," de los ",EI1045," tienen una percepción de ",EL1046,", el ",ROUND(EK9*100,0),"%"," ",EL1047,", un ",ROUND(EK10*100,0),"%"," ",EL1048,",",IF(EJ1049>0,CONCATENATE(" ademas el ",ROUND(EK11*100,0),"%"," ",EL1049,)," "),IF(EJ1049>0,CONCATENATE(" y ",ROUND(EK12*100,0),"%",", ",EL1050,)," "),"en tal sentido la mayoría de los ",EI1045," es decir el ",ROUND(EJ1053*100,0),"%"," tienen una percepción con una inclinación a un valor ",EI1056,","," para ",EJ1062,".") -> 0 | ER35: =CONCATENATE("En ","la ",ER5," y ",ER33," se observa los resultados del ",ER4," el cual aborda ",ES1062,",en donde se demuestra que el ",ROUND(ET8*100,0),"%"," de los ",ER1045," tienen una percepción de ",EU1046,", el ",ROUND(ET9*100,0),"%"," ",EU1047,", un ",ROUND(ET10*100,0),"%"," ",EU1048,",",IF(ES1049>0,CONCATENATE(" ademas el ",ROUND(ET11*100,0),"%"," ",EU1049,)," "),IF(ES1049>0,CONCATENATE(" y ",ROUND(ET12*100,0),"%",", ",EU1050,)," "),"en tal sentido la mayoría de los ",ER1045," es decir el ",ROUND(ES1053*100,0),"%"," tienen una percepción con una inclinación a un valor ",ER1056,","," para ",ES1062,".") -> 0 | FA35: =CONCATENATE("En ","la ",FA5," y ",FA33," se observa los resultados del ",FA4," el cual aborda ",FB1062,",en donde se demuestra que el ",ROUND(FC8*100,0),"%"," de los ",FA1045," tienen una percepción de ",FD1046,", el ",ROUND(FC9*100,0),"%"," ",FD1047,", un ",ROUND(FC10*100,0),"%"," ",FD1048,",",IF(FB1049>0,CONCATENATE(" ademas el ",ROUND(FC11*100,0),"%"," ",FD1049,)," "),IF(FB1049>0,CONCATENATE(" y ",ROUND(FC12*100,0),"%",", ",FD1050,)," "),"en tal sentido la mayoría de los ",FA1045," es decir el ",ROUND(FB1053*100,0),"%"," tienen una percepción con una inclinación a un valor ",FA1056,","," para ",FB1062,".") -> 0 | FJ35: =CONCATENATE("En ","la ",FJ5," y ",FJ33," se observa los resultados del ",FJ4," el cual aborda ",FK1062,",en donde se demuestra que el ",ROUND(FL8*100,0),"%"," de los ",FJ1045," tienen una percepción de ",FM1046,", el ",ROUND(FL9*100,0),"%"," ",FM1047,", un ",ROUND(FL10*100,0),"%"," ",FM1048,",",IF(FK1049>0,CONCATENATE(" ademas el ",ROUND(FL11*100,0),"%"," ",FM1049,)," "),IF(FK1049>0,CONCATENATE(" y ",ROUND(FL12*100,0),"%",", ",FM1050,)," "),"en tal sentido la mayoría de los ",FJ1045," es decir el ",ROUND(FK1053*100,0),"%"," tienen una percepción con una inclinación a un valor ",FJ1056,","," para ",FK1062,".") -> 0 | FS35: =CONCATENATE("En ","la ",FS5," y ",FS33," se observa los resultados del ",FS4," el cual aborda ",FT1062,",en donde se demuestra que el ",ROUND(FU8*100,0),"%"," de los ",FS1045," tienen una percepción de ",FV1046,", el ",ROUND(FU9*100,0),"%"," ",FV1047,", un ",ROUND(FU10*100,0),"%"," ",FV1048,",",IF(FT1049>0,CONCATENATE(" ademas el ",ROUND(FU11*100,0),"%"," ",FV1049,)," "),IF(FT1049>0,CONCATENATE(" y ",ROUND(FU12*100,0),"%",", ",FV1050,)," "),"en tal sentido la mayoría de los ",FS1045," es decir el ",ROUND(FT1053*100,0),"%"," tienen una percepción con una inclinación a un valor ",FS1056,","," para ",FT1062,".") -> 0 | GB35: =CONCATENATE("En ","la ",GB5," y ",GB33," se observa los resultados del ",GB4," el cual aborda ",GC1062,",en donde se demuestra que el ",ROUND(GD8*100,0),"%"," de los ",GB1045," tienen una percepción de ",GE1046,", el ",ROUND(GD9*100,0),"%"," ",GE1047,", un ",ROUND(GD10*100,0),"%"," ",GE1048,",",IF(GC1049>0,CONCATENATE(" ademas el ",ROUND(GD11*100,0),"%"," ",GE1049,)," "),IF(GC1049>0,CONCATENATE(" y ",ROUND(GD12*100,0),"%",", ",GE1050,)," "),"en tal sentido la mayoría de los ",GB1045," es decir el ",ROUND(GC1053*100,0),"%"," tienen una percepción con una inclinación a un valor ",GB1056,","," para ",GC1062,".") -> 0 | GK35: =CONCATENATE("En ","la ",GK5," y ",GK33," se observa los resultados del ",GK4," el cual aborda ",GL1062,",en donde se demuestra que el ",ROUND(GM8*100,0),"%"," de los ",GK1045," tienen una percepción de ",GN1046,", el ",ROUND(GM9*100,0),"%"," ",GN1047,", un ",ROUND(GM10*100,0),"%"," ",GN1048,",",IF(GL1049>0,CONCATENATE(" ademas el ",ROUND(GM11*100,0),"%"," ",GN1049,)," "),IF(GL1049>0,CONCATENATE(" y ",ROUND(GM12*100,0),"%",", ",GN1050,)," "),"en tal sentido la mayoría de los ",GK1045," es decir el ",ROUND(GL1053*100,0),"%"," tienen una percepción con una inclinación a un valor ",GK1056,","," para ",GL1062,".") -> 0
D1045: Participantes | E1045: . | M1045: Participantes | N1045: . | V1045: Participantes | AE1045: Participantes | AN1045: Participantes | AW1045: Participantes | BF1045: Participantes | BO1045: Participantes | BX1045: Participantes | CG1045: Participantes | CP1045: Participantes | CY1045: Participantes | DH1045: Participantes | DQ1045: Participantes | DZ1045: Participantes | EI1045: Participantes | ER1045: Participantes | FA1045: Participantes | FJ1045: Participantes | FS1045: Participantes | GB1045: Participantes | GK1045: Participantes
C1046: 1 | D1046: =IF(E1046=F8,D8,IF(E1046=F9,D9,IF(E1046=F10,D10,IF(E1046=F11,D11,IF(E1046=F12,D12,"ALGO ESTA MAL"))))) -> 0 | E1046: =LARGE($F$8:$F$12,C1046) -> 0 | F1046: =IF(E1046>0.1%,E1046,"Algo Esta Mal") -> 0 | G1046: =IF(F1046=E1046,D1046," ") -> 0 | L1046: 1 | M1046: =IF(N1046=O8,M8,IF(N1046=O9,M9,IF(N1046=O10,M10,IF(N1046=O11,M11,IF(N1046=O12,M12,"ALGO ESTA MAL"))))) -> 0 | N1046: =LARGE($O$8:$O$12,L1046) -> 0 | O1046: =IF(N1046>0.1%,N1046,"Algo Esta Mal") -> 0 | P1046: =IF(O1046=N1046,M1046," ") -> 0 | U1046: 1 | V1046: =IF(W1046=X8,V8,IF(W1046=X9,V9,IF(W1046=X10,V10,IF(W1046=X11,V11,IF(W1046=X12,V12,"ALGO ESTA MAL"))))) -> 0 | W1046: =LARGE($X$8:$X$12,U1046) -> 0 | X1046: =IF(W1046>0.1%,W1046,"Algo Esta Mal") -> 0 | Y1046: =IF(X1046=W1046,V1046," ") -> 0 | AD1046: 1 | AE1046: =IF(AF1046=AG8,AE8,IF(AF1046=AG9,AE9,IF(AF1046=AG10,AE10,IF(AF1046=AG11,AE11,IF(AF1046=AG12,AE12,"ALGO ESTA MAL"))))) -> 0 | AF1046: =LARGE($AG$8:$AG$12,AD1046) -> 0 | AG1046: =IF(AF1046>0.1%,AF1046,"Algo Esta Mal") -> 0 | AH1046: =IF(AG1046=AF1046,AE1046," ") -> 0 | AM1046: 1 | AN1046: =IF(AO1046=AP8,AN8,IF(AO1046=AP9,AN9,IF(AO1046=AP10,AN10,IF(AO1046=AP11,AN11,IF(AO1046=AP12,AN12,"ALGO ESTA MAL"))))) -> 0 | AO1046: =LARGE($AP$8:$AP$12,AM1046) -> 0 | AP1046: =IF(AO1046>0.1%,AO1046,"Algo Esta Mal") -> 0 | AQ1046: =IF(AP1046=AO1046,AN1046," ") -> 0 | AV1046: 1 | AW1046: =IF(AX1046=AY8,AW8,IF(AX1046=AY9,AW9,IF(AX1046=AY10,AW10,IF(AX1046=AY11,AW11,IF(AX1046=AY12,AW12,"ALGO ESTA MAL"))))) -> 0 | AX1046: =LARGE($AY$8:$AY$12,AV1046) -> 0 | AY1046: =IF(AX1046>0.1%,AX1046,"Algo Esta Mal") -> 0 | AZ1046: =IF(AY1046=AX1046,AW1046," ") -> 0 | BE1046: 1 | BF1046: =IF(BG1046=BH8,BF8,IF(BG1046=BH9,BF9,IF(BG1046=BH10,BF10,IF(BG1046=BH11,BF11,IF(BG1046=BH12,BF12,"ALGO ESTA MAL"))))) -> 0 | BG1046: =LARGE($BH$8:$BH$12,BE1046) -> 0 | BH1046: =IF(BG1046>0.1%,BG1046,"Algo Esta Mal") -> 0 | BI1046: =IF(BH1046=BG1046,BF1046," ") -> 0 | BN1046: 1 | BO1046: =IF(BP1046=BQ8,BO8,IF(BP1046=BQ9,BO9,IF(BP1046=BQ10,BO10,IF(BP1046=BQ11,BO11,IF(BP1046=BQ12,BO12,"ALGO ESTA MAL"))))) -> 0 | BP1046: =LARGE($BQ$8:$BQ$12,BN1046) -> 0 | BQ1046: =IF(BP1046>0.1%,BP1046,"Algo Esta Mal") -> 0 | BR1046: =IF(BQ1046=BP1046,BO1046," ") -> 0 | BW1046: 1 | BX1046: =IF(BY1046=BZ8,BX8,IF(BY1046=BZ9,BX9,IF(BY1046=BZ10,BX10,IF(BY1046=BZ11,BX11,IF(BY1046=BZ12,BX12,"ALGO ESTA MAL"))))) -> 0 | BY1046: =LARGE($BZ$8:$BZ$12,BW1046) -> 0 | BZ1046: =IF(BY1046>0.1%,BY1046,"Algo Esta Mal") -> 0 | CA1046: =IF(BZ1046=BY1046,BX1046," ") -> 0 | CF1046: 1 | CG1046: =IF(CH1046=CI8,CG8,IF(CH1046=CI9,CG9,IF(CH1046=CI10,CG10,IF(CH1046=CI11,CG11,IF(CH1046=CI12,CG12,"ALGO ESTA MAL"))))) -> 0 | CH1046: =LARGE($CI$8:$CI$12,CF1046) -> 0 | CI1046: =IF(CH1046>0.1%,CH1046,"Algo Esta Mal") -> 0 | CJ1046: =IF(CI1046=CH1046,CG1046," ") -> 0 | CO1046: 1 | CP1046: =IF(CQ1046=CR8,CP8,IF(CQ1046=CR9,CP9,IF(CQ1046=CR10,CP10,IF(CQ1046=CR11,CP11,IF(CQ1046=CR12,CP12,"ALGO ESTA MAL"))))) -> 0 | CQ1046: =LARGE($CR$8:$CR$12,CO1046) -> 0 | CR1046: =IF(CQ1046>0.1%,CQ1046,"Algo Esta Mal") -> 0 | CS1046: =IF(CR1046=CQ1046,CP1046," ") -> 0 | CX1046: 1 | CY1046: =IF(CZ1046=DA8,CY8,IF(CZ1046=DA9,CY9,IF(CZ1046=DA10,CY10,IF(CZ1046=DA11,CY11,IF(CZ1046=DA12,CY12,"ALGO ESTA MAL"))))) -> 0 | CZ1046: =LARGE($DA$8:$DA$12,CX1046) -> 0 | DA1046: =IF(CZ1046>0.1%,CZ1046,"Algo Esta Mal") -> 0 | DB1046: =IF(DA1046=CZ1046,CY1046," ") -> 0 | DG1046: 1 | DH1046: =IF(DI1046=DJ8,DH8,IF(DI1046=DJ9,DH9,IF(DI1046=DJ10,DH10,IF(DI1046=DJ11,DH11,IF(DI1046=DJ12,DH12,"ALGO ESTA MAL"))))) -> 0 | DI1046: =LARGE($DJ$8:$DJ$12,DG1046) -> 0 | DJ1046: =IF(DI1046>0.1%,DI1046,"Algo Esta Mal") -> 0 | DK1046: =IF(DJ1046=DI1046,DH1046," ") -> 0 | DP1046: 1 | DQ1046: =IF(DR1046=DS8,DQ8,IF(DR1046=DS9,DQ9,IF(DR1046=DS10,DQ10,IF(DR1046=DS11,DQ11,IF(DR1046=DS12,DQ12,"ALGO ESTA MAL"))))) -> 0 | DR1046: =LARGE($DS$8:$DS$12,DP1046) -> 0 | DS1046: =IF(DR1046>0.1%,DR1046,"Algo Esta Mal") -> 0 | DT1046: =IF(DS1046=DR1046,DQ1046," ") -> 0 | DY1046: 1 | DZ1046: =IF(EA1046=EB8,DZ8,IF(EA1046=EB9,DZ9,IF(EA1046=EB10,DZ10,IF(EA1046=EB11,DZ11,IF(EA1046=EB12,DZ12,"ALGO ESTA MAL"))))) -> 0 | EA1046: =LARGE($EB$8:$EB$12,DY1046) -> 0 | EB1046: =IF(EA1046>0.1%,EA1046,"Algo Esta Mal") -> 0 | EC1046: =IF(EB1046=EA1046,DZ1046," ") -> 0 | EH1046: 1 | EI1046: =IF(EJ1046=EK8,EI8,IF(EJ1046=EK9,EI9,IF(EJ1046=EK10,EI10,IF(EJ1046=EK11,EI11,IF(EJ1046=EK12,EI12,"ALGO ESTA MAL"))))) -> 0 | EJ1046: =LARGE($EK$8:$EK$12,EH1046) -> 0 | EK1046: =IF(EJ1046>0.1%,EJ1046,"Algo Esta Mal") -> 0 | EL1046: =IF(EK1046=EJ1046,EI1046," ") -> 0 | EQ1046: 1 | ER1046: =IF(ES1046=ET8,ER8,IF(ES1046=ET9,ER9,IF(ES1046=ET10,ER10,IF(ES1046=ET11,ER11,IF(ES1046=ET12,ER12,"ALGO ESTA MAL"))))) -> 0 | ES1046: =LARGE($ET$8:$ET$12,EQ1046) -> 0 | ET1046: =IF(ES1046>0.1%,ES1046,"Algo Esta Mal") -> 0 | EU1046: =IF(ET1046=ES1046,ER1046," ") -> 0 | EZ1046: 1 | FA1046: =IF(FB1046=FC8,FA8,IF(FB1046=FC9,FA9,IF(FB1046=FC10,FA10,IF(FB1046=FC11,FA11,IF(FB1046=FC12,FA12,"ALGO ESTA MAL"))))) -> 0 | FB1046: =LARGE($FC$8:$FC$12,EZ1046) -> 0 | FC1046: =IF(FB1046>0.1%,FB1046,"Algo Esta Mal") -> 0 | FD1046: =IF(FC1046=FB1046,FA1046," ") -> 0 | FI1046: 1 | FJ1046: =IF(FK1046=FL8,FJ8,IF(FK1046=FL9,FJ9,IF(FK1046=FL10,FJ10,IF(FK1046=FL11,FJ11,IF(FK1046=FL12,FJ12,"ALGO ESTA MAL"))))) -> 0 | FK1046: =LARGE($FL$8:$FL$12,FI1046) -> 0 | FL1046: =IF(FK1046>0.1%,FK1046,"Algo Esta Mal") -> 0 | FM1046: =IF(FL1046=FK1046,FJ1046," ") -> 0 | FR1046: 1 | FS1046: =IF(FT1046=FU8,FS8,IF(FT1046=FU9,FS9,IF(FT1046=FU10,FS10,IF(FT1046=FU11,FS11,IF(FT1046=FU12,FS12,"ALGO ESTA MAL"))))) -> 0 | FT1046: =LARGE($FU$8:$FU$12,FR1046) -> 0 | FU1046: =IF(FT1046>0.1%,FT1046,"Algo Esta Mal") -> 0 | FV1046: =IF(FU1046=FT1046,FS1046," ") -> 0 | GA1046: 1 | GB1046: =IF(GC1046=GD8,GB8,IF(GC1046=GD9,GB9,IF(GC1046=GD10,GB10,IF(GC1046=GD11,GB11,IF(GC1046=GD12,GB12,"ALGO ESTA MAL"))))) -> 0 | GC1046: =LARGE($GD$8:$GD$12,GA1046) -> 0 | GD1046: =IF(GC1046>0.1%,GC1046,"Algo Esta Mal") -> 0 | GE1046: =IF(GD1046=GC1046,GB1046," ") -> 0 | GJ1046: 1 | GK1046: =IF(GL1046=GM8,GK8,IF(GL1046=GM9,GK9,IF(GL1046=GM10,GK10,IF(GL1046=GM11,GK11,IF(GL1046=GM12,GK12,"ALGO ESTA MAL"))))) -> 0 | GL1046: =LARGE($GM$8:$GM$12,GJ1046) -> 0 | GM1046: =IF(GL1046>0.1%,GL1046,"Algo Esta Mal") -> 0 | GN1046: =IF(GM1046=GL1046,GK1046," ") -> 0
